Workbook
Name SeuilConforme: PARAMETRES!$B$5
Name SeuilSurveiller: PARAMETRES!$B$6
Name SeuilAlerte: PARAMETRES!$B$6
Name StatutConforme: PARAMETRES!$B$7
Name StatutSurveiller: PARAMETRES!$B$8
Name StatutSousStandard: PARAMETRES!$B$9
Name StatutInitial: PARAMETRES!$B$10
Name StatutStandardManquant: PARAMETRES!$B$11
Name StatutDoublon: PARAMETRES!$B$12
Name MatriculesEmployes: T_EMPLOYES[MATRICULE]
Name NomsEmployes: T_EMPLOYES[NOM ET PRENOM]
Name ListeMatricules: T_EMPLOYES[MATRICULE]
Name ListeRuns: T_RUNS[ID RUN]
Name ListeLignes: T_LIGNES[LIGNE]
Name ListeEspeces: T_ESPECES[ESPÈCE]
Name ListeProduits: T_PRODUITS[PRODUIT]
Name ListeMarques: T_MARQUES[MARQUE]
Name ListeFormats: T_FORMATS[FORMAT]
Name ListePreparations: T_PREPARATIONS[PRÉPARATION]
Name ListeMoules: T_MOULES[MOULE]
Name ListeActivites: T_ACTIVITES[ACTIVITÉ]
Name ListeTours: T_TOURS[TOUR]
Name ListeMotifs: T_MOTIFS[MOTIF ARRÊT]
Name ListeTypesTest: T_TYPES_TEST[TYPE DE TEST]
Name ListeStatutsRun: T_STATUTS_RUN[STATUT RUN]
Name ListeOuiNon: T_OUI_NON[OUI / NON]

Sheet PARAMETRES
A1: PARAMETRES — CADENCES MO
A2: Feuille de reference unique. Completer les listes ci-dessous AVANT de creer un RUN. Les cellules creme sont les seules a saisir.
A3: SEUILS ET LIBELLES DE PERFORMANCE (CONFIGURABLES)
A4: PARAMÈTRE | B4: VALEUR | C4: COMMENTAIRE
A5: SEUIL CONFORME (% DU STANDARD) | B5: 1 | C5: ATTEINTE >= CE SEUIL : STATUT CONFORME
A6: SEUIL A SURVEILLER (% DU STANDARD) | B6: 0.9 | C6: ATTEINTE >= CE SEUIL ET < SEUIL CONFORME : STATUT A SURVEILLER (valeur reprise de la version 1.3)
A7: LIBELLE STATUT CONFORME | B7: CONFORME
A8: LIBELLE STATUT INTERMEDIAIRE | B8: A SURVEILLER
A9: LIBELLE STATUT INSUFFISANT | B9: SOUS STANDARD
A10: LIBELLE STATUT PREMIER CONTROLE | B10: CONTROLE INITIAL | C10: Premier controle du matricule : aucune duree mesuree, pas de cadence
A11: LIBELLE STATUT STANDARD ABSENT | B11: STANDARD MANQUANT | C11: Aucune ligne active de la table STANDARDS ne correspond a la configuration
A12: LIBELLE STATUT DOUBLON | B12: DOUBLON | C12: Matricule deja controle sur le meme RUN + TOUR + LIGNE
A14: LISTES DE REFERENCE
A15: LIGNE | B15: ESPÈCE | C15: PRODUIT | D15: MARQUE | E15: FORMAT | F15: PRÉPARATION | G15: MOULE | H15: ACTIVITÉ | I15: TOUR | J15: MOTIF ARRÊT | K15: TYPE DE TEST | L15: STATUT RUN | M15: OUI / NON
A16: L1 | B16: SARDINE | C16: FMHT | F16: HG | H16: GRATTAGE | I16: TOUR 01 | J16: PAUSE | K16: TEST INDIVIDUEL | L16: ACTIF | M16: OUI
A17: L2 | B17: MAQUEREAU | C17: SPSA HO | F17: HGT | H17: REMPLISSAGE | I17: TOUR 02 | J17: MANQUE MATIERE | K17: TEST COMPARATIF | L17: CLOTURE | M17: NON
A18: L3 | C18: SPSA HOEV BIO | H18: GRATTAGE + REMPLISSAGE | I18: TOUR 03 | J18: PANNE | K18: TEST FORMATION | L18: ANNULE
A19: L4 | C19: FMHOEV BIO | H19: INACTIVE | I19: TOUR 04 | J19: ATTENTE CUISSON | K19: TEST QUALITE
A20: L5 | I20: TOUR 05 | J20: ATTENTE QUALITE
A21: L6 | I21: TOUR 06 | J21: NETTOYAGE
A22: L7 | I22: TOUR 07 | J22: CHANGEMENT PRODUIT
A23: L8 | I23: TOUR 08 | J23: ORGANISATION
I24: TOUR 09 | J24: CHANGEMENT DE LOT
I25: TOUR 10 | J25: REGLAGE MACHINE
I26: TOUR 11 | J26: MANQUE DE PERSONNEL
I27: TOUR 12 | J27: COUPURE ELECTRICITE
J28: MANQUE EMBALLAGE
J29: EVACUATION DECHETS
J30: AUTRE
A40: STANDARDS DE CADENCE
A41: Une ligne = une configuration de production. Laisser vide une dimension non applicable (ex. MOULE pour la sardine). Seules les lignes ACTIF = OUI sont utilisees. Le standard repris de la version 1.3 est a confirmer.
A42: ESPÈCE | B42: PRODUIT | C42: MARQUE | D42: FORMAT | E42: PRÉPARATION | F42: MOULE | G42: ACTIVITÉ | H42: STANDARD BOITES/H/FEMME | I42: ACTIF | J42: CLÉ (CALCULÉE)
A43: SARDINE | B43: FMHOEV BIO | G43: GRATTAGE + REMPLISSAGE | H43: 112 | I43: OUI | J43: =IF(OR($A43="",$I43<>"OUI"),"",$A43&"|"&$B43&"|"&$C43&"|"&$D43&"|"&$E43&"|"&$F43&"|"&$G43)
J44: =IF(OR($A44="",$I44<>"OUI"),"",$A44&"|"&$B44&"|"&$C44&"|"&$D44&"|"&$E44&"|"&$F44&"|"&$G44)
J45: =IF(OR($A45="",$I45<>"OUI"),"",$A45&"|"&$B45&"|"&$C45&"|"&$D45&"|"&$E45&"|"&$F45&"|"&$G45)
J46: =IF(OR($A46="",$I46<>"OUI"),"",$A46&"|"&$B46&"|"&$C46&"|"&$D46&"|"&$E46&"|"&$F46&"|"&$G46)
J47: =IF(OR($A47="",$I47<>"OUI"),"",$A47&"|"&$B47&"|"&$C47&"|"&$D47&"|"&$E47&"|"&$F47&"|"&$G47)
J48: =IF(OR($A48="",$I48<>"OUI"),"",$A48&"|"&$B48&"|"&$C48&"|"&$D48&"|"&$E48&"|"&$F48&"|"&$G48)
J49: =IF(OR($A49="",$I49<>"OUI"),"",$A49&"|"&$B49&"|"&$C49&"|"&$D49&"|"&$E49&"|"&$F49&"|"&$G49)
J50: =IF(OR($A50="",$I50<>"OUI"),"",$A50&"|"&$B50&"|"&$C50&"|"&$D50&"|"&$E50&"|"&$F50&"|"&$G50)
...

Sheet RUNS
A1: RUNS — CONTEXTE DE PRODUCTION
A2: Un RUN = une configuration de production. L'activite de chaque ligne (L1 a L8) appartient au RUN : elle n'est jamais figee. Saisir un ID RUN unique et stable (ex. RUN-20260905-01) : il relie tout l'historique.
A4: LISTE DES RUNS
A5: ID RUN | B5: DATE | C5: HEURE DEBUT | D5: HEURE FIN | E5: ESPÈCE | F5: PRODUIT | G5: MARQUE | H5: FORMAT | I5: LOT MP | J5: PRÉPARATION | K5: MOULE | L5: ACTIVITÉ L1 | M5: ACTIVITÉ L2 | N5: ACTIVITÉ L3 | O5: ACTIVITÉ L4 | P5: ACTIVITÉ L5 | Q5: ACTIVITÉ L6 | R5: ACTIVITÉ L7 | S5: ACTIVITÉ L8 | T5: STATUT RUN | U5: CONTRÔLE DE COHÉRENCE
U6: =IF($A6="","",IF(COUNTIF(RUNS!$A$6:$A$1005,$A6)>1,"ID RUN EN DOUBLON",IF($B6="","DATE MANQUANTE",IF($E6="","ESPECE MANQUANTE",IF($F6="","PRODUIT MANQUANT",IF($T6="","STATUT RUN MANQUANT",IF(COUNTIF($L6:$S6,"INACTIVE")=8,"AUCUNE LIGNE ACTIVE","RUN VALIDE")))))))
U7: =IF($A7="","",IF(COUNTIF(RUNS!$A$6:$A$1005,$A7)>1,"ID RUN EN DOUBLON",IF($B7="","DATE MANQUANTE",IF($E7="","ESPECE MANQUANTE",IF($F7="","PRODUIT MANQUANT",IF($T7="","STATUT RUN MANQUANT",IF(COUNTIF($L7:$S7,"INACTIVE")=8,"AUCUNE LIGNE ACTIVE","RUN VALIDE")))))))
U8: =IF($A8="","",IF(COUNTIF(RUNS!$A$6:$A$1005,$A8)>1,"ID RUN EN DOUBLON",IF($B8="","DATE MANQUANTE",IF($E8="","ESPECE MANQUANTE",IF($F8="","PRODUIT MANQUANT",IF($T8="","STATUT RUN MANQUANT",IF(COUNTIF($L8:$S8,"INACTIVE")=8,"AUCUNE LIGNE ACTIVE","RUN VALIDE")))))))
U9: =IF($A9="","",IF(COUNTIF(RUNS!$A$6:$A$1005,$A9)>1,"ID RUN EN DOUBLON",IF($B9="","DATE MANQUANTE",IF($E9="","ESPECE MANQUANTE",IF($F9="","PRODUIT MANQUANT",IF($T9="","STATUT RUN MANQUANT",IF(COUNTIF($L9:$S9,"INACTIVE")=8,"AUCUNE LIGNE ACTIVE","RUN VALIDE")))))))
U10: =IF($A10="","",IF(COUNTIF(RUNS!$A$6:$A$1005,$A10)>1,"ID RUN EN DOUBLON",IF($B10="","DATE MANQUANTE",IF($E10="","ESPECE MANQUANTE",IF($F10="","PRODUIT MANQUANT",IF($T10="","STATUT RUN MANQUANT",IF(COUNTIF($L10:$S10,"INACTIVE")=8,"AUCUNE LIGNE ACTIVE","RUN VALIDE")))))))
U11: =IF($A11="","",IF(COUNTIF(RUNS!$A$6:$A$1005,$A11)>1,"ID RUN EN DOUBLON",IF($B11="","DATE MANQUANTE",IF($E11="","ESPECE MANQUANTE",IF($F11="","PRODUIT MANQUANT",IF($T11="","STATUT RUN MANQUANT",IF(COUNTIF($L11:$S11,"INACTIVE")=8,"AUCUNE LIGNE ACTIVE","RUN VALIDE")))))))
U12: =IF($A12="","",IF(COUNTIF(RUNS!$A$6:$A$1005,$A12)>1,"ID RUN EN DOUBLON",IF($B12="","DATE MANQUANTE",IF($E12="","ESPECE MANQUANTE",IF($F12="","PRODUIT MANQUANT",IF($T12="","STATUT RUN MANQUANT",IF(COUNTIF($L12:$S12,"INACTIVE")=8,"AUCUNE LIGNE ACTIVE","RUN VALIDE")))))))
U13: =IF($A13="","",IF(COUNTIF(RUNS!$A$6:$A$1005,$A13)>1,"ID RUN EN DOUBLON",IF($B13="","DATE MANQUANTE",IF($E13="","ESPECE MANQUANTE",IF($F13="","PRODUIT MANQUANT",IF($T13="","STATUT RUN MANQUANT",IF(COUNTIF($L13:$S13,"INACTIVE")=8,"AUCUNE LIGNE ACTIVE","RUN VALIDE")))))))
U14: =IF($A14="","",IF(COUNTIF(RUNS!$A$6:$A$1005,$A14)>1,"ID RUN EN DOUBLON",IF($B14="","DATE MANQUANTE",IF($E14="","ESPECE MANQUANTE",IF($F14="","PRODUIT MANQUANT",IF($T14="","STATUT RUN MANQUANT",IF(COUNTIF($L14:$S14,"INACTIVE")=8,"AUCUNE LIGNE ACTIVE","RUN VALIDE")))))))
U15: =IF($A15="","",IF(COUNTIF(RUNS!$A$6:$A$1005,$A15)>1,"ID RUN EN DOUBLON",IF($B15="","DATE MANQUANTE",IF($E15="","ESPECE MANQUANTE",IF($F15="","PRODUIT MANQUANT",IF($T15="","STATUT RUN MANQUANT",IF(COUNTIF($L15:$S15,"INACTIVE")=8,"AUCUNE LIGNE ACTIVE","RUN VALIDE")))))))
U16: =IF($A16="","",IF(COUNTIF(RUNS!$A$6:$A$1005,$A16)>1,"ID RUN EN DOUBLON",IF($B16="","DATE MANQUANTE",IF($E16="","ESPECE MANQUANTE",IF($F16="","PRODUIT MANQUANT",IF($T16="","STATUT RUN MANQUANT",IF(COUNTIF($L16:$S16,"INACTIVE")=8,"AUCUNE LIGNE ACTIVE","RUN VALIDE")))))))
U17: =IF($A17="","",IF(COUNTIF(RUNS!$A$6:$A$1005,$A17)>1,"ID RUN EN DOUBLON",IF($B17="","DATE MANQUANTE",IF($E17="","ESPECE MANQUANTE",IF($F17="","PRODUIT MANQUANT",IF($T17="","STATUT RUN MANQUANT",IF(COUNTIF($L17:$S17,"INACTIVE")=8,"AUCUNE LIGNE ACTIVE","RUN VALIDE")))))))
... U205: =IF($A205="","",IF(COUNTIF(RUNS!$A$6:$A$1005,$A205)>1,"ID RUN EN DOUBLON",IF($B205="","DATE MANQUANTE",IF($E205="","ESPECE MANQUANTE",IF($F205="","PRODUIT MANQUANT",IF($T205="","STATUT RUN MANQUANT",IF(COUNTIF($L205:$S205,"INACTIVE")=8,"AUCUNE LIGNE ACTIVE","RUN VALIDE")))))))

Sheet SAISIE CONTROLE
A1: SAISIE CONTROLE — TERRAIN
A2: 1. Choisir RUN / TOUR / LIGNE 2. Saisir HEURE DU CONTROLE et EFFECTIF PRESENT 3. Saisir MATRICULE + NB BOITES pour chaque femme 4. Copier le bloc de transfert vers BASE CONTROLES (collage special : valeurs).
A3: CONTEXTE
B4: RUN ACTIF | E4: DATE DU RUN | F4: =IF($C$4="","",IFERROR(IF(INDEX(RUNS!$B$6:$B$1005,MATCH($C$4,RUNS!$A$6:$A$1005,0))="","",INDEX(RUNS!$B$6:$B$1005,MATCH($C$4,RUNS!$A$6:$A$1005,0))),"")) | G4: ESPÈCE | H4: =IF($C$4="","",IFERROR(IF(INDEX(RUNS!$E$6:$E$1005,MATCH($C$4,RUNS!$A$6:$A$1005,0))="","",INDEX(RUNS!$E$6:$E$1005,MATCH($C$4,RUNS!$A$6:$A$1005,0))),""))
B5: TOUR | E5: PRODUIT | F5: =IF($C$4="","",IFERROR(IF(INDEX(RUNS!$F$6:$F$1005,MATCH($C$4,RUNS!$A$6:$A$1005,0))="","",INDEX(RUNS!$F$6:$F$1005,MATCH($C$4,RUNS!$A$6:$A$1005,0))),"")) | G5: PRÉPARATION | H5: =IF($C$4="","",IFERROR(IF(INDEX(RUNS!$J$6:$J$1005,MATCH($C$4,RUNS!$A$6:$A$1005,0))="","",INDEX(RUNS!$J$6:$J$1005,MATCH($C$4,RUNS!$A$6:$A$1005,0))),""))
B6: LIGNE | E6: MARQUE | F6: =IF($C$4="","",IFERROR(IF(INDEX(RUNS!$G$6:$G$1005,MATCH($C$4,RUNS!$A$6:$A$1005,0))="","",INDEX(RUNS!$G$6:$G$1005,MATCH($C$4,RUNS!$A$6:$A$1005,0))),"")) | G6: MOULE | H6: =IF($C$4="","",IFERROR(IF(INDEX(RUNS!$K$6:$K$1005,MATCH($C$4,RUNS!$A$6:$A$1005,0))="","",INDEX(RUNS!$K$6:$K$1005,MATCH($C$4,RUNS!$A$6:$A$1005,0))),""))
B7: HEURE DU CONTROLE | E7: FORMAT | F7: =IF($C$4="","",IFERROR(IF(INDEX(RUNS!$H$6:$H$1005,MATCH($C$4,RUNS!$A$6:$A$1005,0))="","",INDEX(RUNS!$H$6:$H$1005,MATCH($C$4,RUNS!$A$6:$A$1005,0))),"")) | G7: ACTIVITÉ LIGNE | H7: =IF($C$4="","",IFERROR(IF(INDEX(RUNS!$L$6:$S$1005,MATCH($C$4,RUNS!$A$6:$A$1005,0),MATCH("ACTIVITÉ "&$C$6,RUNS!$L$5:$S$5,0))="","",INDEX(RUNS!$L$6:$S$1005,MATCH($C$4,RUNS!$A$6:$A$1005,0),MATCH("ACTIVITÉ "&$C$6,RUNS!$L$5:$S$5,0))),""))
B8: EFFECTIF PRESENT | E8: CONFIGURATION | F8: =IF($C$4="","",_xlfn.TEXTJOIN(" / ",TRUE,$H$4,$F$5,$F$6,$F$7,$H$5,$H$6,$H$7)) | G8: STANDARD | H8: =IF(OR($C$4="",$C$6=""),"",IFERROR(IF(INDEX(PARAMETRES!$H$43:$H$342,MATCH($H$4&"|"&$F$5&"|"&$F$6&"|"&$F$7&"|"&$H$5&"|"&$H$6&"|"&$H$7,PARAMETRES!$J$43:$J$342,0))="","",INDEX(PARAMETRES!$H$43:$H$342,MATCH($H$4&"|"&$F$5&"|"&$F$6&"|"&$F$7&"|"&$H$5&"|"&$H$6&"|"&$H$7,PARAMETRES!$J$43:$J$342,0))),""))
B9: ETAT DU CONTEXTE | C9: =IF($C$4="","SELECTIONNER UN RUN",IF(IFERROR(IF(INDEX(RUNS!$T$6:$T$1005,MATCH($C$4,RUNS!$A$6:$A$1005,0))="","",INDEX(RUNS!$T$6:$T$1005,MATCH($C$4,RUNS!$A$6:$A$1005,0))),"")<>"ACTIF","ATTENTION : RUN NON ACTIF",IF($C$5="","SELECTIONNER UN TOUR",IF($C$6="","SELECTIONNER UNE LIGNE",IF($C$7="","SAISIR L'HEURE DU CONTROLE",IF($C$8="","SAISIR L'EFFECTIF PRESENT",IF($H$7="INACTIVE","ATTENTION : LIGNE INACTIVE SUR CE RUN",IF($H$7="","ATTENTION : ACTIVITE NON DEFINIE POUR CETTE LIGNE",IF($H$8="","ATTENTION : STANDARD MANQUANT POUR CETTE CONFIGURATION","CONTEXTE COMPLET — SAISIE POSSIBLE")))))))))
A11: SAISIE DES CONTROLES — MATRICULE + NB BOITES
A12: N° | B12: MATRICULE | C12: NOM ET PRENOM | D12: NB BOÎTES | E12: STATUT SAISIE
A13: 1 | C13: =IF($B13="","",IFERROR(INDEX(NomsEmployes,MATCH($B13,MatriculesEmployes,0)),"MATRICULE INCONNU")) | E13: =IF($B13="","",IF(ISNA(MATCH($B13,MatriculesEmployes,0)),"MATRICULE INCONNU",IF(COUNTIF($B$13:$B13,$B13)>1,"MATRICULE DEJA CONTROLE",IF(COUNTIFS('BASE CONTROLES'!$D$4:$D$50003,$C$4,'BASE CONTROLES'!$E$4:$E$50003,$C$5,'BASE CONTROLES'!$F$4:$F$50003,$C$6,'BASE CONTROLES'!$G$4:$G$50003,$B13)>0,"MATRICULE DEJA CONTROLE",IF($D13="","SAISIR NB BOITES",IF($D13<=0,"NB BOITES INVALIDE","SAISIE VALIDE"))))))
A14: 2 | C14: =IF($B14="","",IFERROR(INDEX(NomsEmployes,MATCH($B14,MatriculesEmployes,0)),"MATRICULE INCONNU")) | E14: =IF($B14="","",IF(ISNA(MATCH($B14,MatriculesEmployes,0)),"MATRICULE INCONNU",IF(COUNTIF($B$13:$B14,$B14)>1,"MATRICULE DEJA CONTROLE",IF(COUNTIFS('BASE CONTROLES'!$D$4:$D$50003,$C$4,'BASE CONTROLES'!$E$4:$E$50003,$C$5,'BASE CONTROLES'!$F$4:$F$50003,$C$6,'BASE CONTROLES'!$G$4:$G$50003,$B14)>0,"MATRICULE DEJA CONTROLE",IF($D14="","SAISIR NB BOITES",IF($D14<=0,"NB BOITES INVALIDE","SAISIE VALIDE"))))))
A15: 3 | C15: =IF($B15="","",IFERROR(INDEX(NomsEmployes,MATCH($B15,MatriculesEmployes,0)),"MATRICULE INCONNU")) | E15: =IF($B15="","",IF(ISNA(MATCH($B15,MatriculesEmployes,0)),"MATRICULE INCONNU",IF(COUNTIF($B$13:$B15,$B15)>1,"MATRICULE DEJA CONTROLE",IF(COUNTIFS('BASE CONTROLES'!$D$4:$D$50003,$C$4,'BASE CONTROLES'!$E$4:$E$50003,$C$5,'BASE CONTROLES'!$F$4:$F$50003,$C$6,'BASE CONTROLES'!$G$4:$G$50003,$B15)>0,"MATRICULE DEJA CONTROLE",IF($D15="","SAISIR NB BOITES",IF($D15<=0,"NB BOITES INVALIDE","SAISIE VALIDE"))))))
A16: 4 | C16: =IF($B16="","",IFERROR(INDEX(NomsEmployes,MATCH($B16,MatriculesEmployes,0)),"MATRICULE INCONNU")) | E16: =IF($B16="","",IF(ISNA(MATCH($B16,MatriculesEmployes,0)),"MATRICULE INCONNU",IF(COUNTIF($B$13:$B16,$B16)>1,"MATRICULE DEJA CONTROLE",IF(COUNTIFS('BASE CONTROLES'!$D$4:$D$50003,$C$4,'BASE CONTROLES'!$E$4:$E$50003,$C$5,'BASE CONTROLES'!$F$4:$F$50003,$C$6,'BASE CONTROLES'!$G$4:$G$50003,$B16)>0,"MATRICULE DEJA CONTROLE",IF($D16="","SAISIR NB BOITES",IF($D16<=0,"NB BOITES INVALIDE","SAISIE VALIDE"))))))
A17: 5 | C17: =IF($B17="","",IFERROR(INDEX(NomsEmployes,MATCH($B17,MatriculesEmployes,0)),"MATRICULE INCONNU")) | E17: =IF($B17="","",IF(ISNA(MATCH($B17,MatriculesEmployes,0)),"MATRICULE INCONNU",IF(COUNTIF($B$13:$B17,$B17)>1,"MATRICULE DEJA CONTROLE",IF(COUNTIFS('BASE CONTROLES'!$D$4:$D$50003,$C$4,'BASE CONTROLES'!$E$4:$E$50003,$C$5,'BASE CONTROLES'!$F$4:$F$50003,$C$6,'BASE CONTROLES'!$G$4:$G$50003,$B17)>0,"MATRICULE DEJA CONTROLE",IF($D17="","SAISIR NB BOITES",IF($D17<=0,"NB BOITES INVALIDE","SAISIE VALIDE"))))))
A18: 6 | C18: =IF($B18="","",IFERROR(INDEX(NomsEmployes,MATCH($B18,MatriculesEmployes,0)),"MATRICULE INCONNU")) | E18: =IF($B18="","",IF(ISNA(MATCH($B18,MatriculesEmployes,0)),"MATRICULE INCONNU",IF(COUNTIF($B$13:$B18,$B18)>1,"MATRICULE DEJA CONTROLE",IF(COUNTIFS('BASE CONTROLES'!$D$4:$D$50003,$C$4,'BASE CONTROLES'!$E$4:$E$50003,$C$5,'BASE CONTROLES'!$F$4:$F$50003,$C$6,'BASE CONTROLES'!$G$4:$G$50003,$B18)>0,"MATRICULE DEJA CONTROLE",IF($D18="","SAISIR NB BOITES",IF($D18<=0,"NB BOITES INVALIDE","SAISIE VALIDE"))))))
A19: 7 | C19: =IF($B19="","",IFERROR(INDEX(NomsEmployes,MATCH($B19,MatriculesEmployes,0)),"MATRICULE INCONNU")) | E19: =IF($B19="","",IF(ISNA(MATCH($B19,MatriculesEmployes,0)),"MATRICULE INCONNU",IF(COUNTIF($B$13:$B19,$B19)>1,"MATRICULE DEJA CONTROLE",IF(COUNTIFS('BASE CONTROLES'!$D$4:$D$50003,$C$4,'BASE CONTROLES'!$E$4:$E$50003,$C$5,'BASE CONTROLES'!$F$4:$F$50003,$C$6,'BASE CONTROLES'!$G$4:$G$50003,$B19)>0,"MATRICULE DEJA CONTROLE",IF($D19="","SAISIR NB BOITES",IF($D19<=0,"NB BOITES INVALIDE","SAISIE VALIDE"))))))
A20: 8 | C20: =IF($B20="","",IFERROR(INDEX(NomsEmployes,MATCH($B20,MatriculesEmployes,0)),"MATRICULE INCONNU")) | E20: =IF($B20="","",IF(ISNA(MATCH($B20,MatriculesEmployes,0)),"MATRICULE INCONNU",IF(COUNTIF($B$13:$B20,$B20)>1,"MATRICULE DEJA CONTROLE",IF(COUNTIFS('BASE CONTROLES'!$D$4:$D$50003,$C$4,'BASE CONTROLES'!$E$4:$E$50003,$C$5,'BASE CONTROLES'!$F$4:$F$50003,$C$6,'BASE CONTROLES'!$G$4:$G$50003,$B20)>0,"MATRICULE DEJA CONTROLE",IF($D20="","SAISIR NB BOITES",IF($D20<=0,"NB BOITES INVALIDE","SAISIE VALIDE"))))))
A21: 9 | C21: =IF($B21="","",IFERROR(INDEX(NomsEmployes,MATCH($B21,MatriculesEmployes,0)),"MATRICULE INCONNU")) | E21: =IF($B21="","",IF(ISNA(MATCH($B21,MatriculesEmployes,0)),"MATRICULE INCONNU",IF(COUNTIF($B$13:$B21,$B21)>1,"MATRICULE DEJA CONTROLE",IF(COUNTIFS('BASE CONTROLES'!$D$4:$D$50003,$C$4,'BASE CONTROLES'!$E$4:$E$50003,$C$5,'BASE CONTROLES'!$F$4:$F$50003,$C$6,'BASE CONTROLES'!$G$4:$G$50003,$B21)>0,"MATRICULE DEJA CONTROLE",IF($D21="","SAISIR NB BOITES",IF($D21<=0,"NB BOITES INVALIDE","SAISIE VALIDE"))))))
A22: 10 | C22: =IF($B22="","",IFERROR(INDEX(NomsEmployes,MATCH($B22,MatriculesEmployes,0)),"MATRICULE INCONNU")) | E22: =IF($B22="","",IF(ISNA(MATCH($B22,MatriculesEmployes,0)),"MATRICULE INCONNU",IF(COUNTIF($B$13:$B22,$B22)>1,"MATRICULE DEJA CONTROLE",IF(COUNTIFS('BASE CONTROLES'!$D$4:$D$50003,$C$4,'BASE CONTROLES'!$E$4:$E$50003,$C$5,'BASE CONTROLES'!$F$4:$F$50003,$C$6,'BASE CONTROLES'!$G$4:$G$50003,$B22)>0,"MATRICULE DEJA CONTROLE",IF($D22="","SAISIR NB BOITES",IF($D22<=0,"NB BOITES INVALIDE","SAISIE VALIDE"))))))
A23: 11 | C23: =IF($B23="","",IFERROR(INDEX(NomsEmployes,MATCH($B23,MatriculesEmployes,0)),"MATRICULE INCONNU")) | E23: =IF($B23="","",IF(ISNA(MATCH($B23,MatriculesEmployes,0)),"MATRICULE INCONNU",IF(COUNTIF($B$13:$B23,$B23)>1,"MATRICULE DEJA CONTROLE",IF(COUNTIFS('BASE CONTROLES'!$D$4:$D$50003,$C$4,'BASE CONTROLES'!$E$4:$E$50003,$C$5,'BASE CONTROLES'!$F$4:$F$50003,$C$6,'BASE CONTROLES'!$G$4:$G$50003,$B23)>0,"MATRICULE DEJA CONTROLE",IF($D23="","SAISIR NB BOITES",IF($D23<=0,"NB BOITES INVALIDE","SAISIE VALIDE"))))))
A24: 12 | C24: =IF($B24="","",IFERROR(INDEX(NomsEmployes,MATCH($B24,MatriculesEmployes,0)),"MATRICULE INCONNU")) | E24: =IF($B24="","",IF(ISNA(MATCH($B24,MatriculesEmployes,0)),"MATRICULE INCONNU",IF(COUNTIF($B$13:$B24,$B24)>1,"MATRICULE DEJA CONTROLE",IF(COUNTIFS('BASE CONTROLES'!$D$4:$D$50003,$C$4,'BASE CONTROLES'!$E$4:$E$50003,$C$5,'BASE CONTROLES'!$F$4:$F$50003,$C$6,'BASE CONTROLES'!$G$4:$G$50003,$B24)>0,"MATRICULE DEJA CONTROLE",IF($D24="","SAISIR NB BOITES",IF($D24<=0,"NB BOITES INVALIDE","SAISIE VALIDE"))))))
... A28: 16 | C28: =IF($B28="","",IFERROR(INDEX(NomsEmployes,MATCH($B28,MatriculesEmployes,0)),"MATRICULE INCONNU")) | E28: =IF($B28="","",IF(ISNA(MATCH($B28,MatriculesEmployes,0)),"MATRICULE INCONNU",IF(COUNTIF($B$13:$B28,$B28)>1,"MATRICULE DEJA CONTROLE",IF(COUNTIFS('BASE CONTROLES'!$D$4:$D$50003,$C$4,'BASE CONTROLES'!$E$4:$E$50003,$C$5,'BASE CONTROLES'!$F$4:$F$50003,$C$6,'BASE CONTROLES'!$G$4:$G$50003,$B28)>0,"MATRICULE DEJA CONTROLE",IF($D28="","SAISIR NB BOITES",IF($D28<=0,"NB BOITES INVALIDE","SAISIE VALIDE"))))))
A30: AVANCEMENT DU CONTROLE DE LA LIGNE
B31: FEMMES CONTROLEES | C31: EFFECTIF PRESENT | D31: COUVERTURE % | E31: AVANCEMENT | F31: TOTAL BOITES CONTROLEES
B32: =COUNTIF($E$13:$E$28,"SAISIE VALIDE") | C32: =IF($C$8="","",$C$8) | D32: =IF(OR($C$8="",$C$8=0),"",$B$32/$C$8) | E32: =IF($C$8="","",$B$32&" / "&$C$8&IF($B$32>=$C$8," — COMPLET","")) | F32: =SUMIF($E$13:$E$28,"SAISIE VALIDE",$D$13:$D$28)
A34: LIGNES A COPIER DANS BASE CONTROLES
A35: Selectionner la plage B37:I52, Copier, puis dans BASE CONTROLES : clic sur la premiere cellule vide de la colonne DATE > Collage special > Valeurs. Les colonnes calculees se remplissent seules.
B36: DATE | C36: HEURE | D36: ID RUN | E36: TOUR | F36: LIGNE | G36: MATRICULE | H36: NB BOÎTES | I36: EFFECTIF LIGNE
B37: =IF($E13<>"SAISIE VALIDE","",$F$4) | C37: =IF($E13<>"SAISIE VALIDE","",$C$7) | D37: =IF($E13<>"SAISIE VALIDE","",$C$4) | E37: =IF($E13<>"SAISIE VALIDE","",$C$5) | F37: =IF($E13<>"SAISIE VALIDE","",$C$6) | G37: =IF($E13<>"SAISIE VALIDE","",$B13) | H37: =IF($E13<>"SAISIE VALIDE","",$D13) | I37: =IF($E13<>"SAISIE VALIDE","",$C$8)
B38: =IF($E14<>"SAISIE VALIDE","",$F$4) | C38: =IF($E14<>"SAISIE VALIDE","",$C$7) | D38: =IF($E14<>"SAISIE VALIDE","",$C$4) | E38: =IF($E14<>"SAISIE VALIDE","",$C$5) | F38: =IF($E14<>"SAISIE VALIDE","",$C$6) | G38: =IF($E14<>"SAISIE VALIDE","",$B14) | H38: =IF($E14<>"SAISIE VALIDE","",$D14) | I38: =IF($E14<>"SAISIE VALIDE","",$C$8)
B39: =IF($E15<>"SAISIE VALIDE","",$F$4) | C39: =IF($E15<>"SAISIE VALIDE","",$C$7) | D39: =IF($E15<>"SAISIE VALIDE","",$C$4) | E39: =IF($E15<>"SAISIE VALIDE","",$C$5) | F39: =IF($E15<>"SAISIE VALIDE","",$C$6) | G39: =IF($E15<>"SAISIE VALIDE","",$B15) | H39: =IF($E15<>"SAISIE VALIDE","",$D15) | I39: =IF($E15<>"SAISIE VALIDE","",$C$8)
B40: =IF($E16<>"SAISIE VALIDE","",$F$4) | C40: =IF($E16<>"SAISIE VALIDE","",$C$7) | D40: =IF($E16<>"SAISIE VALIDE","",$C$4) | E40: =IF($E16<>"SAISIE VALIDE","",$C$5) | F40: =IF($E16<>"SAISIE VALIDE","",$C$6) | G40: =IF($E16<>"SAISIE VALIDE","",$B16) | H40: =IF($E16<>"SAISIE VALIDE","",$D16) | I40: =IF($E16<>"SAISIE VALIDE","",$C$8)
B41: =IF($E17<>"SAISIE VALIDE","",$F$4) | C41: =IF($E17<>"SAISIE VALIDE","",$C$7) | D41: =IF($E17<>"SAISIE VALIDE","",$C$4) | E41: =IF($E17<>"SAISIE VALIDE","",$C$5) | F41: =IF($E17<>"SAISIE VALIDE","",$C$6) | G41: =IF($E17<>"SAISIE VALIDE","",$B17) | H41: =IF($E17<>"SAISIE VALIDE","",$D17) | I41: =IF($E17<>"SAISIE VALIDE","",$C$8)
B42: =IF($E18<>"SAISIE VALIDE","",$F$4) | C42: =IF($E18<>"SAISIE VALIDE","",$C$7) | D42: =IF($E18<>"SAISIE VALIDE","",$C$4) | E42: =IF($E18<>"SAISIE VALIDE","",$C$5) | F42: =IF($E18<>"SAISIE VALIDE","",$C$6) | G42: =IF($E18<>"SAISIE VALIDE","",$B18) | H42: =IF($E18<>"SAISIE VALIDE","",$D18) | I42: =IF($E18<>"SAISIE VALIDE","",$C$8)
B43: =IF($E19<>"SAISIE VALIDE","",$F$4) | C43: =IF($E19<>"SAISIE VALIDE","",$C$7) | D43: =IF($E19<>"SAISIE VALIDE","",$C$4) | E43: =IF($E19<>"SAISIE VALIDE","",$C$5) | F43: =IF($E19<>"SAISIE VALIDE","",$C$6) | G43: =IF($E19<>"SAISIE VALIDE","",$B19) | H43: =IF($E19<>"SAISIE VALIDE","",$D19) | I43: =IF($E19<>"SAISIE VALIDE","",$C$8)
B44: =IF($E20<>"SAISIE VALIDE","",$F$4) | C44: =IF($E20<>"SAISIE VALIDE","",$C$7) | D44: =IF($E20<>"SAISIE VALIDE","",$C$4) | E44: =IF($E20<>"SAISIE VALIDE","",$C$5) | F44: =IF($E20<>"SAISIE VALIDE","",$C$6) | G44: =IF($E20<>"SAISIE VALIDE","",$B20) | H44: =IF($E20<>"SAISIE VALIDE","",$D20) | I44: =IF($E20<>"SAISIE VALIDE","",$C$8)
B45: =IF($E21<>"SAISIE VALIDE","",$F$4) | C45: =IF($E21<>"SAISIE VALIDE","",$C$7) | D45: =IF($E21<>"SAISIE VALIDE","",$C$4) | E45: =IF($E21<>"SAISIE VALIDE","",$C$5) | F45: =IF($E21<>"SAISIE VALIDE","",$C$6) | G45: =IF($E21<>"SAISIE VALIDE","",$B21) | H45: =IF($E21<>"SAISIE VALIDE","",$D21) | I45: =IF($E21<>"SAISIE VALIDE","",$C$8)
B46: =IF($E22<>"SAISIE VALIDE","",$F$4) | C46: =IF($E22<>"SAISIE VALIDE","",$C$7) | D46: =IF($E22<>"SAISIE VALIDE","",$C$4) | E46: =IF($E22<>"SAISIE VALIDE","",$C$5) | F46: =IF($E22<>"SAISIE VALIDE","",$C$6) | G46: =IF($E22<>"SAISIE VALIDE","",$B22) | H46: =IF($E22<>"SAISIE VALIDE","",$D22) | I46: =IF($E22<>"SAISIE VALIDE","",$C$8)
...

Sheet BASE CONTROLES
A1: BASE CONTROLES — HISTORIQUE PERMANENT
A2: Base continue : ne jamais vider, ne jamais creer une feuille par jour ou par ligne. Coller uniquement les colonnes DATE a EFFECTIF LIGNE (B a I) depuis SAISIE CONTROLE ; toutes les autres colonnes se calculent seules. L'heure est saisie une fois par TOUR et par LIGNE : un horodatage automatique fige demande une macro (voir le rapport de livraison).
A3: ID CONTROLE | B3: DATE | C3: HEURE | D3: ID RUN | E3: TOUR | F3: LIGNE | G3: MATRICULE | H3: NB BOÎTES | I3: EFFECTIF LIGNE | J3: NOM ET PRENOM | K3: ACTIVITÉ | L3: ESPÈCE | M3: PRODUIT | N3: MARQUE | O3: FORMAT | P3: PRÉPARATION | Q3: MOULE | R3: STANDARD | S3: HEURE CONTROLE PRECEDENT | T3: DUREE MESUREE MIN | U3: CADENCE BOITES/H/FEMME | V3: ATTEINTE % | W3: STATUT PERFORMANCE | X3: CONTROLE VALIDE
A4: =IF(OR($B4="",$G4=""),"",TEXT($B4,"YYYYMMDD")&"-"&SUBSTITUTE($E4," ","")&"-"&$F4&"-"&$G4) | J4: =IF($G4="","",IFERROR(INDEX(NomsEmployes,MATCH($G4,MatriculesEmployes,0)),"MATRICULE INCONNU")) | K4: =IF(OR($D4="",$F4=""),"",IFERROR(IF(INDEX(RUNS!$L$6:$S$1005,MATCH($D4,RUNS!$A$6:$A$1005,0),MATCH("ACTIVITÉ "&$F4,RUNS!$L$5:$S$5,0))="","",INDEX(RUNS!$L$6:$S$1005,MATCH($D4,RUNS!$A$6:$A$1005,0),MATCH("ACTIVITÉ "&$F4,RUNS!$L$5:$S$5,0))),"")) | L4: =IF($D4="","",IFERROR(IF(INDEX(RUNS!$E$6:$E$1005,MATCH($D4,RUNS!$A$6:$A$1005,0))="","",INDEX(RUNS!$E$6:$E$1005,MATCH($D4,RUNS!$A$6:$A$1005,0))),"")) | M4: =IF($D4="","",IFERROR(IF(INDEX(RUNS!$F$6:$F$1005,MATCH($D4,RUNS!$A$6:$A$1005,0))="","",INDEX(RUNS!$F$6:$F$1005,MATCH($D4,RUNS!$A$6:$A$1005,0))),"")) | N4: =IF($D4="","",IFERROR(IF(INDEX(RUNS!$G$6:$G$1005,MATCH($D4,RUNS!$A$6:$A$1005,0))="","",INDEX(RUNS!$G$6:$G$1005,MATCH($D4,RUNS!$A$6:$A$1005,0))),"")) | O4: =IF($D4="","",IFERROR(IF(INDEX(RUNS!$H$6:$H$1005,MATCH($D4,RUNS!$A$6:$A$1005,0))="","",INDEX(RUNS!$H$6:$H$1005,MATCH($D4,RUNS!$A$6:$A$1005,0))),"")) | P4: =IF($D4="","",IFERROR(IF(INDEX(RUNS!$J$6:$J$1005,MATCH($D4,RUNS!$A$6:$A$1005,0))="","",INDEX(RUNS!$J$6:$J$1005,MATCH($D4,RUNS!$A$6:$A$1005,0))),"")) | Q4: =IF($D4="","",IFERROR(IF(INDEX(RUNS!$K$6:$K$1005,MATCH($D4,RUNS!$A$6:$A$1005,0))="","",INDEX(RUNS!$K$6:$K$1005,MATCH($D4,RUNS!$A$6:$A$1005,0))),"")) | R4: =IF(OR($L4="",$K4=""),"",IFERROR(IF(INDEX(PARAMETRES!$H$43:$H$342,MATCH($L4&"|"&$M4&"|"&$N4&"|"&$O4&"|"&$P4&"|"&$Q4&"|"&$K4,PARAMETRES!$J$43:$J$342,0))="","",INDEX(PARAMETRES!$H$43:$H$342,MATCH($L4&"|"&$M4&"|"&$N4&"|"&$O4&"|"&$P4&"|"&$Q4&"|"&$K4,PARAMETRES!$J$43:$J$342,0))),"")) | S4: =IF(OR($G4="",$X4<>"VALIDE"),"",IFERROR(LOOKUP(2,1/(($B$3:$B3=$B4)*($G$3:$G3=$G4)*($X$3:$X3="VALIDE")),$C$3:$C3),"")) | T4: =IF(OR($C4="",$S4=""),"",ROUND(($C4-$S4+IF($C4<$S4,1,0))*1440,0)) | U4: =IF(OR($H4="",$T4="",$T4<=0),"",$H4*60/$T4) | V4: =IF(OR($U4="",$R4="",$R4=0),"",$U4/$R4) | W4: =IF($G4="","",IF($X4="CONTEXTE INCOMPLET","CONTEXTE INCOMPLET",IF($X4="DOUBLON",StatutDoublon,IF($S4="",StatutInitial,IF($R4="",StatutStandardManquant,IF($V4="","DONNEES INSUFFISANTES",IF($V4>=SeuilConforme,StatutConforme,IF($V4>=SeuilSurveiller,StatutSurveiller,StatutSousStandard)))))))) | X4: =IF($G4="","",IF(OR($D4="",$E4="",$F4=""),"CONTEXTE INCOMPLET",IF(COUNTIFS($D$3:$D3,$D4,$E$3:$E3,$E4,$F$3:$F3,$F4,$G$3:$G3,$G4)>0,"DOUBLON","VALIDE")))
A5: =IF(OR($B5="",$G5=""),"",TEXT($B5,"YYYYMMDD")&"-"&SUBSTITUTE($E5," ","")&"-"&$F5&"-"&$G5) | J5: =IF($G5="","",IFERROR(INDEX(NomsEmployes,MATCH($G5,MatriculesEmployes,0)),"MATRICULE INCONNU")) | K5: =IF(OR($D5="",$F5=""),"",IFERROR(IF(INDEX(RUNS!$L$6:$S$1005,MATCH($D5,RUNS!$A$6:$A$1005,0),MATCH("ACTIVITÉ "&$F5,RUNS!$L$5:$S$5,0))="","",INDEX(RUNS!$L$6:$S$1005,MATCH($D5,RUNS!$A$6:$A$1005,0),MATCH("ACTIVITÉ "&$F5,RUNS!$L$5:$S$5,0))),"")) | L5: =IF($D5="","",IFERROR(IF(INDEX(RUNS!$E$6:$E$1005,MATCH($D5,RUNS!$A$6:$A$1005,0))="","",INDEX(RUNS!$E$6:$E$1005,MATCH($D5,RUNS!$A$6:$A$1005,0))),"")) | M5: =IF($D5="","",IFERROR(IF(INDEX(RUNS!$F$6:$F$1005,MATCH($D5,RUNS!$A$6:$A$1005,0))="","",INDEX(RUNS!$F$6:$F$1005,MATCH($D5,RUNS!$A$6:$A$1005,0))),"")) | N5: =IF($D5="","",IFERROR(IF(INDEX(RUNS!$G$6:$G$1005,MATCH($D5,RUNS!$A$6:$A$1005,0))="","",INDEX(RUNS!$G$6:$G$1005,MATCH($D5,RUNS!$A$6:$A$1005,0))),"")) | O5: =IF($D5="","",IFERROR(IF(INDEX(RUNS!$H$6:$H$1005,MATCH($D5,RUNS!$A$6:$A$1005,0))="","",INDEX(RUNS!$H$6:$H$1005,MATCH($D5,RUNS!$A$6:$A$1005,0))),"")) | P5: =IF($D5="","",IFERROR(IF(INDEX(RUNS!$J$6:$J$1005,MATCH($D5,RUNS!$A$6:$A$1005,0))="","",INDEX(RUNS!$J$6:$J$1005,MATCH($D5,RUNS!$A$6:$A$1005,0))),"")) | Q5: =IF($D5="","",IFERROR(IF(INDEX(RUNS!$K$6:$K$1005,MATCH($D5,RUNS!$A$6:$A$1005,0))="","",INDEX(RUNS!$K$6:$K$1005,MATCH($D5,RUNS!$A$6:$A$1005,0))),"")) | R5: =IF(OR($L5="",$K5=""),"",IFERROR(IF(INDEX(PARAMETRES!$H$43:$H$342,MATCH($L5&"|"&$M5&"|"&$N5&"|"&$O5&"|"&$P5&"|"&$Q5&"|"&$K5,PARAMETRES!$J$43:$J$342,0))="","",INDEX(PARAMETRES!$H$43:$H$342,MATCH($L5&"|"&$M5&"|"&$N5&"|"&$O5&"|"&$P5&"|"&$Q5&"|"&$K5,PARAMETRES!$J$43:$J$342,0))),"")) | S5: =IF(OR($G5="",$X5<>"VALIDE"),"",IFERROR(LOOKUP(2,1/(($B$3:$B4=$B5)*($G$3:$G4=$G5)*($X$3:$X4="VALIDE")),$C$3:$C4),"")) | T5: =IF(OR($C5="",$S5=""),"",ROUND(($C5-$S5+IF($C5<$S5,1,0))*1440,0)) | U5: =IF(OR($H5="",$T5="",$T5<=0),"",$H5*60/$T5) | V5: =IF(OR($U5="",$R5="",$R5=0),"",$U5/$R5) | W5: =IF($G5="","",IF($X5="CONTEXTE INCOMPLET","CONTEXTE INCOMPLET",IF($X5="DOUBLON",StatutDoublon,IF($S5="",StatutInitial,IF($R5="",StatutStandardManquant,IF($V5="","DONNEES INSUFFISANTES",IF($V5>=SeuilConforme,StatutConforme,IF($V5>=SeuilSurveiller,StatutSurveiller,StatutSousStandard)))))))) | X5: =IF($G5="","",IF(OR($D5="",$E5="",$F5=""),"CONTEXTE INCOMPLET",IF(COUNTIFS($D$3:$D4,$D5,$E$3:$E4,$E5,$F$3:$F4,$F5,$G$3:$G4,$G5)>0,"DOUBLON","VALIDE")))
A6: =IF(OR($B6="",$G6=""),"",TEXT($B6,"YYYYMMDD")&"-"&SUBSTITUTE($E6," ","")&"-"&$F6&"-"&$G6) | J6: =IF($G6="","",IFERROR(INDEX(NomsEmployes,MATCH($G6,MatriculesEmployes,0)),"MATRICULE INCONNU")) | K6: =IF(OR($D6="",$F6=""),"",IFERROR(IF(INDEX(RUNS!$L$6:$S$1005,MATCH($D6,RUNS!$A$6:$A$1005,0),MATCH("ACTIVITÉ "&$F6,RUNS!$L$5:$S$5,0))="","",INDEX(RUNS!$L$6:$S$1005,MATCH($D6,RUNS!$A$6:$A$1005,0),MATCH("ACTIVITÉ "&$F6,RUNS!$L$5:$S$5,0))),"")) | L6: =IF($D6="","",IFERROR(IF(INDEX(RUNS!$E$6:$E$1005,MATCH($D6,RUNS!$A$6:$A$1005,0))="","",INDEX(RUNS!$E$6:$E$1005,MATCH($D6,RUNS!$A$6:$A$1005,0))),"")) | M6: =IF($D6="","",IFERROR(IF(INDEX(RUNS!$F$6:$F$1005,MATCH($D6,RUNS!$A$6:$A$1005,0))="","",INDEX(RUNS!$F$6:$F$1005,MATCH($D6,RUNS!$A$6:$A$1005,0))),"")) | N6: =IF($D6="","",IFERROR(IF(INDEX(RUNS!$G$6:$G$1005,MATCH($D6,RUNS!$A$6:$A$1005,0))="","",INDEX(RUNS!$G$6:$G$1005,MATCH($D6,RUNS!$A$6:$A$1005,0))),"")) | O6: =IF($D6="","",IFERROR(IF(INDEX(RUNS!$H$6:$H$1005,MATCH($D6,RUNS!$A$6:$A$1005,0))="","",INDEX(RUNS!$H$6:$H$1005,MATCH($D6,RUNS!$A$6:$A$1005,0))),"")) | P6: =IF($D6="","",IFERROR(IF(INDEX(RUNS!$J$6:$J$1005,MATCH($D6,RUNS!$A$6:$A$1005,0))="","",INDEX(RUNS!$J$6:$J$1005,MATCH($D6,RUNS!$A$6:$A$1005,0))),"")) | Q6: =IF($D6="","",IFERROR(IF(INDEX(RUNS!$K$6:$K$1005,MATCH($D6,RUNS!$A$6:$A$1005,0))="","",INDEX(RUNS!$K$6:$K$1005,MATCH($D6,RUNS!$A$6:$A$1005,0))),"")) | R6: =IF(OR($L6="",$K6=""),"",IFERROR(IF(INDEX(PARAMETRES!$H$43:$H$342,MATCH($L6&"|"&$M6&"|"&$N6&"|"&$O6&"|"&$P6&"|"&$Q6&"|"&$K6,PARAMETRES!$J$43:$J$342,0))="","",INDEX(PARAMETRES!$H$43:$H$342,MATCH($L6&"|"&$M6&"|"&$N6&"|"&$O6&"|"&$P6&"|"&$Q6&"|"&$K6,PARAMETRES!$J$43:$J$342,0))),"")) | S6: =IF(OR($G6="",$X6<>"VALIDE"),"",IFERROR(LOOKUP(2,1/(($B$3:$B5=$B6)*($G$3:$G5=$G6)*($X$3:$X5="VALIDE")),$C$3:$C5),"")) | T6: =IF(OR($C6="",$S6=""),"",ROUND(($C6-$S6+IF($C6<$S6,1,0))*1440,0)) | U6: =IF(OR($H6="",$T6="",$T6<=0),"",$H6*60/$T6) | V6: =IF(OR($U6="",$R6="",$R6=0),"",$U6/$R6) | W6: =IF($G6="","",IF($X6="CONTEXTE INCOMPLET","CONTEXTE INCOMPLET",IF($X6="DOUBLON",StatutDoublon,IF($S6="",StatutInitial,IF($R6="",StatutStandardManquant,IF($V6="","DONNEES INSUFFISANTES",IF($V6>=SeuilConforme,StatutConforme,IF($V6>=SeuilSurveiller,StatutSurveiller,StatutSousStandard)))))))) | X6: =IF($G6="","",IF(OR($D6="",$E6="",$F6=""),"CONTEXTE INCOMPLET",IF(COUNTIFS($D$3:$D5,$D6,$E$3:$E5,$E6,$F$3:$F5,$F6,$G$3:$G5,$G6)>0,"DOUBLON","VALIDE")))
A7: =IF(OR($B7="",$G7=""),"",TEXT($B7,"YYYYMMDD")&"-"&SUBSTITUTE($E7," ","")&"-"&$F7&"-"&$G7) | J7: =IF($G7="","",IFERROR(INDEX(NomsEmployes,MATCH($G7,MatriculesEmployes,0)),"MATRICULE INCONNU")) | K7: =IF(OR($D7="",$F7=""),"",IFERROR(IF(INDEX(RUNS!$L$6:$S$1005,MATCH($D7,RUNS!$A$6:$A$1005,0),MATCH("ACTIVITÉ "&$F7,RUNS!$L$5:$S$5,0))="","",INDEX(RUNS!$L$6:$S$1005,MATCH($D7,RUNS!$A$6:$A$1005,0),MATCH("ACTIVITÉ "&$F7,RUNS!$L$5:$S$5,0))),"")) | L7: =IF($D7="","",IFERROR(IF(INDEX(RUNS!$E$6:$E$1005,MATCH($D7,RUNS!$A$6:$A$1005,0))="","",INDEX(RUNS!$E$6:$E$1005,MATCH($D7,RUNS!$A$6:$A$1005,0))),"")) | M7: =IF($D7="","",IFERROR(IF(INDEX(RUNS!$F$6:$F$1005,MATCH($D7,RUNS!$A$6:$A$1005,0))="","",INDEX(RUNS!$F$6:$F$1005,MATCH($D7,RUNS!$A$6:$A$1005,0))),"")) | N7: =IF($D7="","",IFERROR(IF(INDEX(RUNS!$G$6:$G$1005,MATCH($D7,RUNS!$A$6:$A$1005,0))="","",INDEX(RUNS!$G$6:$G$1005,MATCH($D7,RUNS!$A$6:$A$1005,0))),"")) | O7: =IF($D7="","",IFERROR(IF(INDEX(RUNS!$H$6:$H$1005,MATCH($D7,RUNS!$A$6:$A$1005,0))="","",INDEX(RUNS!$H$6:$H$1005,MATCH($D7,RUNS!$A$6:$A$1005,0))),"")) | P7: =IF($D7="","",IFERROR(IF(INDEX(RUNS!$J$6:$J$1005,MATCH($D7,RUNS!$A$6:$A$1005,0))="","",INDEX(RUNS!$J$6:$J$1005,MATCH($D7,RUNS!$A$6:$A$1005,0))),"")) | Q7: =IF($D7="","",IFERROR(IF(INDEX(RUNS!$K$6:$K$1005,MATCH($D7,RUNS!$A$6:$A$1005,0))="","",INDEX(RUNS!$K$6:$K$1005,MATCH($D7,RUNS!$A$6:$A$1005,0))),"")) | R7: =IF(OR($L7="",$K7=""),"",IFERROR(IF(INDEX(PARAMETRES!$H$43:$H$342,MATCH($L7&"|"&$M7&"|"&$N7&"|"&$O7&"|"&$P7&"|"&$Q7&"|"&$K7,PARAMETRES!$J$43:$J$342,0))="","",INDEX(PARAMETRES!$H$43:$H$342,MATCH($L7&"|"&$M7&"|"&$N7&"|"&$O7&"|"&$P7&"|"&$Q7&"|"&$K7,PARAMETRES!$J$43:$J$342,0))),"")) | S7: =IF(OR($G7="",$X7<>"VALIDE"),"",IFERROR(LOOKUP(2,1/(($B$3:$B6=$B7)*($G$3:$G6=$G7)*($X$3:$X6="VALIDE")),$C$3:$C6),"")) | T7: =IF(OR($C7="",$S7=""),"",ROUND(($C7-$S7+IF($C7<$S7,1,0))*1440,0)) | U7: =IF(OR($H7="",$T7="",$T7<=0),"",$H7*60/$T7) | V7: =IF(OR($U7="",$R7="",$R7=0),"",$U7/$R7) | W7: =IF($G7="","",IF($X7="CONTEXTE INCOMPLET","CONTEXTE INCOMPLET",IF($X7="DOUBLON",StatutDoublon,IF($S7="",StatutInitial,IF($R7="",StatutStandardManquant,IF($V7="","DONNEES INSUFFISANTES",IF($V7>=SeuilConforme,StatutConforme,IF($V7>=SeuilSurveiller,StatutSurveiller,StatutSousStandard)))))))) | X7: =IF($G7="","",IF(OR($D7="",$E7="",$F7=""),"CONTEXTE INCOMPLET",IF(COUNTIFS($D$3:$D6,$D7,$E$3:$E6,$E7,$F$3:$F6,$F7,$G$3:$G6,$G7)>0,"DOUBLON","VALIDE")))
A8: =IF(OR($B8="",$G8=""),"",TEXT($B8,"YYYYMMDD")&"-"&SUBSTITUTE($E8," ","")&"-"&$F8&"-"&$G8) | J8: =IF($G8="","",IFERROR(INDEX(NomsEmployes,MATCH($G8,MatriculesEmployes,0)),"MATRICULE INCONNU")) | K8: =IF(OR($D8="",$F8=""),"",IFERROR(IF(INDEX(RUNS!$L$6:$S$1005,MATCH($D8,RUNS!$A$6:$A$1005,0),MATCH("ACTIVITÉ "&$F8,RUNS!$L$5:$S$5,0))="","",INDEX(RUNS!$L$6:$S$1005,MATCH($D8,RUNS!$A$6:$A$1005,0),MATCH("ACTIVITÉ "&$F8,RUNS!$L$5:$S$5,0))),"")) | L8: =IF($D8="","",IFERROR(IF(INDEX(RUNS!$E$6:$E$1005,MATCH($D8,RUNS!$A$6:$A$1005,0))="","",INDEX(RUNS!$E$6:$E$1005,MATCH($D8,RUNS!$A$6:$A$1005,0))),"")) | M8: =IF($D8="","",IFERROR(IF(INDEX(RUNS!$F$6:$F$1005,MATCH($D8,RUNS!$A$6:$A$1005,0))="","",INDEX(RUNS!$F$6:$F$1005,MATCH($D8,RUNS!$A$6:$A$1005,0))),"")) | N8: =IF($D8="","",IFERROR(IF(INDEX(RUNS!$G$6:$G$1005,MATCH($D8,RUNS!$A$6:$A$1005,0))="","",INDEX(RUNS!$G$6:$G$1005,MATCH($D8,RUNS!$A$6:$A$1005,0))),"")) | O8: =IF($D8="","",IFERROR(IF(INDEX(RUNS!$H$6:$H$1005,MATCH($D8,RUNS!$A$6:$A$1005,0))="","",INDEX(RUNS!$H$6:$H$1005,MATCH($D8,RUNS!$A$6:$A$1005,0))),"")) | P8: =IF($D8="","",IFERROR(IF(INDEX(RUNS!$J$6:$J$1005,MATCH($D8,RUNS!$A$6:$A$1005,0))="","",INDEX(RUNS!$J$6:$J$1005,MATCH($D8,RUNS!$A$6:$A$1005,0))),"")) | Q8: =IF($D8="","",IFERROR(IF(INDEX(RUNS!$K$6:$K$1005,MATCH($D8,RUNS!$A$6:$A$1005,0))="","",INDEX(RUNS!$K$6:$K$1005,MATCH($D8,RUNS!$A$6:$A$1005,0))),"")) | R8: =IF(OR($L8="",$K8=""),"",IFERROR(IF(INDEX(PARAMETRES!$H$43:$H$342,MATCH($L8&"|"&$M8&"|"&$N8&"|"&$O8&"|"&$P8&"|"&$Q8&"|"&$K8,PARAMETRES!$J$43:$J$342,0))="","",INDEX(PARAMETRES!$H$43:$H$342,MATCH($L8&"|"&$M8&"|"&$N8&"|"&$O8&"|"&$P8&"|"&$Q8&"|"&$K8,PARAMETRES!$J$43:$J$342,0))),"")) | S8: =IF(OR($G8="",$X8<>"VALIDE"),"",IFERROR(LOOKUP(2,1/(($B$3:$B7=$B8)*($G$3:$G7=$G8)*($X$3:$X7="VALIDE")),$C$3:$C7),"")) | T8: =IF(OR($C8="",$S8=""),"",ROUND(($C8-$S8+IF($C8<$S8,1,0))*1440,0)) | U8: =IF(OR($H8="",$T8="",$T8<=0),"",$H8*60/$T8) | V8: =IF(OR($U8="",$R8="",$R8=0),"",$U8/$R8) | W8: =IF($G8="","",IF($X8="CONTEXTE INCOMPLET","CONTEXTE INCOMPLET",IF($X8="DOUBLON",StatutDoublon,IF($S8="",StatutInitial,IF($R8="",StatutStandardManquant,IF($V8="","DONNEES INSUFFISANTES",IF($V8>=SeuilConforme,StatutConforme,IF($V8>=SeuilSurveiller,StatutSurveiller,StatutSousStandard)))))))) | X8: =IF($G8="","",IF(OR($D8="",$E8="",$F8=""),"CONTEXTE INCOMPLET",IF(COUNTIFS($D$3:$D7,$D8,$E$3:$E7,$E8,$F$3:$F7,$F8,$G$3:$G7,$G8)>0,"DOUBLON","VALIDE")))
A9: =IF(OR($B9="",$G9=""),"",TEXT($B9,"YYYYMMDD")&"-"&SUBSTITUTE($E9," ","")&"-"&$F9&"-"&$G9) | J9: =IF($G9="","",IFERROR(INDEX(NomsEmployes,MATCH($G9,MatriculesEmployes,0)),"MATRICULE INCONNU")) | K9: =IF(OR($D9="",$F9=""),"",IFERROR(IF(INDEX(RUNS!$L$6:$S$1005,MATCH($D9,RUNS!$A$6:$A$1005,0),MATCH("ACTIVITÉ "&$F9,RUNS!$L$5:$S$5,0))="","",INDEX(RUNS!$L$6:$S$1005,MATCH($D9,RUNS!$A$6:$A$1005,0),MATCH("ACTIVITÉ "&$F9,RUNS!$L$5:$S$5,0))),"")) | L9: =IF($D9="","",IFERROR(IF(INDEX(RUNS!$E$6:$E$1005,MATCH($D9,RUNS!$A$6:$A$1005,0))="","",INDEX(RUNS!$E$6:$E$1005,MATCH($D9,RUNS!$A$6:$A$1005,0))),"")) | M9: =IF($D9="","",IFERROR(IF(INDEX(RUNS!$F$6:$F$1005,MATCH($D9,RUNS!$A$6:$A$1005,0))="","",INDEX(RUNS!$F$6:$F$1005,MATCH($D9,RUNS!$A$6:$A$1005,0))),"")) | N9: =IF($D9="","",IFERROR(IF(INDEX(RUNS!$G$6:$G$1005,MATCH($D9,RUNS!$A$6:$A$1005,0))="","",INDEX(RUNS!$G$6:$G$1005,MATCH($D9,RUNS!$A$6:$A$1005,0))),"")) | O9: =IF($D9="","",IFERROR(IF(INDEX(RUNS!$H$6:$H$1005,MATCH($D9,RUNS!$A$6:$A$1005,0))="","",INDEX(RUNS!$H$6:$H$1005,MATCH($D9,RUNS!$A$6:$A$1005,0))),"")) | P9: =IF($D9="","",IFERROR(IF(INDEX(RUNS!$J$6:$J$1005,MATCH($D9,RUNS!$A$6:$A$1005,0))="","",INDEX(RUNS!$J$6:$J$1005,MATCH($D9,RUNS!$A$6:$A$1005,0))),"")) | Q9: =IF($D9="","",IFERROR(IF(INDEX(RUNS!$K$6:$K$1005,MATCH($D9,RUNS!$A$6:$A$1005,0))="","",INDEX(RUNS!$K$6:$K$1005,MATCH($D9,RUNS!$A$6:$A$1005,0))),"")) | R9: =IF(OR($L9="",$K9=""),"",IFERROR(IF(INDEX(PARAMETRES!$H$43:$H$342,MATCH($L9&"|"&$M9&"|"&$N9&"|"&$O9&"|"&$P9&"|"&$Q9&"|"&$K9,PARAMETRES!$J$43:$J$342,0))="","",INDEX(PARAMETRES!$H$43:$H$342,MATCH($L9&"|"&$M9&"|"&$N9&"|"&$O9&"|"&$P9&"|"&$Q9&"|"&$K9,PARAMETRES!$J$43:$J$342,0))),"")) | S9: =IF(OR($G9="",$X9<>"VALIDE"),"",IFERROR(LOOKUP(2,1/(($B$3:$B8=$B9)*($G$3:$G8=$G9)*($X$3:$X8="VALIDE")),$C$3:$C8),"")) | T9: =IF(OR($C9="",$S9=""),"",ROUND(($C9-$S9+IF($C9<$S9,1,0))*1440,0)) | U9: =IF(OR($H9="",$T9="",$T9<=0),"",$H9*60/$T9) | V9: =IF(OR($U9="",$R9="",$R9=0),"",$U9/$R9) | W9: =IF($G9="","",IF($X9="CONTEXTE INCOMPLET","CONTEXTE INCOMPLET",IF($X9="DOUBLON",StatutDoublon,IF($S9="",StatutInitial,IF($R9="",StatutStandardManquant,IF($V9="","DONNEES INSUFFISANTES",IF($V9>=SeuilConforme,StatutConforme,IF($V9>=SeuilSurveiller,StatutSurveiller,StatutSousStandard)))))))) | X9: =IF($G9="","",IF(OR($D9="",$E9="",$F9=""),"CONTEXTE INCOMPLET",IF(COUNTIFS($D$3:$D8,$D9,$E$3:$E8,$E9,$F$3:$F8,$F9,$G$3:$G8,$G9)>0,"DOUBLON","VALIDE")))
A10: =IF(OR($B10="",$G10=""),"",TEXT($B10,"YYYYMMDD")&"-"&SUBSTITUTE($E10," ","")&"-"&$F10&"-"&$G10) | J10: =IF($G10="","",IFERROR(INDEX(NomsEmployes,MATCH($G10,MatriculesEmployes,0)),"MATRICULE INCONNU")) | K10: =IF(OR($D10="",$F10=""),"",IFERROR(IF(INDEX(RUNS!$L$6:$S$1005,MATCH($D10,RUNS!$A$6:$A$1005,0),MATCH("ACTIVITÉ "&$F10,RUNS!$L$5:$S$5,0))="","",INDEX(RUNS!$L$6:$S$1005,MATCH($D10,RUNS!$A$6:$A$1005,0),MATCH("ACTIVITÉ "&$F10,RUNS!$L$5:$S$5,0))),"")) | L10: =IF($D10="","",IFERROR(IF(INDEX(RUNS!$E$6:$E$1005,MATCH($D10,RUNS!$A$6:$A$1005,0))="","",INDEX(RUNS!$E$6:$E$1005,MATCH($D10,RUNS!$A$6:$A$1005,0))),"")) | M10: =IF($D10="","",IFERROR(IF(INDEX(RUNS!$F$6:$F$1005,MATCH($D10,RUNS!$A$6:$A$1005,0))="","",INDEX(RUNS!$F$6:$F$1005,MATCH($D10,RUNS!$A$6:$A$1005,0))),"")) | N10: =IF($D10="","",IFERROR(IF(INDEX(RUNS!$G$6:$G$1005,MATCH($D10,RUNS!$A$6:$A$1005,0))="","",INDEX(RUNS!$G$6:$G$1005,MATCH($D10,RUNS!$A$6:$A$1005,0))),"")) | O10: =IF($D10="","",IFERROR(IF(INDEX(RUNS!$H$6:$H$1005,MATCH($D10,RUNS!$A$6:$A$1005,0))="","",INDEX(RUNS!$H$6:$H$1005,MATCH($D10,RUNS!$A$6:$A$1005,0))),"")) | P10: =IF($D10="","",IFERROR(IF(INDEX(RUNS!$J$6:$J$1005,MATCH($D10,RUNS!$A$6:$A$1005,0))="","",INDEX(RUNS!$J$6:$J$1005,MATCH($D10,RUNS!$A$6:$A$1005,0))),"")) | Q10: =IF($D10="","",IFERROR(IF(INDEX(RUNS!$K$6:$K$1005,MATCH($D10,RUNS!$A$6:$A$1005,0))="","",INDEX(RUNS!$K$6:$K$1005,MATCH($D10,RUNS!$A$6:$A$1005,0))),"")) | R10: =IF(OR($L10="",$K10=""),"",IFERROR(IF(INDEX(PARAMETRES!$H$43:$H$342,MATCH($L10&"|"&$M10&"|"&$N10&"|"&$O10&"|"&$P10&"|"&$Q10&"|"&$K10,PARAMETRES!$J$43:$J$342,0))="","",INDEX(PARAMETRES!$H$43:$H$342,MATCH($L10&"|"&$M10&"|"&$N10&"|"&$O10&"|"&$P10&"|"&$Q10&"|"&$K10,PARAMETRES!$J$43:$J$342,0))),"")) | S10: =IF(OR($G10="",$X10<>"VALIDE"),"",IFERROR(LOOKUP(2,1/(($B$3:$B9=$B10)*($G$3:$G9=$G10)*($X$3:$X9="VALIDE")),$C$3:$C9),"")) | T10: =IF(OR($C10="",$S10=""),"",ROUND(($C10-$S10+IF($C10<$S10,1,0))*1440,0)) | U10: =IF(OR($H10="",$T10="",$T10<=0),"",$H10*60/$T10) | V10: =IF(OR($U10="",$R10="",$R10=0),"",$U10/$R10) | W10: =IF($G10="","",IF($X10="CONTEXTE INCOMPLET","CONTEXTE INCOMPLET",IF($X10="DOUBLON",StatutDoublon,IF($S10="",StatutInitial,IF($R10="",StatutStandardManquant,IF($V10="","DONNEES INSUFFISANTES",IF($V10>=SeuilConforme,StatutConforme,IF($V10>=SeuilSurveiller,StatutSurveiller,StatutSousStandard)))))))) | X10: =IF($G10="","",IF(OR($D10="",$E10="",$F10=""),"CONTEXTE INCOMPLET",IF(COUNTIFS($D$3:$D9,$D10,$E$3:$E9,$E10,$F$3:$F9,$F10,$G$3:$G9,$G10)>0,"DOUBLON","VALIDE")))
A11: =IF(OR($B11="",$G11=""),"",TEXT($B11,"YYYYMMDD")&"-"&SUBSTITUTE($E11," ","")&"-"&$F11&"-"&$G11) | J11: =IF($G11="","",IFERROR(INDEX(NomsEmployes,MATCH($G11,MatriculesEmployes,0)),"MATRICULE INCONNU")) | K11: =IF(OR($D11="",$F11=""),"",IFERROR(IF(INDEX(RUNS!$L$6:$S$1005,MATCH($D11,RUNS!$A$6:$A$1005,0),MATCH("ACTIVITÉ "&$F11,RUNS!$L$5:$S$5,0))="","",INDEX(RUNS!$L$6:$S$1005,MATCH($D11,RUNS!$A$6:$A$1005,0),MATCH("ACTIVITÉ "&$F11,RUNS!$L$5:$S$5,0))),"")) | L11: =IF($D11="","",IFERROR(IF(INDEX(RUNS!$E$6:$E$1005,MATCH($D11,RUNS!$A$6:$A$1005,0))="","",INDEX(RUNS!$E$6:$E$1005,MATCH($D11,RUNS!$A$6:$A$1005,0))),"")) | M11: =IF($D11="","",IFERROR(IF(INDEX(RUNS!$F$6:$F$1005,MATCH($D11,RUNS!$A$6:$A$1005,0))="","",INDEX(RUNS!$F$6:$F$1005,MATCH($D11,RUNS!$A$6:$A$1005,0))),"")) | N11: =IF($D11="","",IFERROR(IF(INDEX(RUNS!$G$6:$G$1005,MATCH($D11,RUNS!$A$6:$A$1005,0))="","",INDEX(RUNS!$G$6:$G$1005,MATCH($D11,RUNS!$A$6:$A$1005,0))),"")) | O11: =IF($D11="","",IFERROR(IF(INDEX(RUNS!$H$6:$H$1005,MATCH($D11,RUNS!$A$6:$A$1005,0))="","",INDEX(RUNS!$H$6:$H$1005,MATCH($D11,RUNS!$A$6:$A$1005,0))),"")) | P11: =IF($D11="","",IFERROR(IF(INDEX(RUNS!$J$6:$J$1005,MATCH($D11,RUNS!$A$6:$A$1005,0))="","",INDEX(RUNS!$J$6:$J$1005,MATCH($D11,RUNS!$A$6:$A$1005,0))),"")) | Q11: =IF($D11="","",IFERROR(IF(INDEX(RUNS!$K$6:$K$1005,MATCH($D11,RUNS!$A$6:$A$1005,0))="","",INDEX(RUNS!$K$6:$K$1005,MATCH($D11,RUNS!$A$6:$A$1005,0))),"")) | R11: =IF(OR($L11="",$K11=""),"",IFERROR(IF(INDEX(PARAMETRES!$H$43:$H$342,MATCH($L11&"|"&$M11&"|"&$N11&"|"&$O11&"|"&$P11&"|"&$Q11&"|"&$K11,PARAMETRES!$J$43:$J$342,0))="","",INDEX(PARAMETRES!$H$43:$H$342,MATCH($L11&"|"&$M11&"|"&$N11&"|"&$O11&"|"&$P11&"|"&$Q11&"|"&$K11,PARAMETRES!$J$43:$J$342,0))),"")) | S11: =IF(OR($G11="",$X11<>"VALIDE"),"",IFERROR(LOOKUP(2,1/(($B$3:$B10=$B11)*($G$3:$G10=$G11)*($X$3:$X10="VALIDE")),$C$3:$C10),"")) | T11: =IF(OR($C11="",$S11=""),"",ROUND(($C11-$S11+IF($C11<$S11,1,0))*1440,0)) | U11: =IF(OR($H11="",$T11="",$T11<=0),"",$H11*60/$T11) | V11: =IF(OR($U11="",$R11="",$R11=0),"",$U11/$R11) | W11: =IF($G11="","",IF($X11="CONTEXTE INCOMPLET","CONTEXTE INCOMPLET",IF($X11="DOUBLON",StatutDoublon,IF($S11="",StatutInitial,IF($R11="",StatutStandardManquant,IF($V11="","DONNEES INSUFFISANTES",IF($V11>=SeuilConforme,StatutConforme,IF($V11>=SeuilSurveiller,StatutSurveiller,StatutSousStandard)))))))) | X11: =IF($G11="","",IF(OR($D11="",$E11="",$F11=""),"CONTEXTE INCOMPLET",IF(COUNTIFS($D$3:$D10,$D11,$E$3:$E10,$E11,$F$3:$F10,$F11,$G$3:$G10,$G11)>0,"DOUBLON","VALIDE")))
A12: =IF(OR($B12="",$G12=""),"",TEXT($B12,"YYYYMMDD")&"-"&SUBSTITUTE($E12," ","")&"-"&$F12&"-"&$G12) | J12: =IF($G12="","",IFERROR(INDEX(NomsEmployes,MATCH($G12,MatriculesEmployes,0)),"MATRICULE INCONNU")) | K12: =IF(OR($D12="",$F12=""),"",IFERROR(IF(INDEX(RUNS!$L$6:$S$1005,MATCH($D12,RUNS!$A$6:$A$1005,0),MATCH("ACTIVITÉ "&$F12,RUNS!$L$5:$S$5,0))="","",INDEX(RUNS!$L$6:$S$1005,MATCH($D12,RUNS!$A$6:$A$1005,0),MATCH("ACTIVITÉ "&$F12,RUNS!$L$5:$S$5,0))),"")) | L12: =IF($D12="","",IFERROR(IF(INDEX(RUNS!$E$6:$E$1005,MATCH($D12,RUNS!$A$6:$A$1005,0))="","",INDEX(RUNS!$E$6:$E$1005,MATCH($D12,RUNS!$A$6:$A$1005,0))),"")) | M12: =IF($D12="","",IFERROR(IF(INDEX(RUNS!$F$6:$F$1005,MATCH($D12,RUNS!$A$6:$A$1005,0))="","",INDEX(RUNS!$F$6:$F$1005,MATCH($D12,RUNS!$A$6:$A$1005,0))),"")) | N12: =IF($D12="","",IFERROR(IF(INDEX(RUNS!$G$6:$G$1005,MATCH($D12,RUNS!$A$6:$A$1005,0))="","",INDEX(RUNS!$G$6:$G$1005,MATCH($D12,RUNS!$A$6:$A$1005,0))),"")) | O12: =IF($D12="","",IFERROR(IF(INDEX(RUNS!$H$6:$H$1005,MATCH($D12,RUNS!$A$6:$A$1005,0))="","",INDEX(RUNS!$H$6:$H$1005,MATCH($D12,RUNS!$A$6:$A$1005,0))),"")) | P12: =IF($D12="","",IFERROR(IF(INDEX(RUNS!$J$6:$J$1005,MATCH($D12,RUNS!$A$6:$A$1005,0))="","",INDEX(RUNS!$J$6:$J$1005,MATCH($D12,RUNS!$A$6:$A$1005,0))),"")) | Q12: =IF($D12="","",IFERROR(IF(INDEX(RUNS!$K$6:$K$1005,MATCH($D12,RUNS!$A$6:$A$1005,0))="","",INDEX(RUNS!$K$6:$K$1005,MATCH($D12,RUNS!$A$6:$A$1005,0))),"")) | R12: =IF(OR($L12="",$K12=""),"",IFERROR(IF(INDEX(PARAMETRES!$H$43:$H$342,MATCH($L12&"|"&$M12&"|"&$N12&"|"&$O12&"|"&$P12&"|"&$Q12&"|"&$K12,PARAMETRES!$J$43:$J$342,0))="","",INDEX(PARAMETRES!$H$43:$H$342,MATCH($L12&"|"&$M12&"|"&$N12&"|"&$O12&"|"&$P12&"|"&$Q12&"|"&$K12,PARAMETRES!$J$43:$J$342,0))),"")) | S12: =IF(OR($G12="",$X12<>"VALIDE"),"",IFERROR(LOOKUP(2,1/(($B$3:$B11=$B12)*($G$3:$G11=$G12)*($X$3:$X11="VALIDE")),$C$3:$C11),"")) | T12: =IF(OR($C12="",$S12=""),"",ROUND(($C12-$S12+IF($C12<$S12,1,0))*1440,0)) | U12: =IF(OR($H12="",$T12="",$T12<=0),"",$H12*60/$T12) | V12: =IF(OR($U12="",$R12="",$R12=0),"",$U12/$R12) | W12: =IF($G12="","",IF($X12="CONTEXTE INCOMPLET","CONTEXTE INCOMPLET",IF($X12="DOUBLON",StatutDoublon,IF($S12="",StatutInitial,IF($R12="",StatutStandardManquant,IF($V12="","DONNEES INSUFFISANTES",IF($V12>=SeuilConforme,StatutConforme,IF($V12>=SeuilSurveiller,StatutSurveiller,StatutSousStandard)))))))) | X12: =IF($G12="","",IF(OR($D12="",$E12="",$F12=""),"CONTEXTE INCOMPLET",IF(COUNTIFS($D$3:$D11,$D12,$E$3:$E11,$E12,$F$3:$F11,$F12,$G$3:$G11,$G12)>0,"DOUBLON","VALIDE")))
A13: =IF(OR($B13="",$G13=""),"",TEXT($B13,"YYYYMMDD")&"-"&SUBSTITUTE($E13," ","")&"-"&$F13&"-"&$G13) | J13: =IF($G13="","",IFERROR(INDEX(NomsEmployes,MATCH($G13,MatriculesEmployes,0)),"MATRICULE INCONNU")) | K13: =IF(OR($D13="",$F13=""),"",IFERROR(IF(INDEX(RUNS!$L$6:$S$1005,MATCH($D13,RUNS!$A$6:$A$1005,0),MATCH("ACTIVITÉ "&$F13,RUNS!$L$5:$S$5,0))="","",INDEX(RUNS!$L$6:$S$1005,MATCH($D13,RUNS!$A$6:$A$1005,0),MATCH("ACTIVITÉ "&$F13,RUNS!$L$5:$S$5,0))),"")) | L13: =IF($D13="","",IFERROR(IF(INDEX(RUNS!$E$6:$E$1005,MATCH($D13,RUNS!$A$6:$A$1005,0))="","",INDEX(RUNS!$E$6:$E$1005,MATCH($D13,RUNS!$A$6:$A$1005,0))),"")) | M13: =IF($D13="","",IFERROR(IF(INDEX(RUNS!$F$6:$F$1005,MATCH($D13,RUNS!$A$6:$A$1005,0))="","",INDEX(RUNS!$F$6:$F$1005,MATCH($D13,RUNS!$A$6:$A$1005,0))),"")) | N13: =IF($D13="","",IFERROR(IF(INDEX(RUNS!$G$6:$G$1005,MATCH($D13,RUNS!$A$6:$A$1005,0))="","",INDEX(RUNS!$G$6:$G$1005,MATCH($D13,RUNS!$A$6:$A$1005,0))),"")) | O13: =IF($D13="","",IFERROR(IF(INDEX(RUNS!$H$6:$H$1005,MATCH($D13,RUNS!$A$6:$A$1005,0))="","",INDEX(RUNS!$H$6:$H$1005,MATCH($D13,RUNS!$A$6:$A$1005,0))),"")) | P13: =IF($D13="","",IFERROR(IF(INDEX(RUNS!$J$6:$J$1005,MATCH($D13,RUNS!$A$6:$A$1005,0))="","",INDEX(RUNS!$J$6:$J$1005,MATCH($D13,RUNS!$A$6:$A$1005,0))),"")) | Q13: =IF($D13="","",IFERROR(IF(INDEX(RUNS!$K$6:$K$1005,MATCH($D13,RUNS!$A$6:$A$1005,0))="","",INDEX(RUNS!$K$6:$K$1005,MATCH($D13,RUNS!$A$6:$A$1005,0))),"")) | R13: =IF(OR($L13="",$K13=""),"",IFERROR(IF(INDEX(PARAMETRES!$H$43:$H$342,MATCH($L13&"|"&$M13&"|"&$N13&"|"&$O13&"|"&$P13&"|"&$Q13&"|"&$K13,PARAMETRES!$J$43:$J$342,0))="","",INDEX(PARAMETRES!$H$43:$H$342,MATCH($L13&"|"&$M13&"|"&$N13&"|"&$O13&"|"&$P13&"|"&$Q13&"|"&$K13,PARAMETRES!$J$43:$J$342,0))),"")) | S13: =IF(OR($G13="",$X13<>"VALIDE"),"",IFERROR(LOOKUP(2,1/(($B$3:$B12=$B13)*($G$3:$G12=$G13)*($X$3:$X12="VALIDE")),$C$3:$C12),"")) | T13: =IF(OR($C13="",$S13=""),"",ROUND(($C13-$S13+IF($C13<$S13,1,0))*1440,0)) | U13: =IF(OR($H13="",$T13="",$T13<=0),"",$H13*60/$T13) | V13: =IF(OR($U13="",$R13="",$R13=0),"",$U13/$R13) | W13: =IF($G13="","",IF($X13="CONTEXTE INCOMPLET","CONTEXTE INCOMPLET",IF($X13="DOUBLON",StatutDoublon,IF($S13="",StatutInitial,IF($R13="",StatutStandardManquant,IF($V13="","DONNEES INSUFFISANTES",IF($V13>=SeuilConforme,StatutConforme,IF($V13>=SeuilSurveiller,StatutSurveiller,StatutSousStandard)))))))) | X13: =IF($G13="","",IF(OR($D13="",$E13="",$F13=""),"CONTEXTE INCOMPLET",IF(COUNTIFS($D$3:$D12,$D13,$E$3:$E12,$E13,$F$3:$F12,$F13,$G$3:$G12,$G13)>0,"DOUBLON","VALIDE")))
A14: =IF(OR($B14="",$G14=""),"",TEXT($B14,"YYYYMMDD")&"-"&SUBSTITUTE($E14," ","")&"-"&$F14&"-"&$G14) | J14: =IF($G14="","",IFERROR(INDEX(NomsEmployes,MATCH($G14,MatriculesEmployes,0)),"MATRICULE INCONNU")) | K14: =IF(OR($D14="",$F14=""),"",IFERROR(IF(INDEX(RUNS!$L$6:$S$1005,MATCH($D14,RUNS!$A$6:$A$1005,0),MATCH("ACTIVITÉ "&$F14,RUNS!$L$5:$S$5,0))="","",INDEX(RUNS!$L$6:$S$1005,MATCH($D14,RUNS!$A$6:$A$1005,0),MATCH("ACTIVITÉ "&$F14,RUNS!$L$5:$S$5,0))),"")) | L14: =IF($D14="","",IFERROR(IF(INDEX(RUNS!$E$6:$E$1005,MATCH($D14,RUNS!$A$6:$A$1005,0))="","",INDEX(RUNS!$E$6:$E$1005,MATCH($D14,RUNS!$A$6:$A$1005,0))),"")) | M14: =IF($D14="","",IFERROR(IF(INDEX(RUNS!$F$6:$F$1005,MATCH($D14,RUNS!$A$6:$A$1005,0))="","",INDEX(RUNS!$F$6:$F$1005,MATCH($D14,RUNS!$A$6:$A$1005,0))),"")) | N14: =IF($D14="","",IFERROR(IF(INDEX(RUNS!$G$6:$G$1005,MATCH($D14,RUNS!$A$6:$A$1005,0))="","",INDEX(RUNS!$G$6:$G$1005,MATCH($D14,RUNS!$A$6:$A$1005,0))),"")) | O14: =IF($D14="","",IFERROR(IF(INDEX(RUNS!$H$6:$H$1005,MATCH($D14,RUNS!$A$6:$A$1005,0))="","",INDEX(RUNS!$H$6:$H$1005,MATCH($D14,RUNS!$A$6:$A$1005,0))),"")) | P14: =IF($D14="","",IFERROR(IF(INDEX(RUNS!$J$6:$J$1005,MATCH($D14,RUNS!$A$6:$A$1005,0))="","",INDEX(RUNS!$J$6:$J$1005,MATCH($D14,RUNS!$A$6:$A$1005,0))),"")) | Q14: =IF($D14="","",IFERROR(IF(INDEX(RUNS!$K$6:$K$1005,MATCH($D14,RUNS!$A$6:$A$1005,0))="","",INDEX(RUNS!$K$6:$K$1005,MATCH($D14,RUNS!$A$6:$A$1005,0))),"")) | R14: =IF(OR($L14="",$K14=""),"",IFERROR(IF(INDEX(PARAMETRES!$H$43:$H$342,MATCH($L14&"|"&$M14&"|"&$N14&"|"&$O14&"|"&$P14&"|"&$Q14&"|"&$K14,PARAMETRES!$J$43:$J$342,0))="","",INDEX(PARAMETRES!$H$43:$H$342,MATCH($L14&"|"&$M14&"|"&$N14&"|"&$O14&"|"&$P14&"|"&$Q14&"|"&$K14,PARAMETRES!$J$43:$J$342,0))),"")) | S14: =IF(OR($G14="",$X14<>"VALIDE"),"",IFERROR(LOOKUP(2,1/(($B$3:$B13=$B14)*($G$3:$G13=$G14)*($X$3:$X13="VALIDE")),$C$3:$C13),"")) | T14: =IF(OR($C14="",$S14=""),"",ROUND(($C14-$S14+IF($C14<$S14,1,0))*1440,0)) | U14: =IF(OR($H14="",$T14="",$T14<=0),"",$H14*60/$T14) | V14: =IF(OR($U14="",$R14="",$R14=0),"",$U14/$R14) | W14: =IF($G14="","",IF($X14="CONTEXTE INCOMPLET","CONTEXTE INCOMPLET",IF($X14="DOUBLON",StatutDoublon,IF($S14="",StatutInitial,IF($R14="",StatutStandardManquant,IF($V14="","DONNEES INSUFFISANTES",IF($V14>=SeuilConforme,StatutConforme,IF($V14>=SeuilSurveiller,StatutSurveiller,StatutSousStandard)))))))) | X14: =IF($G14="","",IF(OR($D14="",$E14="",$F14=""),"CONTEXTE INCOMPLET",IF(COUNTIFS($D$3:$D13,$D14,$E$3:$E13,$E14,$F$3:$F13,$F14,$G$3:$G13,$G14)>0,"DOUBLON","VALIDE")))
A15: =IF(OR($B15="",$G15=""),"",TEXT($B15,"YYYYMMDD")&"-"&SUBSTITUTE($E15," ","")&"-"&$F15&"-"&$G15) | J15: =IF($G15="","",IFERROR(INDEX(NomsEmployes,MATCH($G15,MatriculesEmployes,0)),"MATRICULE INCONNU")) | K15: =IF(OR($D15="",$F15=""),"",IFERROR(IF(INDEX(RUNS!$L$6:$S$1005,MATCH($D15,RUNS!$A$6:$A$1005,0),MATCH("ACTIVITÉ "&$F15,RUNS!$L$5:$S$5,0))="","",INDEX(RUNS!$L$6:$S$1005,MATCH($D15,RUNS!$A$6:$A$1005,0),MATCH("ACTIVITÉ "&$F15,RUNS!$L$5:$S$5,0))),"")) | L15: =IF($D15="","",IFERROR(IF(INDEX(RUNS!$E$6:$E$1005,MATCH($D15,RUNS!$A$6:$A$1005,0))="","",INDEX(RUNS!$E$6:$E$1005,MATCH($D15,RUNS!$A$6:$A$1005,0))),"")) | M15: =IF($D15="","",IFERROR(IF(INDEX(RUNS!$F$6:$F$1005,MATCH($D15,RUNS!$A$6:$A$1005,0))="","",INDEX(RUNS!$F$6:$F$1005,MATCH($D15,RUNS!$A$6:$A$1005,0))),"")) | N15: =IF($D15="","",IFERROR(IF(INDEX(RUNS!$G$6:$G$1005,MATCH($D15,RUNS!$A$6:$A$1005,0))="","",INDEX(RUNS!$G$6:$G$1005,MATCH($D15,RUNS!$A$6:$A$1005,0))),"")) | O15: =IF($D15="","",IFERROR(IF(INDEX(RUNS!$H$6:$H$1005,MATCH($D15,RUNS!$A$6:$A$1005,0))="","",INDEX(RUNS!$H$6:$H$1005,MATCH($D15,RUNS!$A$6:$A$1005,0))),"")) | P15: =IF($D15="","",IFERROR(IF(INDEX(RUNS!$J$6:$J$1005,MATCH($D15,RUNS!$A$6:$A$1005,0))="","",INDEX(RUNS!$J$6:$J$1005,MATCH($D15,RUNS!$A$6:$A$1005,0))),"")) | Q15: =IF($D15="","",IFERROR(IF(INDEX(RUNS!$K$6:$K$1005,MATCH($D15,RUNS!$A$6:$A$1005,0))="","",INDEX(RUNS!$K$6:$K$1005,MATCH($D15,RUNS!$A$6:$A$1005,0))),"")) | R15: =IF(OR($L15="",$K15=""),"",IFERROR(IF(INDEX(PARAMETRES!$H$43:$H$342,MATCH($L15&"|"&$M15&"|"&$N15&"|"&$O15&"|"&$P15&"|"&$Q15&"|"&$K15,PARAMETRES!$J$43:$J$342,0))="","",INDEX(PARAMETRES!$H$43:$H$342,MATCH($L15&"|"&$M15&"|"&$N15&"|"&$O15&"|"&$P15&"|"&$Q15&"|"&$K15,PARAMETRES!$J$43:$J$342,0))),"")) | S15: =IF(OR($G15="",$X15<>"VALIDE"),"",IFERROR(LOOKUP(2,1/(($B$3:$B14=$B15)*($G$3:$G14=$G15)*($X$3:$X14="VALIDE")),$C$3:$C14),"")) | T15: =IF(OR($C15="",$S15=""),"",ROUND(($C15-$S15+IF($C15<$S15,1,0))*1440,0)) | U15: =IF(OR($H15="",$T15="",$T15<=0),"",$H15*60/$T15) | V15: =IF(OR($U15="",$R15="",$R15=0),"",$U15/$R15) | W15: =IF($G15="","",IF($X15="CONTEXTE INCOMPLET","CONTEXTE INCOMPLET",IF($X15="DOUBLON",StatutDoublon,IF($S15="",StatutInitial,IF($R15="",StatutStandardManquant,IF($V15="","DONNEES INSUFFISANTES",IF($V15>=SeuilConforme,StatutConforme,IF($V15>=SeuilSurveiller,StatutSurveiller,StatutSousStandard)))))))) | X15: =IF($G15="","",IF(OR($D15="",$E15="",$F15=""),"CONTEXTE INCOMPLET",IF(COUNTIFS($D$3:$D14,$D15,$E$3:$E14,$E15,$F$3:$F14,$F15,$G$3:$G14,$G15)>0,"DOUBLON","VALIDE")))
... A903: =IF(OR($B903="",$G903=""),"",TEXT($B903,"YYYYMMDD")&"-"&SUBSTITUTE($E903," ","")&"-"&$F903&"-"&$G903) | J903: =IF($G903="","",IFERROR(INDEX(NomsEmployes,MATCH($G903,MatriculesEmployes,0)),"MATRICULE INCONNU")) | K903: =IF(OR($D903="",$F903=""),"",IFERROR(IF(INDEX(RUNS!$L$6:$S$1005,MATCH($D903,RUNS!$A$6:$A$1005,0),MATCH("ACTIVITÉ "&$F903,RUNS!$L$5:$S$5,0))="","",INDEX(RUNS!$L$6:$S$1005,MATCH($D903,RUNS!$A$6:$A$1005,0),MATCH("ACTIVITÉ "&$F903,RUNS!$L$5:$S$5,0))),"")) | L903: =IF($D903="","",IFERROR(IF(INDEX(RUNS!$E$6:$E$1005,MATCH($D903,RUNS!$A$6:$A$1005,0))="","",INDEX(RUNS!$E$6:$E$1005,MATCH($D903,RUNS!$A$6:$A$1005,0))),"")) | M903: =IF($D903="","",IFERROR(IF(INDEX(RUNS!$F$6:$F$1005,MATCH($D903,RUNS!$A$6:$A$1005,0))="","",INDEX(RUNS!$F$6:$F$1005,MATCH($D903,RUNS!$A$6:$A$1005,0))),"")) | N903: =IF($D903="","",IFERROR(IF(INDEX(RUNS!$G$6:$G$1005,MATCH($D903,RUNS!$A$6:$A$1005,0))="","",INDEX(RUNS!$G$6:$G$1005,MATCH($D903,RUNS!$A$6:$A$1005,0))),"")) | O903: =IF($D903="","",IFERROR(IF(INDEX(RUNS!$H$6:$H$1005,MATCH($D903,RUNS!$A$6:$A$1005,0))="","",INDEX(RUNS!$H$6:$H$1005,MATCH($D903,RUNS!$A$6:$A$1005,0))),"")) | P903: =IF($D903="","",IFERROR(IF(INDEX(RUNS!$J$6:$J$1005,MATCH($D903,RUNS!$A$6:$A$1005,0))="","",INDEX(RUNS!$J$6:$J$1005,MATCH($D903,RUNS!$A$6:$A$1005,0))),"")) | Q903: =IF($D903="","",IFERROR(IF(INDEX(RUNS!$K$6:$K$1005,MATCH($D903,RUNS!$A$6:$A$1005,0))="","",INDEX(RUNS!$K$6:$K$1005,MATCH($D903,RUNS!$A$6:$A$1005,0))),"")) | R903: =IF(OR($L903="",$K903=""),"",IFERROR(IF(INDEX(PARAMETRES!$H$43:$H$342,MATCH($L903&"|"&$M903&"|"&$N903&"|"&$O903&"|"&$P903&"|"&$Q903&"|"&$K903,PARAMETRES!$J$43:$J$342,0))="","",INDEX(PARAMETRES!$H$43:$H$342,MATCH($L903&"|"&$M903&"|"&$N903&"|"&$O903&"|"&$P903&"|"&$Q903&"|"&$K903,PARAMETRES!$J$43:$J$342,0))),"")) | S903: =IF(OR($G903="",$X903<>"VALIDE"),"",IFERROR(LOOKUP(2,1/(($B$3:$B902=$B903)*($G$3:$G902=$G903)*($X$3:$X902="VALIDE")),$C$3:$C902),"")) | T903: =IF(OR($C903="",$S903=""),"",ROUND(($C903-$S903+IF($C903<$S903,1,0))*1440,0)) | U903: =IF(OR($H903="",$T903="",$T903<=0),"",$H903*60/$T903) | V903: =IF(OR($U903="",$R903="",$R903=0),"",$U903/$R903) | W903: =IF($G903="","",IF($X903="CONTEXTE INCOMPLET","CONTEXTE INCOMPLET",IF($X903="DOUBLON",StatutDoublon,IF($S903="",StatutInitial,IF($R903="",StatutStandardManquant,IF($V903="","DONNEES INSUFFISANTES",IF($V903>=SeuilConforme,StatutConforme,IF($V903>=SeuilSurveiller,StatutSurveiller,StatutSousStandard)))))))) | X903: =IF($G903="","",IF(OR($D903="",$E903="",$F903=""),"CONTEXTE INCOMPLET",IF(COUNTIFS($D$3:$D902,$D903,$E$3:$E902,$E903,$F$3:$F902,$F903,$G$3:$G902,$G903)>0,"DOUBLON","VALIDE")))
A904: =IF(OR($B904="",$G904=""),"",TEXT($B904,"YYYYMMDD")&"-"&SUBSTITUTE($E904," ","")&"-"&$F904&"-"&$G904) | J904: =IF($G904="","",IFERROR(INDEX(NomsEmployes,MATCH($G904,MatriculesEmployes,0)),"MATRICULE INCONNU")) | K904: =IF(OR($D904="",$F904=""),"",IFERROR(IF(INDEX(RUNS!$L$6:$S$1005,MATCH($D904,RUNS!$A$6:$A$1005,0),MATCH("ACTIVITÉ "&$F904,RUNS!$L$5:$S$5,0))="","",INDEX(RUNS!$L$6:$S$1005,MATCH($D904,RUNS!$A$6:$A$1005,0),MATCH("ACTIVITÉ "&$F904,RUNS!$L$5:$S$5,0))),"")) | L904: =IF($D904="","",IFERROR(IF(INDEX(RUNS!$E$6:$E$1005,MATCH($D904,RUNS!$A$6:$A$1005,0))="","",INDEX(RUNS!$E$6:$E$1005,MATCH($D904,RUNS!$A$6:$A$1005,0))),"")) | M904: =IF($D904="","",IFERROR(IF(INDEX(RUNS!$F$6:$F$1005,MATCH($D904,RUNS!$A$6:$A$1005,0))="","",INDEX(RUNS!$F$6:$F$1005,MATCH($D904,RUNS!$A$6:$A$1005,0))),"")) | N904: =IF($D904="","",IFERROR(IF(INDEX(RUNS!$G$6:$G$1005,MATCH($D904,RUNS!$A$6:$A$1005,0))="","",INDEX(RUNS!$G$6:$G$1005,MATCH($D904,RUNS!$A$6:$A$1005,0))),"")) | O904: =IF($D904="","",IFERROR(IF(INDEX(RUNS!$H$6:$H$1005,MATCH($D904,RUNS!$A$6:$A$1005,0))="","",INDEX(RUNS!$H$6:$H$1005,MATCH($D904,RUNS!$A$6:$A$1005,0))),"")) | P904: =IF($D904="","",IFERROR(IF(INDEX(RUNS!$J$6:$J$1005,MATCH($D904,RUNS!$A$6:$A$1005,0))="","",INDEX(RUNS!$J$6:$J$1005,MATCH($D904,RUNS!$A$6:$A$1005,0))),"")) | Q904: =IF($D904="","",IFERROR(IF(INDEX(RUNS!$K$6:$K$1005,MATCH($D904,RUNS!$A$6:$A$1005,0))="","",INDEX(RUNS!$K$6:$K$1005,MATCH($D904,RUNS!$A$6:$A$1005,0))),"")) | R904: =IF(OR($L904="",$K904=""),"",IFERROR(IF(INDEX(PARAMETRES!$H$43:$H$342,MATCH($L904&"|"&$M904&"|"&$N904&"|"&$O904&"|"&$P904&"|"&$Q904&"|"&$K904,PARAMETRES!$J$43:$J$342,0))="","",INDEX(PARAMETRES!$H$43:$H$342,MATCH($L904&"|"&$M904&"|"&$N904&"|"&$O904&"|"&$P904&"|"&$Q904&"|"&$K904,PARAMETRES!$J$43:$J$342,0))),"")) | S904: =IF(OR($G904="",$X904<>"VALIDE"),"",IFERROR(LOOKUP(2,1/(($B4:$B903=$B904)*($G4:$G903=$G904)*($X4:$X903="VALIDE")),$C4:$C903),"")) | T904: =IF(OR($C904="",$S904=""),"",ROUND(($C904-$S904+IF($C904<$S904,1,0))*1440,0)) | U904: =IF(OR($H904="",$T904="",$T904<=0),"",$H904*60/$T904) | V904: =IF(OR($U904="",$R904="",$R904=0),"",$U904/$R904) | W904: =IF($G904="","",IF($X904="CONTEXTE INCOMPLET","CONTEXTE INCOMPLET",IF($X904="DOUBLON",StatutDoublon,IF($S904="",StatutInitial,IF($R904="",StatutStandardManquant,IF($V904="","DONNEES INSUFFISANTES",IF($V904>=SeuilConforme,StatutConforme,IF($V904>=SeuilSurveiller,StatutSurveiller,StatutSousStandard)))))))) | X904: =IF($G904="","",IF(OR($D904="",$E904="",$F904=""),"CONTEXTE INCOMPLET",IF(COUNTIFS($D4:$D903,$D904,$E4:$E903,$E904,$F4:$F903,$F904,$G4:$G903,$G904)>0,"DOUBLON","VALIDE")))
