Workbook
Name ListeLignes: #REF!
Name ListeMotifs: PARAMETRES!$E$5:$E$18
Name ListeProduits: PARAMETRES!$A$5:$A$24
Name SeuilAlerte: PARAMETRES!$B$2

Sheet Fiche Jour
A1: CADENCES MO (GRATTAGE)
A2: Date | B2: 46251 | D2: Produit | F2: FMHOEV BIO | J2: Standard boites/h/femme | M2: =IFERROR(INDEX(PARAMETRES!$B$5:$B$24,MATCH($F$2,PARAMETRES!$A$5:$A$24,0)),"") -> 112
A4: LIGNE 1 | H4: LIGNE 2 | O4: LIGNE 3 | V4: LIGNE 4
A5: Demarrage | B5: 0.36458333 | C5: Effectif | D5: 11 | H5: Demarrage | I5: 0.36458333 | J5: Effectif | K5: 11 | O5: Demarrage | P5: 0.36458333 | Q5: Effectif | R5: 13 | V5: Demarrage | W5: 0.33333333 | X5: Effectif
A6: Heure controle | B6: Arret (min) | C6: Motif d'arret | D6: Duree nette (h) | E6: Nb boites | F6: Nbre Femmes | G6: Cadence boites/h/femme | H6: Heure controle | I6: Arret (min) | J6: Motif d'arret | K6: Duree nette (h) | L6: Nb boites | M6: Nbre Femmes | N6: Cadence boites/h/femme | O6: Heure controle | P6: Arret (min) | Q6: Motif d'arret | R6: Duree nette (h) | S6: Nb boites | T6: Nbre Femmes | U6: Cadence boites/h/femme | V6: Heure controle | W6: Arret (min) | X6: Motif d'arret | Y6: Duree nette (h) | Z6: Nb boites | AA6: Nbre Femmes | AB6: Cadence boites/h/femme
A7: 0.40625 | D7: =IF(A7="","",(A7-$B$5+IF(A7<$B$5,1,0))*24-IF(B7="",0,B7)/60) -> 1 | E7: 1008 | F7: =IF($D$5="","",$D$5) -> 11 | G7: =IF(OR(E7="",F7="",F7=0,D7="",D7<=0),"",E7/D7/F7) -> 91.636364 | H7: 0.40625 | K7: =IF(H7="","",(H7-$I$5+IF(H7<$I$5,1,0))*24-IF(I7="",0,I7)/60) -> 1 | L7: 980 | M7: =IF($K$5="","",$K$5) -> 11 | N7: =IF(OR(L7="",M7="",M7=0,K7="",K7<=0),"",L7/K7/M7) -> 89.090909 | O7: 0.40625 | R7: =IF(O7="","",(O7-$P$5+IF(O7<$P$5,1,0))*24-IF(P7="",0,P7)/60) -> 1 | S7: 1008 | T7: =IF($R$5="","",$R$5) -> 13 | U7: =IF(OR(S7="",T7="",T7=0,R7="",R7<=0),"",S7/R7/T7) -> 77.538462 | Y7: =IF(V7="","",(V7-$W$5+IF(V7<$W$5,1,0))*24-IF(W7="",0,W7)/60) | AA7: =IF($Y$5="","",$Y$5) | AB7: =IF(OR(Z7="",AA7="",AA7=0,Y7="",Y7<=0),"",Z7/Y7/AA7) | AD7: =IF(D7="",0,D7) -> 1 | AE7: =IF(K7="",0,K7) -> 1 | AF7: =IF(R7="",0,R7) -> 1 | AG7: =IF(Y7="",0,Y7) -> 0 | AH7: =IF(F7="",0,F7) -> 11 | AI7: =IF(M7="",0,M7) -> 11 | AJ7: =IF(T7="",0,T7) -> 13 | AK7: =IF(AA7="",0,AA7) -> 0
A8: 0.44791667 | D8: =IF(A8="","",(A8-IFERROR(LOOKUP(2,1/($A$7:A7<>""),$A$7:A7),$B$5)+IF(A8<IFERROR(LOOKUP(2,1/($A$7:A7<>""),$A$7:A7),$B$5),1,0))*24-IF(B8="",0,B8)/60) -> 1 | E8: 1260 | F8: =IF($D$5="","",$D$5) -> 11 | G8: =IF(OR(E8="",F8="",F8=0,D8="",D8<=0),"",E8/D8/F8) -> 114.54545 | H8: 0.44791667 | K8: =IF(H8="","",(H8-IFERROR(LOOKUP(2,1/($H$7:H7<>""),$H$7:H7),$I$5)+IF(H8<IFERROR(LOOKUP(2,1/($H$7:H7<>""),$H$7:H7),$I$5),1,0))*24-IF(I8="",0,I8)/60) -> 1 | L8: 1148 | M8: =IF($K$5="","",$K$5) -> 11 | N8: =IF(OR(L8="",M8="",M8=0,K8="",K8<=0),"",L8/K8/M8) -> 104.36364 | O8: 0.44791667 | R8: =IF(O8="","",(O8-IFERROR(LOOKUP(2,1/($O$7:O7<>""),$O$7:O7),$P$5)+IF(O8<IFERROR(LOOKUP(2,1/($O$7:O7<>""),$O$7:O7),$P$5),1,0))*24-IF(P8="",0,P8)/60) -> 1 | S8: 1428 | T8: =IF($R$5="","",$R$5) -> 13 | U8: =IF(OR(S8="",T8="",T8=0,R8="",R8<=0),"",S8/R8/T8) -> 109.84615 | Y8: =IF(V8="","",(V8-IFERROR(LOOKUP(2,1/($V$7:V7<>""),$V$7:V7),$W$5)+IF(V8<IFERROR(LOOKUP(2,1/($V$7:V7<>""),$V$7:V7),$W$5),1,0))*24-IF(W8="",0,W8)/60) | AA8: =IF($Y$5="","",$Y$5) | AB8: =IF(OR(Z8="",AA8="",AA8=0,Y8="",Y8<=0),"",Z8/Y8/AA8) | AD8: =IF(D8="",0,D8) -> 1 | AE8: =IF(K8="",0,K8) -> 1 | AF8: =IF(R8="",0,R8) -> 1 | AG8: =IF(Y8="",0,Y8) -> 0 | AH8: =IF(F8="",0,F8) -> 11 | AI8: =IF(M8="",0,M8) -> 11 | AJ8: =IF(T8="",0,T8) -> 13 | AK8: =IF(AA8="",0,AA8) -> 0
A9: 0.48958333 | D9: =IF(A9="","",(A9-IFERROR(LOOKUP(2,1/($A$7:A8<>""),$A$7:A8),$B$5)+IF(A9<IFERROR(LOOKUP(2,1/($A$7:A8<>""),$A$7:A8),$B$5),1,0))*24-IF(B9="",0,B9)/60) -> 1 | E9: 1204 | F9: =IF($D$5="","",$D$5) -> 11 | G9: =IF(OR(E9="",F9="",F9=0,D9="",D9<=0),"",E9/D9/F9) -> 109.45455 | H9: 0.48958333 | K9: =IF(H9="","",(H9-IFERROR(LOOKUP(2,1/($H$7:H8<>""),$H$7:H8),$I$5)+IF(H9<IFERROR(LOOKUP(2,1/($H$7:H8<>""),$H$7:H8),$I$5),1,0))*24-IF(I9="",0,I9)/60) -> 1 | L9: 1036 | M9: =IF($K$5="","",$K$5) -> 11 | N9: =IF(OR(L9="",M9="",M9=0,K9="",K9<=0),"",L9/K9/M9) -> 94.181818 | O9: 0.48958333 | R9: =IF(O9="","",(O9-IFERROR(LOOKUP(2,1/($O$7:O8<>""),$O$7:O8),$P$5)+IF(O9<IFERROR(LOOKUP(2,1/($O$7:O8<>""),$O$7:O8),$P$5),1,0))*24-IF(P9="",0,P9)/60) -> 1 | S9: 1372 | T9: =IF($R$5="","",$R$5) -> 13 | U9: =IF(OR(S9="",T9="",T9=0,R9="",R9<=0),"",S9/R9/T9) -> 105.53846 | Y9: =IF(V9="","",(V9-IFERROR(LOOKUP(2,1/($V$7:V8<>""),$V$7:V8),$W$5)+IF(V9<IFERROR(LOOKUP(2,1/($V$7:V8<>""),$V$7:V8),$W$5),1,0))*24-IF(W9="",0,W9)/60) | AA9: =IF($Y$5="","",$Y$5) | AB9: =IF(OR(Z9="",AA9="",AA9=0,Y9="",Y9<=0),"",Z9/Y9/AA9) | AD9: =IF(D9="",0,D9) -> 1 | AE9: =IF(K9="",0,K9) -> 1 | AF9: =IF(R9="",0,R9) -> 1 | AG9: =IF(Y9="",0,Y9) -> 0 | AH9: =IF(F9="",0,F9) -> 11 | AI9: =IF(M9="",0,M9) -> 11 | AJ9: =IF(T9="",0,T9) -> 13 | AK9: =IF(AA9="",0,AA9) -> 0
A10: 0.53125 | D10: =IF(A10="","",(A10-IFERROR(LOOKUP(2,1/($A$7:A9<>""),$A$7:A9),$B$5)+IF(A10<IFERROR(LOOKUP(2,1/($A$7:A9<>""),$A$7:A9),$B$5),1,0))*24-IF(B10="",0,B10)/60) -> 1 | E10: 1176 | F10: =IF($D$5="","",$D$5) -> 11 | G10: =IF(OR(E10="",F10="",F10=0,D10="",D10<=0),"",E10/D10/F10) -> 106.90909 | H10: 0.53125 | K10: =IF(H10="","",(H10-IFERROR(LOOKUP(2,1/($H$7:H9<>""),$H$7:H9),$I$5)+IF(H10<IFERROR(LOOKUP(2,1/($H$7:H9<>""),$H$7:H9),$I$5),1,0))*24-IF(I10="",0,I10)/60) -> 1 | L10: 1120 | M10: =IF($K$5="","",$K$5) -> 11 | N10: =IF(OR(L10="",M10="",M10=0,K10="",K10<=0),"",L10/K10/M10) -> 101.81818 | O10: 0.53125 | R10: =IF(O10="","",(O10-IFERROR(LOOKUP(2,1/($O$7:O9<>""),$O$7:O9),$P$5)+IF(O10<IFERROR(LOOKUP(2,1/($O$7:O9<>""),$O$7:O9),$P$5),1,0))*24-IF(P10="",0,P10)/60) -> 1 | S10: 1438 | T10: =IF($R$5="","",$R$5) -> 13 | U10: =IF(OR(S10="",T10="",T10=0,R10="",R10<=0),"",S10/R10/T10) -> 110.61538 | Y10: =IF(V10="","",(V10-IFERROR(LOOKUP(2,1/($V$7:V9<>""),$V$7:V9),$W$5)+IF(V10<IFERROR(LOOKUP(2,1/($V$7:V9<>""),$V$7:V9),$W$5),1,0))*24-IF(W10="",0,W10)/60) | AA10: =IF($Y$5="","",$Y$5) | AB10: =IF(OR(Z10="",AA10="",AA10=0,Y10="",Y10<=0),"",Z10/Y10/AA10) | AD10: =IF(D10="",0,D10) -> 1 | AE10: =IF(K10="",0,K10) -> 1 | AF10: =IF(R10="",0,R10) -> 1 | AG10: =IF(Y10="",0,Y10) -> 0 | AH10: =IF(F10="",0,F10) -> 11 | AI10: =IF(M10="",0,M10) -> 11 | AJ10: =IF(T10="",0,T10) -> 13 | AK10: =IF(AA10="",0,AA10) -> 0
A11: 0.55694444 | D11: =IF(A11="","",(A11-IFERROR(LOOKUP(2,1/($A$7:A10<>""),$A$7:A10),$B$5)+IF(A11<IFERROR(LOOKUP(2,1/($A$7:A10<>""),$A$7:A10),$B$5),1,0))*24-IF(B11="",0,B11)/60) -> 0.61666667 | E11: 716 | F11: =IF($D$5="","",$D$5) -> 11 | G11: =IF(OR(E11="",F11="",F11=0,D11="",D11<=0),"",E11/D11/F11) -> 105.55283 | H11: 0.55694444 | K11: =IF(H11="","",(H11-IFERROR(LOOKUP(2,1/($H$7:H10<>""),$H$7:H10),$I$5)+IF(H11<IFERROR(LOOKUP(2,1/($H$7:H10<>""),$H$7:H10),$I$5),1,0))*24-IF(I11="",0,I11)/60) -> 0.61666667 | L11: 493 | M11: =IF($K$5="","",$K$5) -> 11 | N11: =IF(OR(L11="",M11="",M11=0,K11="",K11<=0),"",L11/K11/M11) -> 72.678133 | O11: 0.55694444 | R11: =IF(O11="","",(O11-IFERROR(LOOKUP(2,1/($O$7:O10<>""),$O$7:O10),$P$5)+IF(O11<IFERROR(LOOKUP(2,1/($O$7:O10<>""),$O$7:O10),$P$5),1,0))*24-IF(P11="",0,P11)/60) -> 0.61666667 | S11: 511 | T11: =IF($R$5="","",$R$5) -> 13 | U11: =IF(OR(S11="",T11="",T11=0,R11="",R11<=0),"",S11/R11/T11) -> 63.742204 | Y11: =IF(V11="","",(V11-IFERROR(LOOKUP(2,1/($V$7:V10<>""),$V$7:V10),$W$5)+IF(V11<IFERROR(LOOKUP(2,1/($V$7:V10<>""),$V$7:V10),$W$5),1,0))*24-IF(W11="",0,W11)/60) | AA11: =IF($Y$5="","",$Y$5) | AB11: =IF(OR(Z11="",AA11="",AA11=0,Y11="",Y11<=0),"",Z11/Y11/AA11) | AD11: =IF(D11="",0,D11) -> 0.61666667 | AE11: =IF(K11="",0,K11) -> 0.61666667 | AF11: =IF(R11="",0,R11) -> 0.61666667 | AG11: =IF(Y11="",0,Y11) -> 0 | AH11: =IF(F11="",0,F11) -> 11 | AI11: =IF(M11="",0,M11) -> 11 | AJ11: =IF(T11="",0,T11) -> 13 | AK11: =IF(AA11="",0,AA11) -> 0
A12: 0.64236111 | B12: 70 | C12: Pause repas / reglementaire | D12: =IF(A12="","",(A12-IFERROR(LOOKUP(2,1/($A$7:A11<>""),$A$7:A11),$B$5)+IF(A12<IFERROR(LOOKUP(2,1/($A$7:A11<>""),$A$7:A11),$B$5),1,0))*24-IF(B12="",0,B12)/60) -> 0.88333333 | E12: 1419 | F12: =IF($D$5="","",$D$5) -> 11 | G12: =IF(OR(E12="",F12="",F12=0,D12="",D12<=0),"",E12/D12/F12) -> 146.03774 | H12: 0.64236111 | I12: 70 | J12: Pause repas / reglementaire | K12: =IF(H12="","",(H12-IFERROR(LOOKUP(2,1/($H$7:H11<>""),$H$7:H11),$I$5)+IF(H12<IFERROR(LOOKUP(2,1/($H$7:H11<>""),$H$7:H11),$I$5),1,0))*24-IF(I12="",0,I12)/60) -> 0.88333333 | L12: 1392 | M12: =IF($K$5="","",$K$5) -> 11 | N12: =IF(OR(L12="",M12="",M12=0,K12="",K12<=0),"",L12/K12/M12) -> 143.25901 | O12: 0.64236111 | P12: 70 | Q12: Pause repas / reglementaire | R12: =IF(O12="","",(O12-IFERROR(LOOKUP(2,1/($O$7:O11<>""),$O$7:O11),$P$5)+IF(O12<IFERROR(LOOKUP(2,1/($O$7:O11<>""),$O$7:O11),$P$5),1,0))*24-IF(P12="",0,P12)/60) -> 0.88333333 | S12: 2417 | T12: =IF($R$5="","",$R$5) -> 13 | U12: =IF(OR(S12="",T12="",T12=0,R12="",R12<=0),"",S12/R12/T12) -> 210.47896 | Y12: =IF(V12="","",(V12-IFERROR(LOOKUP(2,1/($V$7:V11<>""),$V$7:V11),$W$5)+IF(V12<IFERROR(LOOKUP(2,1/($V$7:V11<>""),$V$7:V11),$W$5),1,0))*24-IF(W12="",0,W12)/60) | AA12: =IF($Y$5="","",$Y$5) | AB12: =IF(OR(Z12="",AA12="",AA12=0,Y12="",Y12<=0),"",Z12/Y12/AA12) | AD12: =IF(D12="",0,D12) -> 0.88333333 | AE12: =IF(K12="",0,K12) -> 0.88333333 | AF12: =IF(R12="",0,R12) -> 0.88333333 | AG12: =IF(Y12="",0,Y12) -> 0 | AH12: =IF(F12="",0,F12) -> 11 | AI12: =IF(M12="",0,M12) -> 11 | AJ12: =IF(T12="",0,T12) -> 13 | AK12: =IF(AA12="",0,AA12) -> 0
D13: =IF(A13="","",(A13-IFERROR(LOOKUP(2,1/($A$7:A12<>""),$A$7:A12),$B$5)+IF(A13<IFERROR(LOOKUP(2,1/($A$7:A12<>""),$A$7:A12),$B$5),1,0))*24-IF(B13="",0,B13)/60) | F13: =IF($D$5="","",$D$5) -> 11 | G13: =IF(OR(E13="",F13="",F13=0,D13="",D13<=0),"",E13/D13/F13) | K13: =IF(H13="","",(H13-IFERROR(LOOKUP(2,1/($H$7:H12<>""),$H$7:H12),$I$5)+IF(H13<IFERROR(LOOKUP(2,1/($H$7:H12<>""),$H$7:H12),$I$5),1,0))*24-IF(I13="",0,I13)/60) | M13: =IF($K$5="","",$K$5) -> 11 | N13: =IF(OR(L13="",M13="",M13=0,K13="",K13<=0),"",L13/K13/M13) | R13: =IF(O13="","",(O13-IFERROR(LOOKUP(2,1/($O$7:O12<>""),$O$7:O12),$P$5)+IF(O13<IFERROR(LOOKUP(2,1/($O$7:O12<>""),$O$7:O12),$P$5),1,0))*24-IF(P13="",0,P13)/60) | T13: =IF($R$5="","",$R$5) -> 13 | U13: =IF(OR(S13="",T13="",T13=0,R13="",R13<=0),"",S13/R13/T13) | Y13: =IF(V13="","",(V13-IFERROR(LOOKUP(2,1/($V$7:V12<>""),$V$7:V12),$W$5)+IF(V13<IFERROR(LOOKUP(2,1/($V$7:V12<>""),$V$7:V12),$W$5),1,0))*24-IF(W13="",0,W13)/60) | AA13: =IF($Y$5="","",$Y$5) | AB13: =IF(OR(Z13="",AA13="",AA13=0,Y13="",Y13<=0),"",Z13/Y13/AA13) | AD13: =IF(D13="",0,D13) -> 0 | AE13: =IF(K13="",0,K13) -> 0 | AF13: =IF(R13="",0,R13) -> 0 | AG13: =IF(Y13="",0,Y13) -> 0 | AH13: =IF(F13="",0,F13) -> 11 | AI13: =IF(M13="",0,M13) -> 11 | AJ13: =IF(T13="",0,T13) -> 13 | AK13: =IF(AA13="",0,AA13) -> 0
D14: =IF(A14="","",(A14-IFERROR(LOOKUP(2,1/($A$7:A13<>""),$A$7:A13),$B$5)+IF(A14<IFERROR(LOOKUP(2,1/($A$7:A13<>""),$A$7:A13),$B$5),1,0))*24-IF(B14="",0,B14)/60) | F14: =IF($D$5="","",$D$5) -> 11 | G14: =IF(OR(E14="",F14="",F14=0,D14="",D14<=0),"",E14/D14/F14) | K14: =IF(H14="","",(H14-IFERROR(LOOKUP(2,1/($H$7:H13<>""),$H$7:H13),$I$5)+IF(H14<IFERROR(LOOKUP(2,1/($H$7:H13<>""),$H$7:H13),$I$5),1,0))*24-IF(I14="",0,I14)/60) | M14: =IF($K$5="","",$K$5) -> 11 | N14: =IF(OR(L14="",M14="",M14=0,K14="",K14<=0),"",L14/K14/M14) | R14: =IF(O14="","",(O14-IFERROR(LOOKUP(2,1/($O$7:O13<>""),$O$7:O13),$P$5)+IF(O14<IFERROR(LOOKUP(2,1/($O$7:O13<>""),$O$7:O13),$P$5),1,0))*24-IF(P14="",0,P14)/60) | T14: =IF($R$5="","",$R$5) -> 13 | U14: =IF(OR(S14="",T14="",T14=0,R14="",R14<=0),"",S14/R14/T14) | Y14: =IF(V14="","",(V14-IFERROR(LOOKUP(2,1/($V$7:V13<>""),$V$7:V13),$W$5)+IF(V14<IFERROR(LOOKUP(2,1/($V$7:V13<>""),$V$7:V13),$W$5),1,0))*24-IF(W14="",0,W14)/60) | AA14: =IF($Y$5="","",$Y$5) | AB14: =IF(OR(Z14="",AA14="",AA14=0,Y14="",Y14<=0),"",Z14/Y14/AA14) | AD14: =IF(D14="",0,D14) -> 0 | AE14: =IF(K14="",0,K14) -> 0 | AF14: =IF(R14="",0,R14) -> 0 | AG14: =IF(Y14="",0,Y14) -> 0 | AH14: =IF(F14="",0,F14) -> 11 | AI14: =IF(M14="",0,M14) -> 11 | AJ14: =IF(T14="",0,T14) -> 13 | AK14: =IF(AA14="",0,AA14) -> 0
D15: =IF(A15="","",(A15-IFERROR(LOOKUP(2,1/($A$7:A14<>""),$A$7:A14),$B$5)+IF(A15<IFERROR(LOOKUP(2,1/($A$7:A14<>""),$A$7:A14),$B$5),1,0))*24-IF(B15="",0,B15)/60) | F15: =IF($D$5="","",$D$5) -> 11 | G15: =IF(OR(E15="",F15="",F15=0,D15="",D15<=0),"",E15/D15/F15) | K15: =IF(H15="","",(H15-IFERROR(LOOKUP(2,1/($H$7:H14<>""),$H$7:H14),$I$5)+IF(H15<IFERROR(LOOKUP(2,1/($H$7:H14<>""),$H$7:H14),$I$5),1,0))*24-IF(I15="",0,I15)/60) | M15: =IF($K$5="","",$K$5) -> 11 | N15: =IF(OR(L15="",M15="",M15=0,K15="",K15<=0),"",L15/K15/M15) | R15: =IF(O15="","",(O15-IFERROR(LOOKUP(2,1/($O$7:O14<>""),$O$7:O14),$P$5)+IF(O15<IFERROR(LOOKUP(2,1/($O$7:O14<>""),$O$7:O14),$P$5),1,0))*24-IF(P15="",0,P15)/60) | T15: =IF($R$5="","",$R$5) -> 13 | U15: =IF(OR(S15="",T15="",T15=0,R15="",R15<=0),"",S15/R15/T15) | Y15: =IF(V15="","",(V15-IFERROR(LOOKUP(2,1/($V$7:V14<>""),$V$7:V14),$W$5)+IF(V15<IFERROR(LOOKUP(2,1/($V$7:V14<>""),$V$7:V14),$W$5),1,0))*24-IF(W15="",0,W15)/60) | AA15: =IF($Y$5="","",$Y$5) | AB15: =IF(OR(Z15="",AA15="",AA15=0,Y15="",Y15<=0),"",Z15/Y15/AA15) | AD15: =IF(D15="",0,D15) -> 0 | AE15: =IF(K15="",0,K15) -> 0 | AF15: =IF(R15="",0,R15) -> 0 | AG15: =IF(Y15="",0,Y15) -> 0 | AH15: =IF(F15="",0,F15) -> 11 | AI15: =IF(M15="",0,M15) -> 11 | AJ15: =IF(T15="",0,T15) -> 13 | AK15: =IF(AA15="",0,AA15) -> 0
D16: =IF(A16="","",(A16-IFERROR(LOOKUP(2,1/($A$7:A15<>""),$A$7:A15),$B$5)+IF(A16<IFERROR(LOOKUP(2,1/($A$7:A15<>""),$A$7:A15),$B$5),1,0))*24-IF(B16="",0,B16)/60) | F16: =IF($D$5="","",$D$5) -> 11 | G16: =IF(OR(E16="",F16="",F16=0,D16="",D16<=0),"",E16/D16/F16) | K16: =IF(H16="","",(H16-IFERROR(LOOKUP(2,1/($H$7:H15<>""),$H$7:H15),$I$5)+IF(H16<IFERROR(LOOKUP(2,1/($H$7:H15<>""),$H$7:H15),$I$5),1,0))*24-IF(I16="",0,I16)/60) | M16: =IF($K$5="","",$K$5) -> 11 | N16: =IF(OR(L16="",M16="",M16=0,K16="",K16<=0),"",L16/K16/M16) | R16: =IF(O16="","",(O16-IFERROR(LOOKUP(2,1/($O$7:O15<>""),$O$7:O15),$P$5)+IF(O16<IFERROR(LOOKUP(2,1/($O$7:O15<>""),$O$7:O15),$P$5),1,0))*24-IF(P16="",0,P16)/60) | T16: =IF($R$5="","",$R$5) -> 13 | U16: =IF(OR(S16="",T16="",T16=0,R16="",R16<=0),"",S16/R16/T16) | Y16: =IF(V16="","",(V16-IFERROR(LOOKUP(2,1/($V$7:V15<>""),$V$7:V15),$W$5)+IF(V16<IFERROR(LOOKUP(2,1/($V$7:V15<>""),$V$7:V15),$W$5),1,0))*24-IF(W16="",0,W16)/60) | AA16: =IF($Y$5="","",$Y$5) | AB16: =IF(OR(Z16="",AA16="",AA16=0,Y16="",Y16<=0),"",Z16/Y16/AA16) | AD16: =IF(D16="",0,D16) -> 0 | AE16: =IF(K16="",0,K16) -> 0 | AF16: =IF(R16="",0,R16) -> 0 | AG16: =IF(Y16="",0,Y16) -> 0 | AH16: =IF(F16="",0,F16) -> 11 | AI16: =IF(M16="",0,M16) -> 11 | AJ16: =IF(T16="",0,T16) -> 13 | AK16: =IF(AA16="",0,AA16) -> 0
D17: =IF(A17="","",(A17-IFERROR(LOOKUP(2,1/($A$7:A16<>""),$A$7:A16),$B$5)+IF(A17<IFERROR(LOOKUP(2,1/($A$7:A16<>""),$A$7:A16),$B$5),1,0))*24-IF(B17="",0,B17)/60) | F17: =IF($D$5="","",$D$5) -> 11 | G17: =IF(OR(E17="",F17="",F17=0,D17="",D17<=0),"",E17/D17/F17) | K17: =IF(H17="","",(H17-IFERROR(LOOKUP(2,1/($H$7:H16<>""),$H$7:H16),$I$5)+IF(H17<IFERROR(LOOKUP(2,1/($H$7:H16<>""),$H$7:H16),$I$5),1,0))*24-IF(I17="",0,I17)/60) | M17: =IF($K$5="","",$K$5) -> 11 | N17: =IF(OR(L17="",M17="",M17=0,K17="",K17<=0),"",L17/K17/M17) | R17: =IF(O17="","",(O17-IFERROR(LOOKUP(2,1/($O$7:O16<>""),$O$7:O16),$P$5)+IF(O17<IFERROR(LOOKUP(2,1/($O$7:O16<>""),$O$7:O16),$P$5),1,0))*24-IF(P17="",0,P17)/60) | T17: =IF($R$5="","",$R$5) -> 13 | U17: =IF(OR(S17="",T17="",T17=0,R17="",R17<=0),"",S17/R17/T17) | Y17: =IF(V17="","",(V17-IFERROR(LOOKUP(2,1/($V$7:V16<>""),$V$7:V16),$W$5)+IF(V17<IFERROR(LOOKUP(2,1/($V$7:V16<>""),$V$7:V16),$W$5),1,0))*24-IF(W17="",0,W17)/60) | AA17: =IF($Y$5="","",$Y$5) | AB17: =IF(OR(Z17="",AA17="",AA17=0,Y17="",Y17<=0),"",Z17/Y17/AA17) | AD17: =IF(D17="",0,D17) -> 0 | AE17: =IF(K17="",0,K17) -> 0 | AF17: =IF(R17="",0,R17) -> 0 | AG17: =IF(Y17="",0,Y17) -> 0 | AH17: =IF(F17="",0,F17) -> 11 | AI17: =IF(M17="",0,M17) -> 11 | AJ17: =IF(T17="",0,T17) -> 13 | AK17: =IF(AA17="",0,AA17) -> 0
D18: =IF(A18="","",(A18-IFERROR(LOOKUP(2,1/($A$7:A17<>""),$A$7:A17),$B$5)+IF(A18<IFERROR(LOOKUP(2,1/($A$7:A17<>""),$A$7:A17),$B$5),1,0))*24-IF(B18="",0,B18)/60) | F18: =IF($D$5="","",$D$5) -> 11 | G18: =IF(OR(E18="",F18="",F18=0,D18="",D18<=0),"",E18/D18/F18) | K18: =IF(H18="","",(H18-IFERROR(LOOKUP(2,1/($H$7:H17<>""),$H$7:H17),$I$5)+IF(H18<IFERROR(LOOKUP(2,1/($H$7:H17<>""),$H$7:H17),$I$5),1,0))*24-IF(I18="",0,I18)/60) | M18: =IF($K$5="","",$K$5) -> 11 | N18: =IF(OR(L18="",M18="",M18=0,K18="",K18<=0),"",L18/K18/M18) | R18: =IF(O18="","",(O18-IFERROR(LOOKUP(2,1/($O$7:O17<>""),$O$7:O17),$P$5)+IF(O18<IFERROR(LOOKUP(2,1/($O$7:O17<>""),$O$7:O17),$P$5),1,0))*24-IF(P18="",0,P18)/60) | T18: =IF($R$5="","",$R$5) -> 13 | U18: =IF(OR(S18="",T18="",T18=0,R18="",R18<=0),"",S18/R18/T18) | Y18: =IF(V18="","",(V18-IFERROR(LOOKUP(2,1/($V$7:V17<>""),$V$7:V17),$W$5)+IF(V18<IFERROR(LOOKUP(2,1/($V$7:V17<>""),$V$7:V17),$W$5),1,0))*24-IF(W18="",0,W18)/60) | AA18: =IF($Y$5="","",$Y$5) | AB18: =IF(OR(Z18="",AA18="",AA18=0,Y18="",Y18<=0),"",Z18/Y18/AA18) | AD18: =IF(D18="",0,D18) -> 0 | AE18: =IF(K18="",0,K18) -> 0 | AF18: =IF(R18="",0,R18) -> 0 | AG18: =IF(Y18="",0,Y18) -> 0 | AH18: =IF(F18="",0,F18) -> 11 | AI18: =IF(M18="",0,M18) -> 11 | AJ18: =IF(T18="",0,T18) -> 13 | AK18: =IF(AA18="",0,AA18) -> 0
D19: =IF(A19="","",(A19-IFERROR(LOOKUP(2,1/($A$7:A18<>""),$A$7:A18),$B$5)+IF(A19<IFERROR(LOOKUP(2,1/($A$7:A18<>""),$A$7:A18),$B$5),1,0))*24-IF(B19="",0,B19)/60) | F19: =IF($D$5="","",$D$5) -> 11 | G19: =IF(OR(E19="",F19="",F19=0,D19="",D19<=0),"",E19/D19/F19) | K19: =IF(H19="","",(H19-IFERROR(LOOKUP(2,1/($H$7:H18<>""),$H$7:H18),$I$5)+IF(H19<IFERROR(LOOKUP(2,1/($H$7:H18<>""),$H$7:H18),$I$5),1,0))*24-IF(I19="",0,I19)/60) | M19: =IF($K$5="","",$K$5) -> 11 | N19: =IF(OR(L19="",M19="",M19=0,K19="",K19<=0),"",L19/K19/M19) | R19: =IF(O19="","",(O19-IFERROR(LOOKUP(2,1/($O$7:O18<>""),$O$7:O18),$P$5)+IF(O19<IFERROR(LOOKUP(2,1/($O$7:O18<>""),$O$7:O18),$P$5),1,0))*24-IF(P19="",0,P19)/60) | T19: =IF($R$5="","",$R$5) -> 13 | U19: =IF(OR(S19="",T19="",T19=0,R19="",R19<=0),"",S19/R19/T19) | Y19: =IF(V19="","",(V19-IFERROR(LOOKUP(2,1/($V$7:V18<>""),$V$7:V18),$W$5)+IF(V19<IFERROR(LOOKUP(2,1/($V$7:V18<>""),$V$7:V18),$W$5),1,0))*24-IF(W19="",0,W19)/60) | AA19: =IF($Y$5="","",$Y$5) | AB19: =IF(OR(Z19="",AA19="",AA19=0,Y19="",Y19<=0),"",Z19/Y19/AA19) | AD19: =IF(D19="",0,D19) -> 0 | AE19: =IF(K19="",0,K19) -> 0 | AF19: =IF(R19="",0,R19) -> 0 | AG19: =IF(Y19="",0,Y19) -> 0 | AH19: =IF(F19="",0,F19) -> 11 | AI19: =IF(M19="",0,M19) -> 11 | AJ19: =IF(T19="",0,T19) -> 13 | AK19: =IF(AA19="",0,AA19) -> 0
D20: =IF(A20="","",(A20-IFERROR(LOOKUP(2,1/($A$7:A19<>""),$A$7:A19),$B$5)+IF(A20<IFERROR(LOOKUP(2,1/($A$7:A19<>""),$A$7:A19),$B$5),1,0))*24-IF(B20="",0,B20)/60) | F20: =IF($D$5="","",$D$5) -> 11 | G20: =IF(OR(E20="",F20="",F20=0,D20="",D20<=0),"",E20/D20/F20) | K20: =IF(H20="","",(H20-IFERROR(LOOKUP(2,1/($H$7:H19<>""),$H$7:H19),$I$5)+IF(H20<IFERROR(LOOKUP(2,1/($H$7:H19<>""),$H$7:H19),$I$5),1,0))*24-IF(I20="",0,I20)/60) | M20: =IF($K$5="","",$K$5) -> 11 | N20: =IF(OR(L20="",M20="",M20=0,K20="",K20<=0),"",L20/K20/M20) | R20: =IF(O20="","",(O20-IFERROR(LOOKUP(2,1/($O$7:O19<>""),$O$7:O19),$P$5)+IF(O20<IFERROR(LOOKUP(2,1/($O$7:O19<>""),$O$7:O19),$P$5),1,0))*24-IF(P20="",0,P20)/60) | T20: =IF($R$5="","",$R$5) -> 13 | U20: =IF(OR(S20="",T20="",T20=0,R20="",R20<=0),"",S20/R20/T20) | Y20: =IF(V20="","",(V20-IFERROR(LOOKUP(2,1/($V$7:V19<>""),$V$7:V19),$W$5)+IF(V20<IFERROR(LOOKUP(2,1/($V$7:V19<>""),$V$7:V19),$W$5),1,0))*24-IF(W20="",0,W20)/60) | AA20: =IF($Y$5="","",$Y$5) | AB20: =IF(OR(Z20="",AA20="",AA20=0,Y20="",Y20<=0),"",Z20/Y20/AA20) | AD20: =IF(D20="",0,D20) -> 0 | AE20: =IF(K20="",0,K20) -> 0 | AF20: =IF(R20="",0,R20) -> 0 | AG20: =IF(Y20="",0,Y20) -> 0 | AH20: =IF(F20="",0,F20) -> 11 | AI20: =IF(M20="",0,M20) -> 11 | AJ20: =IF(T20="",0,T20) -> 13 | AK20: =IF(AA20="",0,AA20) -> 0
A21: TOTAL | B21: =SUM(B7:B20) -> 70 | C21: =COUNTIF(B7:B20,">0")&" arret(s)" -> 1 arret(s) | D21: =SUM(D7:D20) -> 5.5 | E21: =SUM(E7:E20) -> 6783 | F21: =IF(OR(SUM($D$7:$D$20)=0,SUMPRODUCT($AD$7:$AD$20*$AH$7:$AH$20)=0),"",SUMPRODUCT($AD$7:$AD$20*$AH$7:$AH$20)/SUM($D$7:$D$20)) -> 11 | G21: =IF(OR($D$21=0,$F$21="",$F$21=0),"",$E$21/$D$21/$F$21) -> 112.1157 | H21: TOTAL | I21: =SUM(I7:I20) -> 70 | J21: =COUNTIF(I7:I20,">0")&" arret(s)" -> 1 arret(s) | K21: =SUM(K7:K20) -> 5.5 | L21: =SUM(L7:L20) -> 6169 | M21: =IF(OR(SUM($K$7:$K$20)=0,SUMPRODUCT($AE$7:$AE$20*$AI$7:$AI$20)=0),"",SUMPRODUCT($AE$7:$AE$20*$AI$7:$AI$20)/SUM($K$7:$K$20)) -> 11 | N21: =IF(OR($K$21=0,$M$21="",$M$21=0),"",$L$21/$K$21/$M$21) -> 101.96694 | O21: TOTAL | P21: =SUM(P7:P20) -> 70 | Q21: =COUNTIF(P7:P20,">0")&" arret(s)" -> 1 arret(s) | R21: =SUM(R7:R20) -> 5.5 | S21: =SUM(S7:S20) -> 8174 | T21: =IF(OR(SUM($R$7:$R$20)=0,SUMPRODUCT($AF$7:$AF$20*$AJ$7:$AJ$20)=0),"",SUMPRODUCT($AF$7:$AF$20*$AJ$7:$AJ$20)/SUM($R$7:$R$20)) -> 13 | U21: =IF(OR($R$21=0,$T$21="",$T$21=0),"",$S$21/$R$21/$T$21) -> 114.32168 | V21: TOTAL | W21: =SUM(W7:W20) -> 0 | X21: =COUNTIF(W7:W20,">0")&" arret(s)" -> 0 arret(s) | Y21: =SUM(Y7:Y20) -> 0 | Z21: =SUM(Z7:Z20) -> 0 | AA21: =IF(OR(SUM($Y$7:$Y$20)=0,SUMPRODUCT($AG$7:$AG$20*$AK$7:$AK$20)=0),"",SUMPRODUCT($AG$7:$AG$20*$AK$7:$AK$20)/SUM($Y$7:$Y$20)) | AB21: =IF(OR($Y$21=0,$AA$21="",$AA$21=0),"",$Z$21/$Y$21/$AA$21)
A23: SYNTHESE DU JOUR
A24: Ligne | B24: Nb boites | C24: Duree nette (h) | D24: Total arret (min) | E24: Nbre femmes | F24: Cadence boites/h/femme | G24: Cadence ligne (boites/h) | H24: % atteinte | I24: Ecart vs standard
A25: ="Ligne 1" -> Ligne 1 | B25: =$E$21 -> 6783 | C25: =$D$21 -> 5.5 | D25: =$B$21 -> 70 | E25: =$F$21 -> 11 | F25: =$G$21 -> 112.1157 | G25: =IF(OR($C25="",$C25=0),"",$B25/$C25) -> 1233.2727 | H25: =IF(OR($F25="",NOT(ISNUMBER($M$2)),$M$2=0),"",$F25/$M$2) -> 1.0010331 | I25: =IF(OR($F25="",NOT(ISNUMBER($M$2))),"",$F25-$M$2) -> 0.11570248
A26: ="Ligne 2" -> Ligne 2 | B26: =$L$21 -> 6169 | C26: =$K$21 -> 5.5 | D26: =$I$21 -> 70 | E26: =$M$21 -> 11 | F26: =$N$21 -> 101.96694 | G26: =IF(OR($C26="",$C26=0),"",$B26/$C26) -> 1121.6364 | H26: =IF(OR($F26="",NOT(ISNUMBER($M$2)),$M$2=0),"",$F26/$M$2) -> 0.91041913 | I26: =IF(OR($F26="",NOT(ISNUMBER($M$2))),"",$F26-$M$2) -> -10.033058
A27: ="Ligne 3" -> Ligne 3 | B27: =$S$21 -> 8174 | C27: =$R$21 -> 5.5 | D27: =$P$21 -> 70 | E27: =$T$21 -> 13 | F27: =$U$21 -> 114.32168 | G27: =IF(OR($C27="",$C27=0),"",$B27/$C27) -> 1486.1818 | H27: =IF(OR($F27="",NOT(ISNUMBER($M$2)),$M$2=0),"",$F27/$M$2) -> 1.0207293 | I27: =IF(OR($F27="",NOT(ISNUMBER($M$2))),"",$F27-$M$2) -> 2.3216783
A28: ="Ligne 4" -> Ligne 4 | B28: =$Z$21 -> 0 | C28: =$Y$21 -> 0 | D28: =$W$21 -> 0 | E28: =$AA$21 | F28: =$AB$21 | G28: =IF(OR($C28="",$C28=0),"",$B28/$C28) | H28: =IF(OR($F28="",NOT(ISNUMBER($M$2)),$M$2=0),"",$F28/$M$2) | I28: =IF(OR($F28="",NOT(ISNUMBER($M$2))),"",$F28-$M$2)
A29: ="TOTAL" -> TOTAL | B29: =SUM($B$25:$B$28) -> 21126 | C29: =SUM($C$25:$C$28) -> 16.5 | D29: =SUM($D$25:$D$28) -> 210 | E29: =IF(COUNT($E$25:$E$28)=0,"",SUM($E$25:$E$28)) -> 35 | F29: =IF(SUMPRODUCT($C$25:$C$28*$K$25:$K$28)=0,"",SUMPRODUCT($B$25:$B$28*$J$25:$J$28)/SUMPRODUCT($C$25:$C$28*$K$25:$K$28)) | G29: =IF(OR($C29="",$C29=0),"",$B29/$C29) -> 1280.3636 | H29: =IF(OR($F29="",NOT(ISNUMBER($M$2)),$M$2=0),"",$F29/$M$2) | I29: =IF(OR($F29="",NOT(ISNUMBER($M$2))),"",$F29-$M$2)
A31: ARRETS DU JOUR PAR MOTIF
A32: Motif d'arret | C32: Total arret (min) | D32: % des arrets | E32: Nb occurrences
A33: =IF(PARAMETRES!$E$5="","",PARAMETRES!$E$5) -> Pause repas / reglementaire | C33: =IF($A33="","",SUMIF($C$7:$C$20,$A33,$B$7:$B$20)+SUMIF($J$7:$J$20,$A33,$I$7:$I$20)+SUMIF($Q$7:$Q$20,$A33,$P$7:$P$20)+SUMIF($X$7:$X$20,$A33,$W$7:$W$20)) -> 210 | D33: =IF(OR($A33="",$C$47=0),"",$C33/$C$47) -> 1 | E33: =IF($A33="","",COUNTIF($C$7:$C$20,$A33)+COUNTIF($J$7:$J$20,$A33)+COUNTIF($Q$7:$Q$20,$A33)+COUNTIF($X$7:$X$20,$A33)) -> 3
A34: =IF(PARAMETRES!$E$6="","",PARAMETRES!$E$6) -> Panne machine | C34: =IF($A34="","",SUMIF($C$7:$C$20,$A34,$B$7:$B$20)+SUMIF($J$7:$J$20,$A34,$I$7:$I$20)+SUMIF($Q$7:$Q$20,$A34,$P$7:$P$20)+SUMIF($X$7:$X$20,$A34,$W$7:$W$20)) -> 0 | D34: =IF(OR($A34="",$C$47=0),"",$C34/$C$47) -> 0 | E34: =IF($A34="","",COUNTIF($C$7:$C$20,$A34)+COUNTIF($J$7:$J$20,$A34)+COUNTIF($Q$7:$Q$20,$A34)+COUNTIF($X$7:$X$20,$A34)) -> 0
A35: =IF(PARAMETRES!$E$7="","",PARAMETRES!$E$7) -> Manque matiere premiere | C35: =IF($A35="","",SUMIF($C$7:$C$20,$A35,$B$7:$B$20)+SUMIF($J$7:$J$20,$A35,$I$7:$I$20)+SUMIF($Q$7:$Q$20,$A35,$P$7:$P$20)+SUMIF($X$7:$X$20,$A35,$W$7:$W$20)) -> 0 | D35: =IF(OR($A35="",$C$47=0),"",$C35/$C$47) -> 0 | E35: =IF($A35="","",COUNTIF($C$7:$C$20,$A35)+COUNTIF($J$7:$J$20,$A35)+COUNTIF($Q$7:$Q$20,$A35)+COUNTIF($X$7:$X$20,$A35)) -> 0
A36: =IF(PARAMETRES!$E$8="","",PARAMETRES!$E$8) -> Changement de lot | C36: =IF($A36="","",SUMIF($C$7:$C$20,$A36,$B$7:$B$20)+SUMIF($J$7:$J$20,$A36,$I$7:$I$20)+SUMIF($Q$7:$Q$20,$A36,$P$7:$P$20)+SUMIF($X$7:$X$20,$A36,$W$7:$W$20)) -> 0 | D36: =IF(OR($A36="",$C$47=0),"",$C36/$C$47) -> 0 | E36: =IF($A36="","",COUNTIF($C$7:$C$20,$A36)+COUNTIF($J$7:$J$20,$A36)+COUNTIF($Q$7:$Q$20,$A36)+COUNTIF($X$7:$X$20,$A36)) -> 0
A37: =IF(PARAMETRES!$E$9="","",PARAMETRES!$E$9) -> Nettoyage / sanitation | C37: =IF($A37="","",SUMIF($C$7:$C$20,$A37,$B$7:$B$20)+SUMIF($J$7:$J$20,$A37,$I$7:$I$20)+SUMIF($Q$7:$Q$20,$A37,$P$7:$P$20)+SUMIF($X$7:$X$20,$A37,$W$7:$W$20)) -> 0 | D37: =IF(OR($A37="",$C$47=0),"",$C37/$C$47) -> 0 | E37: =IF($A37="","",COUNTIF($C$7:$C$20,$A37)+COUNTIF($J$7:$J$20,$A37)+COUNTIF($Q$7:$Q$20,$A37)+COUNTIF($X$7:$X$20,$A37)) -> 0
A38: =IF(PARAMETRES!$E$10="","",PARAMETRES!$E$10) -> Reglage machine | C38: =IF($A38="","",SUMIF($C$7:$C$20,$A38,$B$7:$B$20)+SUMIF($J$7:$J$20,$A38,$I$7:$I$20)+SUMIF($Q$7:$Q$20,$A38,$P$7:$P$20)+SUMIF($X$7:$X$20,$A38,$W$7:$W$20)) -> 0 | D38: =IF(OR($A38="",$C$47=0),"",$C38/$C$47) -> 0 | E38: =IF($A38="","",COUNTIF($C$7:$C$20,$A38)+COUNTIF($J$7:$J$20,$A38)+COUNTIF($Q$7:$Q$20,$A38)+COUNTIF($X$7:$X$20,$A38)) -> 0
A39: =IF(PARAMETRES!$E$11="","",PARAMETRES!$E$11) -> Manque de personnel | C39: =IF($A39="","",SUMIF($C$7:$C$20,$A39,$B$7:$B$20)+SUMIF($J$7:$J$20,$A39,$I$7:$I$20)+SUMIF($Q$7:$Q$20,$A39,$P$7:$P$20)+SUMIF($X$7:$X$20,$A39,$W$7:$W$20)) -> 0 | D39: =IF(OR($A39="",$C$47=0),"",$C39/$C$47) -> 0 | E39: =IF($A39="","",COUNTIF($C$7:$C$20,$A39)+COUNTIF($J$7:$J$20,$A39)+COUNTIF($Q$7:$Q$20,$A39)+COUNTIF($X$7:$X$20,$A39)) -> 0
A40: =IF(PARAMETRES!$E$12="","",PARAMETRES!$E$12) -> Attente controle qualite | C40: =IF($A40="","",SUMIF($C$7:$C$20,$A40,$B$7:$B$20)+SUMIF($J$7:$J$20,$A40,$I$7:$I$20)+SUMIF($Q$7:$Q$20,$A40,$P$7:$P$20)+SUMIF($X$7:$X$20,$A40,$W$7:$W$20)) -> 0 | D40: =IF(OR($A40="",$C$47=0),"",$C40/$C$47) -> 0 | E40: =IF($A40="","",COUNTIF($C$7:$C$20,$A40)+COUNTIF($J$7:$J$20,$A40)+COUNTIF($Q$7:$Q$20,$A40)+COUNTIF($X$7:$X$20,$A40)) -> 0
A41: =IF(PARAMETRES!$E$13="","",PARAMETRES!$E$13) -> Coupure electricite | C41: =IF($A41="","",SUMIF($C$7:$C$20,$A41,$B$7:$B$20)+SUMIF($J$7:$J$20,$A41,$I$7:$I$20)+SUMIF($Q$7:$Q$20,$A41,$P$7:$P$20)+SUMIF($X$7:$X$20,$A41,$W$7:$W$20)) -> 0 | D41: =IF(OR($A41="",$C$47=0),"",$C41/$C$47) -> 0 | E41: =IF($A41="","",COUNTIF($C$7:$C$20,$A41)+COUNTIF($J$7:$J$20,$A41)+COUNTIF($Q$7:$Q$20,$A41)+COUNTIF($X$7:$X$20,$A41)) -> 0
A42: =IF(PARAMETRES!$E$14="","",PARAMETRES!$E$14) -> Manque emballage | C42: =IF($A42="","",SUMIF($C$7:$C$20,$A42,$B$7:$B$20)+SUMIF($J$7:$J$20,$A42,$I$7:$I$20)+SUMIF($Q$7:$Q$20,$A42,$P$7:$P$20)+SUMIF($X$7:$X$20,$A42,$W$7:$W$20)) -> 0 | D42: =IF(OR($A42="",$C$47=0),"",$C42/$C$47) -> 0 | E42: =IF($A42="","",COUNTIF($C$7:$C$20,$A42)+COUNTIF($J$7:$J$20,$A42)+COUNTIF($Q$7:$Q$20,$A42)+COUNTIF($X$7:$X$20,$A42)) -> 0
A43: =IF(PARAMETRES!$E$15="","",PARAMETRES!$E$15) -> Evacuation dechets | C43: =IF($A43="","",SUMIF($C$7:$C$20,$A43,$B$7:$B$20)+SUMIF($J$7:$J$20,$A43,$I$7:$I$20)+SUMIF($Q$7:$Q$20,$A43,$P$7:$P$20)+SUMIF($X$7:$X$20,$A43,$W$7:$W$20)) -> 0 | D43: =IF(OR($A43="",$C$47=0),"",$C43/$C$47) -> 0 | E43: =IF($A43="","",COUNTIF($C$7:$C$20,$A43)+COUNTIF($J$7:$J$20,$A43)+COUNTIF($Q$7:$Q$20,$A43)+COUNTIF($X$7:$X$20,$A43)) -> 0
...

Sheet Suivi Mensuel
A1: SUIVI MENSUEL — CADENCES MO GRATTAGE
A2: Date | B2: Produit | C2: Ligne | D2: Nb boites | E2: Duree nette (h) | F2: Total arret (min) | G2: Nbre femmes | H2: Standard boites/h/femme | I2: Cadence boites/h/femme | J2: % atteinte | K2: Ecart vs standard | L2: Statut | M2: Cadence ligne (boites/h)
I3: =IF(OR($D3="",$E3="",$G3="",$E3<=0,$G3=0),"",$D3/$E3/$G3) | J3: =IF(OR($I3="",NOT(ISNUMBER($H3)),$H3=0),"",$I3/$H3) | K3: =IF(OR($I3="",NOT(ISNUMBER($H3))),"",$I3-$H3) | L3: =IF($I3="","",IF(NOT(ISNUMBER($H3)),"Standard manquant",IF($J3>=1,"Standard atteint",IF($J3>=SeuilAlerte,"Alerte","Sous standard")))) | M3: =IF(OR($D3="",$E3="",$E3<=0),"",$D3/$E3)
I4: =IF(OR($D4="",$E4="",$G4="",$E4<=0,$G4=0),"",$D4/$E4/$G4) | J4: =IF(OR($I4="",NOT(ISNUMBER($H4)),$H4=0),"",$I4/$H4) | K4: =IF(OR($I4="",NOT(ISNUMBER($H4))),"",$I4-$H4) | L4: =IF($I4="","",IF(NOT(ISNUMBER($H4)),"Standard manquant",IF($J4>=1,"Standard atteint",IF($J4>=SeuilAlerte,"Alerte","Sous standard")))) | M4: =IF(OR($D4="",$E4="",$E4<=0),"",$D4/$E4)
I5: =IF(OR($D5="",$E5="",$G5="",$E5<=0,$G5=0),"",$D5/$E5/$G5) | J5: =IF(OR($I5="",NOT(ISNUMBER($H5)),$H5=0),"",$I5/$H5) | K5: =IF(OR($I5="",NOT(ISNUMBER($H5))),"",$I5-$H5) | L5: =IF($I5="","",IF(NOT(ISNUMBER($H5)),"Standard manquant",IF($J5>=1,"Standard atteint",IF($J5>=SeuilAlerte,"Alerte","Sous standard")))) | M5: =IF(OR($D5="",$E5="",$E5<=0),"",$D5/$E5)
I6: =IF(OR($D6="",$E6="",$G6="",$E6<=0,$G6=0),"",$D6/$E6/$G6) | J6: =IF(OR($I6="",NOT(ISNUMBER($H6)),$H6=0),"",$I6/$H6) | K6: =IF(OR($I6="",NOT(ISNUMBER($H6))),"",$I6-$H6) | L6: =IF($I6="","",IF(NOT(ISNUMBER($H6)),"Standard manquant",IF($J6>=1,"Standard atteint",IF($J6>=SeuilAlerte,"Alerte","Sous standard")))) | M6: =IF(OR($D6="",$E6="",$E6<=0),"",$D6/$E6)
I7: =IF(OR($D7="",$E7="",$G7="",$E7<=0,$G7=0),"",$D7/$E7/$G7) | J7: =IF(OR($I7="",NOT(ISNUMBER($H7)),$H7=0),"",$I7/$H7) | K7: =IF(OR($I7="",NOT(ISNUMBER($H7))),"",$I7-$H7) | L7: =IF($I7="","",IF(NOT(ISNUMBER($H7)),"Standard manquant",IF($J7>=1,"Standard atteint",IF($J7>=SeuilAlerte,"Alerte","Sous standard")))) | M7: =IF(OR($D7="",$E7="",$E7<=0),"",$D7/$E7)
I8: =IF(OR($D8="",$E8="",$G8="",$E8<=0,$G8=0),"",$D8/$E8/$G8) | J8: =IF(OR($I8="",NOT(ISNUMBER($H8)),$H8=0),"",$I8/$H8) | K8: =IF(OR($I8="",NOT(ISNUMBER($H8))),"",$I8-$H8) | L8: =IF($I8="","",IF(NOT(ISNUMBER($H8)),"Standard manquant",IF($J8>=1,"Standard atteint",IF($J8>=SeuilAlerte,"Alerte","Sous standard")))) | M8: =IF(OR($D8="",$E8="",$E8<=0),"",$D8/$E8)
I9: =IF(OR($D9="",$E9="",$G9="",$E9<=0,$G9=0),"",$D9/$E9/$G9) | J9: =IF(OR($I9="",NOT(ISNUMBER($H9)),$H9=0),"",$I9/$H9) | K9: =IF(OR($I9="",NOT(ISNUMBER($H9))),"",$I9-$H9) | L9: =IF($I9="","",IF(NOT(ISNUMBER($H9)),"Standard manquant",IF($J9>=1,"Standard atteint",IF($J9>=SeuilAlerte,"Alerte","Sous standard")))) | M9: =IF(OR($D9="",$E9="",$E9<=0),"",$D9/$E9)
I10: =IF(OR($D10="",$E10="",$G10="",$E10<=0,$G10=0),"",$D10/$E10/$G10) | J10: =IF(OR($I10="",NOT(ISNUMBER($H10)),$H10=0),"",$I10/$H10) | K10: =IF(OR($I10="",NOT(ISNUMBER($H10))),"",$I10-$H10) | L10: =IF($I10="","",IF(NOT(ISNUMBER($H10)),"Standard manquant",IF($J10>=1,"Standard atteint",IF($J10>=SeuilAlerte,"Alerte","Sous standard")))) | M10: =IF(OR($D10="",$E10="",$E10<=0),"",$D10/$E10)
I11: =IF(OR($D11="",$E11="",$G11="",$E11<=0,$G11=0),"",$D11/$E11/$G11) | J11: =IF(OR($I11="",NOT(ISNUMBER($H11)),$H11=0),"",$I11/$H11) | K11: =IF(OR($I11="",NOT(ISNUMBER($H11))),"",$I11-$H11) | L11: =IF($I11="","",IF(NOT(ISNUMBER($H11)),"Standard manquant",IF($J11>=1,"Standard atteint",IF($J11>=SeuilAlerte,"Alerte","Sous standard")))) | M11: =IF(OR($D11="",$E11="",$E11<=0),"",$D11/$E11)
I12: =IF(OR($D12="",$E12="",$G12="",$E12<=0,$G12=0),"",$D12/$E12/$G12) | J12: =IF(OR($I12="",NOT(ISNUMBER($H12)),$H12=0),"",$I12/$H12) | K12: =IF(OR($I12="",NOT(ISNUMBER($H12))),"",$I12-$H12) | L12: =IF($I12="","",IF(NOT(ISNUMBER($H12)),"Standard manquant",IF($J12>=1,"Standard atteint",IF($J12>=SeuilAlerte,"Alerte","Sous standard")))) | M12: =IF(OR($D12="",$E12="",$E12<=0),"",$D12/$E12)
I13: =IF(OR($D13="",$E13="",$G13="",$E13<=0,$G13=0),"",$D13/$E13/$G13) | J13: =IF(OR($I13="",NOT(ISNUMBER($H13)),$H13=0),"",$I13/$H13) | K13: =IF(OR($I13="",NOT(ISNUMBER($H13))),"",$I13-$H13) | L13: =IF($I13="","",IF(NOT(ISNUMBER($H13)),"Standard manquant",IF($J13>=1,"Standard atteint",IF($J13>=SeuilAlerte,"Alerte","Sous standard")))) | M13: =IF(OR($D13="",$E13="",$E13<=0),"",$D13/$E13)
I14: =IF(OR($D14="",$E14="",$G14="",$E14<=0,$G14=0),"",$D14/$E14/$G14) | J14: =IF(OR($I14="",NOT(ISNUMBER($H14)),$H14=0),"",$I14/$H14) | K14: =IF(OR($I14="",NOT(ISNUMBER($H14))),"",$I14-$H14) | L14: =IF($I14="","",IF(NOT(ISNUMBER($H14)),"Standard manquant",IF($J14>=1,"Standard atteint",IF($J14>=SeuilAlerte,"Alerte","Sous standard")))) | M14: =IF(OR($D14="",$E14="",$E14<=0),"",$D14/$E14)
... I302: =IF(OR($D302="",$E302="",$G302="",$E302<=0,$G302=0),"",$D302/$E302/$G302) | J302: =IF(OR($I302="",NOT(ISNUMBER($H302)),$H302=0),"",$I302/$H302) | K302: =IF(OR($I302="",NOT(ISNUMBER($H302))),"",$I302-$H302) | L302: =IF($I302="","",IF(NOT(ISNUMBER($H302)),"Standard manquant",IF($J302>=1,"Standard atteint",IF($J302>=SeuilAlerte,"Alerte","Sous standard")))) | M302: =IF(OR($D302="",$E302="",$E302<=0),"",$D302/$E302)

Sheet PARAMETRES
A1: PARAMETRES — CADENCES MO GRATTAGE
A2: Seuil alerte (% du standard) | B2: 0.9
A3: STANDARDS PAR PRODUIT | E3: LISTE DES MOTIFS D'ARRET
A4: Produit | B4: Standard boites/h/femme | C4: Commentaire | E4: Motif d'arret
A5: FMHOEV BIO | B5: 112 | E5: Pause repas / reglementaire
E6: Panne machine
E7: Manque matiere premiere
E8: Changement de lot
E9: Nettoyage / sanitation
E10: Reglage machine
E11: Manque de personnel
E12: Attente controle qualite
E13: Coupure electricite
E14: Manque emballage
E15: Evacuation dechets
