Workbook

Sheet ACCUEIL
A1: OCEAMIC - QUALITE, STOCK & SOUS-TRAITANCE
A2: Classeur unique - sans macro. Le stock est integralement reconstruit a partir de l'onglet MOUVEMENTS.
A4: NAVIGATION
B5: =HYPERLINK("#'LOTS'!A1","1. Fiches lot") -> 1. Fiches lot | E5: =HYPERLINK("#'OPERATIONS'!A1","2. Operations de stock") -> 2. Operations de stock | H5: =HYPERLINK("#'SOUS_TRAITANCE'!A1","3. Envois sous-traitance") -> 3. Envois sous-traitance
B6: =HYPERLINK("#'ST_RESULTATS'!A1","4. Resultats sous-traitance") -> 4. Resultats sous-traitance | E6: =HYPERLINK("#'QUALITE'!A1","5. Controles qualite") -> 5. Controles qualite | H6: =HYPERLINK("#'STOCK'!A1","6. Synthese stock") -> 6. Synthese stock
B7: =HYPERLINK("#'RECHERCHE'!A1","7. Recherche lot") -> 7. Recherche lot | E7: =HYPERLINK("#'MOUVEMENTS'!A1","8. Grand livre") -> 8. Grand livre | H7: =HYPERLINK("#'PARAM'!A1","9. Parametres") -> 9. Parametres
B8: =HYPERLINK("#'GUIDE'!A1","10. Mode d'emploi") -> 10. Mode d'emploi
A10: TABLEAU DE BORD
B11: STOCK INTERNE (kg) | C11: =STOCK!$D$4 -> 4065 | E11: STOCK EXTERNE (kg) | F11: =STOCK!$D$5 -> 1350 | H11: STOCK TOTAL (kg) | I11: =STOCK!$D$6 -> 5415
B12: EN COURS SOUS-TRAITANCE (kg) | C12: =STOCK!$D$8 -> 200 | E12: STOCK BLOQUE QUALITE (kg) | F12: =STOCK!$D$9 -> 200 | H12: NOMBRE DE LOTS | I12: =COUNTA(LOT_KEY) -> 10
A14: CONTROLE D'INTEGRITE
B15: =IF(SUM($C$17:$C$23)=0,"INTEGRITE DES DONNEES : OK","INTEGRITE DES DONNEES : A CORRIGER") -> INTEGRITE DES DONNEES : A CORRIGER | E15: Les 6 premieres lignes ci-dessous sont bloquantes : tant qu'elles ne sont pas a zero, le stock affiche n'est pas fiable a 100%. Les suivantes sont informatives.
B17: Operations de stock en anomalie | C17: =COUNTIF(OPS_STATUT,"DONNEES MANQUANTES")+COUNTIF(OPS_STATUT,"STOCK INSUFFISANT")+COUNTIF(OPS_STATUT,"EMPLACEMENT INCOHERENT") -> 1 | E17: LEGENDE DES COULEURS
B18: Envois sous-traitance bloquants | C18: =COUNTIF(ST_STATUT,"DONNEES MANQUANTES")+COUNTIF(ST_STATUT,"STOCK INSUFFISANT")+COUNTIF(ST_STATUT,"EMPLACEMENT INCOHERENT")+COUNTIF(ST_STATUT,"BLOQUE") -> 0 | F18: Cellule a saisir
B19: Resultats de sous-traitance en anomalie | C19: =COUNTIF(RES_STATUT,"DONNEES MANQUANTES")+COUNTIF(RES_STATUT,"BLOQUE") -> 0 | F19: Cellule calculee - ne rien y ecrire
B20: Fiches lot en anomalie (doublon / incoherence) | C20: =COUNTIF(LOT_STATUT,"INCOHERENCE")+COUNTIF(LOT_STATUT,"LOT EN DOUBLE") -> 0 | F20: OK - la ligne est valide et comptee en stock
B21: Lots avec stock negatif | C21: =COUNTIF(STOCK!$N$14:$N$213,"<0") -> 0 | F21: EN COURS - etape normale, en attente de la suite
B22: Ecart matrice / grand livre (kg) | C22: =STOCK!$D$10 -> 0 | F22: A JUSTIFIER - il manque une explication
B23: Reconciliation du grand livre | C23: =IF(STOCK!$H$225="BILAN OK",0,1) -> 0 | F23: ANOMALIE - la ligne n'est PAS comptee en stock
B24: Envois EN COURS (normal, en attente de resultat) | C24: =COUNTIF(ST_STATUT,"EN COURS") -> 1
B25: Ecarts de sous-traitance A JUSTIFIER | C25: =COUNTIF(ST_STATUT,"A JUSTIFIER") -> 1
B26: Controles qualite a verifier | C26: =COUNTIF(QC_STATUT,"DONNEES MANQUANTES")+COUNTIF(QC_STATUT,"EMPLACEMENT INCOHERENT") -> 1
B27: Alertes qualite (histamine / temperature) | C27: =COUNTIF(QC_ALERTE,"?*") -> 3
B28: Lignes de mouvement rejetees (non comptees en stock) | C28: =SUMPRODUCT((MVT_BRUT<>0)*(MVT_NET=0)) -> 1
A29: MODE OPERATOIRE EN 7 ETAPES
B30: 1. Creer le lot | C30: Onglet LOTS : une ligne par lot, une seule fois. C'est la seule saisie de l'identite (produit, fournisseur, origine, camion, etat, conservation).
B31: 2. Enregistrer les mouvements | C31: Onglet OPERATIONS : RECEPTION, TRANSFERT ou CONSOMMATION. On choisit le lot, les emplacements et la quantite - rien d'autre.
B32: 3. Envoyer en sous-traitance | C32: Onglet SOUS_TRAITANCE. SOURCE = FOURNISSEUR pour une livraison directe (aucun stock consomme, aucune reception a saisir) ; SOURCE = STOCK EXISTANT pour un prelevement.
B33: 4. Completer les resultats | C33: Onglet ST_RESULTATS, meme des jours plus tard. Un envoi sans resultat reste EN COURS : ce n'est pas une erreur.
B34: 5. Justifier les ecarts | C34: QTE ENVOYEE - TOTAL SORTIE = ECART. Tant qu'un ecart positif n'est pas justifie, l'envoi reste A JUSTIFIER.
B35: 6. Controler la qualite | C35: Onglet QUALITE : uniquement les mesures reellement faites. Un controle ne modifie jamais le stock.
B36: 7. Corriger un inventaire | C36: Onglet OPERATIONS, type AJUSTEMENT : quantite signee sur l'emplacement de destination (negative = perte) et MOTIF obligatoire. C'est le seul moyen de corriger un stock.
B37: 8. Consulter | C37: Onglet STOCK pour la synthese (par lot, par espece, par etat matiere, reconciliation), RECHERCHE pour tout savoir d'un lot, MOUVEMENTS pour l'historique complet.

Sheet LOTS
A1: LOTS - FICHIER D'IDENTITE
A2: Une ligne = un lot. LOT INTERNE est la cle du stock : elle est obligatoire et ne change plus. Si aucun numero interne n'est encore attribue, reprenez le LOT EXTERNE du fournisseur. Ces informations ne se saisissent qu'une seule fois.
A3: Champs jaunes = saisie | Champs gris = calcules automatiquement, ne rien y ecrire
A4: LOT INTERNE | B4: LOT EXTERNE | C4: ESPECE | D4: PRODUCTEUR / FOURNISSEUR | E4: ORIGINE | F4: MATRICULE CAMION | G4: ETAT MATIERE | H4: CONSERVATION | I4: QUALITE INITIALE | J4: MOULE INITIAL | K4: DATE CREATION | L4: LOT PARENT | M4: OBSERVATION | N4: LOT PARENT EFFECTIF | O4: LOT EXTERNE EFFECTIF | P4: ESPECE EFFECTIVE | Q4: PRODUCTEUR EFFECTIF | R4: ORIGINE EFFECTIVE | S4: CONSERVATION EFFECTIVE | T4: MATRICULE EFFECTIF | U4: STOCK TOTAL (KG) | V4: NB MOUVEMENTS | W4: NB CONTROLES | X4: DERNIERE DECISION QUALITE | Y4: STATUT FICHE | Z4: REL. LOT EXTERNE | AA4: RANG LOT EXTERNE
A5: 255 | B5: L-EXT-255 | C5: Sardine | D5: Fournisseur local | E5: Laayoune | F5: 12345-A-6 | G5: ENTIER | H5: CONGELE | I5: A | J5: 20/24 | K5: 46237 | M5: Lot de reference - scenarios 1, 5, 8, 11, 12, 14, 15 | N5: =IF($A5="","",IF($L5<>"",$L5,IF(IFERROR(INDEX(RES_LOTSRC,MATCH($A5,RES_LOTEFF,0)),"")=$A5,"",IFERROR(INDEX(RES_LOTSRC,MATCH($A5,RES_LOTEFF,0)),"")))) | O5: =IF($A5="","",IF($B5<>"",$B5,IF($N5="","",IFERROR(INDEX($B$5:$B$204,MATCH($N5,$A$5:$A$204,0)),"")))) -> L-EXT-255 | P5: =IF($A5="","",IF($C5<>"",$C5,IF($N5="","",IFERROR(INDEX($C$5:$C$204,MATCH($N5,$A$5:$A$204,0)),"")))) -> Sardine | Q5: =IF($A5="","",IF($D5<>"",$D5,IF($N5="","",IFERROR(INDEX($D$5:$D$204,MATCH($N5,$A$5:$A$204,0)),"")))) -> Fournisseur local | R5: =IF($A5="","",IF($E5<>"",$E5,IF($N5="","",IFERROR(INDEX($E$5:$E$204,MATCH($N5,$A$5:$A$204,0)),"")))) -> Laayoune | S5: =IF($A5="","",IF($H5<>"",$H5,IF($N5="","",IFERROR(INDEX($H$5:$H$204,MATCH($N5,$A$5:$A$204,0)),"")))) -> CONGELE | T5: =IF($A5="","",IF($F5<>"",$F5,IF($N5="","",IFERROR(INDEX($F$5:$F$204,MATCH($N5,$A$5:$A$204,0)),"")))) -> 12345-A-6 | U5: =IF($A5="","",SUMIFS(MVT_NET,MVT_LOT,$A5)) -> 500 | V5: =IF($A5="","",COUNTIFS(MVT_LOT,$A5,MVT_BRUT,"<>0")) -> 2 | W5: =IF($A5="","",COUNTIFS(QC_LOT,$A5)) -> 1 | X5: =IF($A5="","",IFERROR(INDEX(QC_DEC,MATCH($A5,QC_CLEDER,0)),"")) -> ACCEPTER | Y5: =IF($A5="","",IF(COUNTIF($A$5:$A$204,$A5)>1,IF(SUMPRODUCT(($A$5:$A$204=$A5)*(($C$5:$C$204<>$C5)+($D$5:$D$204<>$D5)))>0,"INCOHERENCE","LOT EN DOUBLE"),"OK")) -> OK | Z5: =IF($A5="",0,IF(AND($O5<>"",$A5<>R_LOT,$O5=IFERROR(INDEX(LOT_EXTE,MATCH(R_LOT,LOT_KEY,0)),"#")),1,0)) -> 0 | AA5: =IF($Z5=0,"",COUNTIF($Z$5:$Z5,1))
A6: 256 | B6: L-EXT-256 | C6: Maquereau | D6: Producteur Boujdour | E6: Boujdour | F6: 22876-B-1 | G6: ENTIER | H6: CONGELE | I6: B | J6: 26/30 | K6: 46238 | M6: Scenarios 2 et 4 - stock externe puis transfert | N6: =IF($A6="","",IF($L6<>"",$L6,IF(IFERROR(INDEX(RES_LOTSRC,MATCH($A6,RES_LOTEFF,0)),"")=$A6,"",IFERROR(INDEX(RES_LOTSRC,MATCH($A6,RES_LOTEFF,0)),"")))) | O6: =IF($A6="","",IF($B6<>"",$B6,IF($N6="","",IFERROR(INDEX($B$5:$B$204,MATCH($N6,$A$5:$A$204,0)),"")))) -> L-EXT-256 | P6: =IF($A6="","",IF($C6<>"",$C6,IF($N6="","",IFERROR(INDEX($C$5:$C$204,MATCH($N6,$A$5:$A$204,0)),"")))) -> Maquereau | Q6: =IF($A6="","",IF($D6<>"",$D6,IF($N6="","",IFERROR(INDEX($D$5:$D$204,MATCH($N6,$A$5:$A$204,0)),"")))) -> Producteur Boujdour | R6: =IF($A6="","",IF($E6<>"",$E6,IF($N6="","",IFERROR(INDEX($E$5:$E$204,MATCH($N6,$A$5:$A$204,0)),"")))) -> Boujdour | S6: =IF($A6="","",IF($H6<>"",$H6,IF($N6="","",IFERROR(INDEX($H$5:$H$204,MATCH($N6,$A$5:$A$204,0)),"")))) -> CONGELE | T6: =IF($A6="","",IF($F6<>"",$F6,IF($N6="","",IFERROR(INDEX($F$5:$F$204,MATCH($N6,$A$5:$A$204,0)),"")))) -> 22876-B-1 | U6: =IF($A6="","",SUMIFS(MVT_NET,MVT_LOT,$A6)) -> 2000 | V6: =IF($A6="","",COUNTIFS(MVT_LOT,$A6,MVT_BRUT,"<>0")) -> 3 | W6: =IF($A6="","",COUNTIFS(QC_LOT,$A6)) -> 1 | X6: =IF($A6="","",IFERROR(INDEX(QC_DEC,MATCH($A6,QC_CLEDER,0)),"")) -> A RECONTROLER | Y6: =IF($A6="","",IF(COUNTIF($A$5:$A$204,$A6)>1,IF(SUMPRODUCT(($A$5:$A$204=$A6)*(($C$5:$C$204<>$C6)+($D$5:$D$204<>$D6)))>0,"INCOHERENCE","LOT EN DOUBLE"),"OK")) -> OK | Z6: =IF($A6="",0,IF(AND($O6<>"",$A6<>R_LOT,$O6=IFERROR(INDEX(LOT_EXTE,MATCH(R_LOT,LOT_KEY,0)),"#")),1,0)) -> 0 | AA6: =IF($Z6=0,"",COUNTIF($Z$5:$Z6,1))
A7: 257 | B7: L-EXT-255 | C7: Sardine | D7: Fournisseur local | E7: Laayoune | F7: 33111-C-2 | G7: ENTIER | H7: FRAIS | I7: A | J7: 20/24 | K7: 46239 | M7: Scenario 3 - meme lot externe que 255 (cas reel a deux lots) | N7: =IF($A7="","",IF($L7<>"",$L7,IF(IFERROR(INDEX(RES_LOTSRC,MATCH($A7,RES_LOTEFF,0)),"")=$A7,"",IFERROR(INDEX(RES_LOTSRC,MATCH($A7,RES_LOTEFF,0)),"")))) | O7: =IF($A7="","",IF($B7<>"",$B7,IF($N7="","",IFERROR(INDEX($B$5:$B$204,MATCH($N7,$A$5:$A$204,0)),"")))) -> L-EXT-255 | P7: =IF($A7="","",IF($C7<>"",$C7,IF($N7="","",IFERROR(INDEX($C$5:$C$204,MATCH($N7,$A$5:$A$204,0)),"")))) -> Sardine | Q7: =IF($A7="","",IF($D7<>"",$D7,IF($N7="","",IFERROR(INDEX($D$5:$D$204,MATCH($N7,$A$5:$A$204,0)),"")))) -> Fournisseur local | R7: =IF($A7="","",IF($E7<>"",$E7,IF($N7="","",IFERROR(INDEX($E$5:$E$204,MATCH($N7,$A$5:$A$204,0)),"")))) -> Laayoune | S7: =IF($A7="","",IF($H7<>"",$H7,IF($N7="","",IFERROR(INDEX($H$5:$H$204,MATCH($N7,$A$5:$A$204,0)),"")))) -> FRAIS | T7: =IF($A7="","",IF($F7<>"",$F7,IF($N7="","",IFERROR(INDEX($F$5:$F$204,MATCH($N7,$A$5:$A$204,0)),"")))) -> 33111-C-2 | U7: =IF($A7="","",SUMIFS(MVT_NET,MVT_LOT,$A7)) -> 500 | V7: =IF($A7="","",COUNTIFS(MVT_LOT,$A7,MVT_BRUT,"<>0")) -> 2 | W7: =IF($A7="","",COUNTIFS(QC_LOT,$A7)) -> 1 | X7: =IF($A7="","",IFERROR(INDEX(QC_DEC,MATCH($A7,QC_CLEDER,0)),"")) -> ACCEPTER | Y7: =IF($A7="","",IF(COUNTIF($A$5:$A$204,$A7)>1,IF(SUMPRODUCT(($A$5:$A$204=$A7)*(($C$5:$C$204<>$C7)+($D$5:$D$204<>$D7)))>0,"INCOHERENCE","LOT EN DOUBLE"),"OK")) -> OK | Z7: =IF($A7="",0,IF(AND($O7<>"",$A7<>R_LOT,$O7=IFERROR(INDEX(LOT_EXTE,MATCH(R_LOT,LOT_KEY,0)),"#")),1,0)) -> 1 | AA7: =IF($Z7=0,"",COUNTIF($Z$5:$Z7,1)) -> 1
A8: 258 | B8: L-EXT-258 | C8: Sardine | D8: Fournisseur local | E8: tan tan | F8: 44900-E-7 | G8: ENTIER | H8: CONGELE | I8: B | J8: 20/24 | K8: 46240 | M8: Scenario 13 - tentative de sortie superieure au stock | N8: =IF($A8="","",IF($L8<>"",$L8,IF(IFERROR(INDEX(RES_LOTSRC,MATCH($A8,RES_LOTEFF,0)),"")=$A8,"",IFERROR(INDEX(RES_LOTSRC,MATCH($A8,RES_LOTEFF,0)),"")))) | O8: =IF($A8="","",IF($B8<>"",$B8,IF($N8="","",IFERROR(INDEX($B$5:$B$204,MATCH($N8,$A$5:$A$204,0)),"")))) -> L-EXT-258 | P8: =IF($A8="","",IF($C8<>"",$C8,IF($N8="","",IFERROR(INDEX($C$5:$C$204,MATCH($N8,$A$5:$A$204,0)),"")))) -> Sardine | Q8: =IF($A8="","",IF($D8<>"",$D8,IF($N8="","",IFERROR(INDEX($D$5:$D$204,MATCH($N8,$A$5:$A$204,0)),"")))) -> Fournisseur local | R8: =IF($A8="","",IF($E8<>"",$E8,IF($N8="","",IFERROR(INDEX($E$5:$E$204,MATCH($N8,$A$5:$A$204,0)),"")))) -> tan tan | S8: =IF($A8="","",IF($H8<>"",$H8,IF($N8="","",IFERROR(INDEX($H$5:$H$204,MATCH($N8,$A$5:$A$204,0)),"")))) -> CONGELE | T8: =IF($A8="","",IF($F8<>"",$F8,IF($N8="","",IFERROR(INDEX($F$5:$F$204,MATCH($N8,$A$5:$A$204,0)),"")))) -> 44900-E-7 | U8: =IF($A8="","",SUMIFS(MVT_NET,MVT_LOT,$A8)) -> 200 | V8: =IF($A8="","",COUNTIFS(MVT_LOT,$A8,MVT_BRUT,"<>0")) -> 2 | W8: =IF($A8="","",COUNTIFS(QC_LOT,$A8)) -> 0 | X8: =IF($A8="","",IFERROR(INDEX(QC_DEC,MATCH($A8,QC_CLEDER,0)),"")) | Y8: =IF($A8="","",IF(COUNTIF($A$5:$A$204,$A8)>1,IF(SUMPRODUCT(($A$5:$A$204=$A8)*(($C$5:$C$204<>$C8)+($D$5:$D$204<>$D8)))>0,"INCOHERENCE","LOT EN DOUBLE"),"OK")) -> OK | Z8: =IF($A8="",0,IF(AND($O8<>"",$A8<>R_LOT,$O8=IFERROR(INDEX(LOT_EXTE,MATCH(R_LOT,LOT_KEY,0)),"#")),1,0)) -> 0 | AA8: =IF($Z8=0,"",COUNTIF($Z$5:$Z8,1))
A9: 300 | B9: L-EXT-300 | C9: Anchois | D9: Producteur Dakhla | E9: Dakhla | F9: 44222-D-3 | G9: ENTIER | H9: CONGELE | I9: A | J9: 20/24 | K9: 46241 | M9: Scenario 6 - livraison directe fournisseur vers sous-traitant | N9: =IF($A9="","",IF($L9<>"",$L9,IF(IFERROR(INDEX(RES_LOTSRC,MATCH($A9,RES_LOTEFF,0)),"")=$A9,"",IFERROR(INDEX(RES_LOTSRC,MATCH($A9,RES_LOTEFF,0)),"")))) | O9: =IF($A9="","",IF($B9<>"",$B9,IF($N9="","",IFERROR(INDEX($B$5:$B$204,MATCH($N9,$A$5:$A$204,0)),"")))) -> L-EXT-300 | P9: =IF($A9="","",IF($C9<>"",$C9,IF($N9="","",IFERROR(INDEX($C$5:$C$204,MATCH($N9,$A$5:$A$204,0)),"")))) -> Anchois | Q9: =IF($A9="","",IF($D9<>"",$D9,IF($N9="","",IFERROR(INDEX($D$5:$D$204,MATCH($N9,$A$5:$A$204,0)),"")))) -> Producteur Dakhla | R9: =IF($A9="","",IF($E9<>"",$E9,IF($N9="","",IFERROR(INDEX($E$5:$E$204,MATCH($N9,$A$5:$A$204,0)),"")))) -> Dakhla | S9: =IF($A9="","",IF($H9<>"",$H9,IF($N9="","",IFERROR(INDEX($H$5:$H$204,MATCH($N9,$A$5:$A$204,0)),"")))) -> CONGELE | T9: =IF($A9="","",IF($F9<>"",$F9,IF($N9="","",IFERROR(INDEX($F$5:$F$204,MATCH($N9,$A$5:$A$204,0)),"")))) -> 44222-D-3 | U9: =IF($A9="","",SUMIFS(MVT_NET,MVT_LOT,$A9)) -> 0 | V9: =IF($A9="","",COUNTIFS(MVT_LOT,$A9,MVT_BRUT,"<>0")) -> 0 | W9: =IF($A9="","",COUNTIFS(QC_LOT,$A9)) -> 0 | X9: =IF($A9="","",IFERROR(INDEX(QC_DEC,MATCH($A9,QC_CLEDER,0)),"")) | Y9: =IF($A9="","",IF(COUNTIF($A$5:$A$204,$A9)>1,IF(SUMPRODUCT(($A$5:$A$204=$A9)*(($C$5:$C$204<>$C9)+($D$5:$D$204<>$D9)))>0,"INCOHERENCE","LOT EN DOUBLE"),"OK")) -> OK | Z9: =IF($A9="",0,IF(AND($O9<>"",$A9<>R_LOT,$O9=IFERROR(INDEX(LOT_EXTE,MATCH(R_LOT,LOT_KEY,0)),"#")),1,0)) -> 0 | AA9: =IF($Z9=0,"",COUNTIF($Z$5:$Z9,1))
A10: 301 | B10: L-EXT-301 | C10: Maquereau | D10: Producteur Boujdour | E10: Boujdour | F10: 55333-F-8 | G10: ENTIER | H10: CONGELE | I10: A | J10: 26/30 | K10: 46244 | M10: Scenario 7 - sous-traitance EN COURS, puis blocage qualite | N10: =IF($A10="","",IF($L10<>"",$L10,IF(IFERROR(INDEX(RES_LOTSRC,MATCH($A10,RES_LOTEFF,0)),"")=$A10,"",IFERROR(INDEX(RES_LOTSRC,MATCH($A10,RES_LOTEFF,0)),"")))) | O10: =IF($A10="","",IF($B10<>"",$B10,IF($N10="","",IFERROR(INDEX($B$5:$B$204,MATCH($N10,$A$5:$A$204,0)),"")))) -> L-EXT-301 | P10: =IF($A10="","",IF($C10<>"",$C10,IF($N10="","",IFERROR(INDEX($C$5:$C$204,MATCH($N10,$A$5:$A$204,0)),"")))) -> Maquereau | Q10: =IF($A10="","",IF($D10<>"",$D10,IF($N10="","",IFERROR(INDEX($D$5:$D$204,MATCH($N10,$A$5:$A$204,0)),"")))) -> Producteur Boujdour | R10: =IF($A10="","",IF($E10<>"",$E10,IF($N10="","",IFERROR(INDEX($E$5:$E$204,MATCH($N10,$A$5:$A$204,0)),"")))) -> Boujdour | S10: =IF($A10="","",IF($H10<>"",$H10,IF($N10="","",IFERROR(INDEX($H$5:$H$204,MATCH($N10,$A$5:$A$204,0)),"")))) -> CONGELE | T10: =IF($A10="","",IF($F10<>"",$F10,IF($N10="","",IFERROR(INDEX($F$5:$F$204,MATCH($N10,$A$5:$A$204,0)),"")))) -> 55333-F-8 | U10: =IF($A10="","",SUMIFS(MVT_NET,MVT_LOT,$A10)) -> 200 | V10: =IF($A10="","",COUNTIFS(MVT_LOT,$A10,MVT_BRUT,"<>0")) -> 2 | W10: =IF($A10="","",COUNTIFS(QC_LOT,$A10)) -> 1 | X10: =IF($A10="","",IFERROR(INDEX(QC_DEC,MATCH($A10,QC_CLEDER,0)),"")) -> BLOQUER | Y10: =IF($A10="","",IF(COUNTIF($A$5:$A$204,$A10)>1,IF(SUMPRODUCT(($A$5:$A$204=$A10)*(($C$5:$C$204<>$C10)+($D$5:$D$204<>$D10)))>0,"INCOHERENCE","LOT EN DOUBLE"),"OK")) -> OK | Z10: =IF($A10="",0,IF(AND($O10<>"",$A10<>R_LOT,$O10=IFERROR(INDEX(LOT_EXTE,MATCH(R_LOT,LOT_KEY,0)),"#")),1,0)) -> 0 | AA10: =IF($Z10=0,"",COUNTIF($Z$5:$Z10,1))
A11: 302 | B11: L-EXT-302 | C11: Chinchard | D11: Producteur Dakhla | E11: Dakhla | F11: 66444-G-9 | G11: ENTIER | H11: CONGELE | I11: A | J11: 26/30 | K11: 46251 | M11: Scenario 21 - ajustement d'inventaire | N11: =IF($A11="","",IF($L11<>"",$L11,IF(IFERROR(INDEX(RES_LOTSRC,MATCH($A11,RES_LOTEFF,0)),"")=$A11,"",IFERROR(INDEX(RES_LOTSRC,MATCH($A11,RES_LOTEFF,0)),"")))) | O11: =IF($A11="","",IF($B11<>"",$B11,IF($N11="","",IFERROR(INDEX($B$5:$B$204,MATCH($N11,$A$5:$A$204,0)),"")))) -> L-EXT-302 | P11: =IF($A11="","",IF($C11<>"",$C11,IF($N11="","",IFERROR(INDEX($C$5:$C$204,MATCH($N11,$A$5:$A$204,0)),"")))) -> Chinchard | Q11: =IF($A11="","",IF($D11<>"",$D11,IF($N11="","",IFERROR(INDEX($D$5:$D$204,MATCH($N11,$A$5:$A$204,0)),"")))) -> Producteur Dakhla | R11: =IF($A11="","",IF($E11<>"",$E11,IF($N11="","",IFERROR(INDEX($E$5:$E$204,MATCH($N11,$A$5:$A$204,0)),"")))) -> Dakhla | S11: =IF($A11="","",IF($H11<>"",$H11,IF($N11="","",IFERROR(INDEX($H$5:$H$204,MATCH($N11,$A$5:$A$204,0)),"")))) -> CONGELE | T11: =IF($A11="","",IF($F11<>"",$F11,IF($N11="","",IFERROR(INDEX($F$5:$F$204,MATCH($N11,$A$5:$A$204,0)),"")))) -> 66444-G-9 | U11: =IF($A11="","",SUMIFS(MVT_NET,MVT_LOT,$A11)) -> 975 | V11: =IF($A11="","",COUNTIFS(MVT_LOT,$A11,MVT_BRUT,"<>0")) -> 2 | W11: =IF($A11="","",COUNTIFS(QC_LOT,$A11)) -> 0 | X11: =IF($A11="","",IFERROR(INDEX(QC_DEC,MATCH($A11,QC_CLEDER,0)),"")) | Y11: =IF($A11="","",IF(COUNTIF($A$5:$A$204,$A11)>1,IF(SUMPRODUCT(($A$5:$A$204=$A11)*(($C$5:$C$204<>$C11)+($D$5:$D$204<>$D11)))>0,"INCOHERENCE","LOT EN DOUBLE"),"OK")) -> OK | Z11: =IF($A11="",0,IF(AND($O11<>"",$A11<>R_LOT,$O11=IFERROR(INDEX(LOT_EXTE,MATCH(R_LOT,LOT_KEY,0)),"#")),1,0)) -> 0 | AA11: =IF($Z11=0,"",COUNTIF($Z$5:$Z11,1))
A12: 255-HG | G12: HG | H12: CONGELE | I12: A | J12: 20/24 | K12: 46248 | L12: 255 | M12: Issu de ST-001 - identite heritee du lot 255 | N12: =IF($A12="","",IF($L12<>"",$L12,IF(IFERROR(INDEX(RES_LOTSRC,MATCH($A12,RES_LOTEFF,0)),"")=$A12,"",IFERROR(INDEX(RES_LOTSRC,MATCH($A12,RES_LOTEFF,0)),"")))) -> 255 | O12: =IF($A12="","",IF($B12<>"",$B12,IF($N12="","",IFERROR(INDEX($B$5:$B$204,MATCH($N12,$A$5:$A$204,0)),"")))) -> L-EXT-255 | P12: =IF($A12="","",IF($C12<>"",$C12,IF($N12="","",IFERROR(INDEX($C$5:$C$204,MATCH($N12,$A$5:$A$204,0)),"")))) -> Sardine | Q12: =IF($A12="","",IF($D12<>"",$D12,IF($N12="","",IFERROR(INDEX($D$5:$D$204,MATCH($N12,$A$5:$A$204,0)),"")))) -> Fournisseur local | R12: =IF($A12="","",IF($E12<>"",$E12,IF($N12="","",IFERROR(INDEX($E$5:$E$204,MATCH($N12,$A$5:$A$204,0)),"")))) -> Laayoune | S12: =IF($A12="","",IF($H12<>"",$H12,IF($N12="","",IFERROR(INDEX($H$5:$H$204,MATCH($N12,$A$5:$A$204,0)),"")))) -> CONGELE | T12: =IF($A12="","",IF($F12<>"",$F12,IF($N12="","",IFERROR(INDEX($F$5:$F$204,MATCH($N12,$A$5:$A$204,0)),"")))) -> 12345-A-6 | U12: =IF($A12="","",SUMIFS(MVT_NET,MVT_LOT,$A12)) -> 300 | V12: =IF($A12="","",COUNTIFS(MVT_LOT,$A12,MVT_BRUT,"<>0")) -> 1 | W12: =IF($A12="","",COUNTIFS(QC_LOT,$A12)) -> 0 | X12: =IF($A12="","",IFERROR(INDEX(QC_DEC,MATCH($A12,QC_CLEDER,0)),"")) | Y12: =IF($A12="","",IF(COUNTIF($A$5:$A$204,$A12)>1,IF(SUMPRODUCT(($A$5:$A$204=$A12)*(($C$5:$C$204<>$C12)+($D$5:$D$204<>$D12)))>0,"INCOHERENCE","LOT EN DOUBLE"),"OK")) -> OK | Z12: =IF($A12="",0,IF(AND($O12<>"",$A12<>R_LOT,$O12=IFERROR(INDEX(LOT_EXTE,MATCH(R_LOT,LOT_KEY,0)),"#")),1,0)) -> 1 | AA12: =IF($Z12=0,"",COUNTIF($Z$5:$Z12,1)) -> 2
A13: 255-HGT | G13: HGT | H13: CONGELE | I13: B | J13: 26/30 | K13: 46248 | L13: 255 | M13: Issu de ST-001 - envoye en stock externe COFRIGOP | N13: =IF($A13="","",IF($L13<>"",$L13,IF(IFERROR(INDEX(RES_LOTSRC,MATCH($A13,RES_LOTEFF,0)),"")=$A13,"",IFERROR(INDEX(RES_LOTSRC,MATCH($A13,RES_LOTEFF,0)),"")))) -> 255 | O13: =IF($A13="","",IF($B13<>"",$B13,IF($N13="","",IFERROR(INDEX($B$5:$B$204,MATCH($N13,$A$5:$A$204,0)),"")))) -> L-EXT-255 | P13: =IF($A13="","",IF($C13<>"",$C13,IF($N13="","",IFERROR(INDEX($C$5:$C$204,MATCH($N13,$A$5:$A$204,0)),"")))) -> Sardine | Q13: =IF($A13="","",IF($D13<>"",$D13,IF($N13="","",IFERROR(INDEX($D$5:$D$204,MATCH($N13,$A$5:$A$204,0)),"")))) -> Fournisseur local | R13: =IF($A13="","",IF($E13<>"",$E13,IF($N13="","",IFERROR(INDEX($E$5:$E$204,MATCH($N13,$A$5:$A$204,0)),"")))) -> Laayoune | S13: =IF($A13="","",IF($H13<>"",$H13,IF($N13="","",IFERROR(INDEX($H$5:$H$204,MATCH($N13,$A$5:$A$204,0)),"")))) -> CONGELE | T13: =IF($A13="","",IF($F13<>"",$F13,IF($N13="","",IFERROR(INDEX($F$5:$F$204,MATCH($N13,$A$5:$A$204,0)),"")))) -> 12345-A-6 | U13: =IF($A13="","",SUMIFS(MVT_NET,MVT_LOT,$A13)) -> 150 | V13: =IF($A13="","",COUNTIFS(MVT_LOT,$A13,MVT_BRUT,"<>0")) -> 1 | W13: =IF($A13="","",COUNTIFS(QC_LOT,$A13)) -> 0 | X13: =IF($A13="","",IFERROR(INDEX(QC_DEC,MATCH($A13,QC_CLEDER,0)),"")) | Y13: =IF($A13="","",IF(COUNTIF($A$5:$A$204,$A13)>1,IF(SUMPRODUCT(($A$5:$A$204=$A13)*(($C$5:$C$204<>$C13)+($D$5:$D$204<>$D13)))>0,"INCOHERENCE","LOT EN DOUBLE"),"OK")) -> OK | Z13: =IF($A13="",0,IF(AND($O13<>"",$A13<>R_LOT,$O13=IFERROR(INDEX(LOT_EXTE,MATCH(R_LOT,LOT_KEY,0)),"#")),1,0)) -> 1 | AA13: =IF($Z13=0,"",COUNTIF($Z$5:$Z13,1)) -> 3
A14: 300-FIL | G14: FILET | H14: CONGELE | I14: A | J14: 20/24 | K14: 46247 | L14: 300 | M14: Issu de ST-002 - retour OCEAMIC 2 | N14: =IF($A14="","",IF($L14<>"",$L14,IF(IFERROR(INDEX(RES_LOTSRC,MATCH($A14,RES_LOTEFF,0)),"")=$A14,"",IFERROR(INDEX(RES_LOTSRC,MATCH($A14,RES_LOTEFF,0)),"")))) -> 300 | O14: =IF($A14="","",IF($B14<>"",$B14,IF($N14="","",IFERROR(INDEX($B$5:$B$204,MATCH($N14,$A$5:$A$204,0)),"")))) -> L-EXT-300 | P14: =IF($A14="","",IF($C14<>"",$C14,IF($N14="","",IFERROR(INDEX($C$5:$C$204,MATCH($N14,$A$5:$A$204,0)),"")))) -> Anchois | Q14: =IF($A14="","",IF($D14<>"",$D14,IF($N14="","",IFERROR(INDEX($D$5:$D$204,MATCH($N14,$A$5:$A$204,0)),"")))) -> Producteur Dakhla | R14: =IF($A14="","",IF($E14<>"",$E14,IF($N14="","",IFERROR(INDEX($E$5:$E$204,MATCH($N14,$A$5:$A$204,0)),"")))) -> Dakhla | S14: =IF($A14="","",IF($H14<>"",$H14,IF($N14="","",IFERROR(INDEX($H$5:$H$204,MATCH($N14,$A$5:$A$204,0)),"")))) -> CONGELE | T14: =IF($A14="","",IF($F14<>"",$F14,IF($N14="","",IFERROR(INDEX($F$5:$F$204,MATCH($N14,$A$5:$A$204,0)),"")))) -> 44222-D-3 | U14: =IF($A14="","",SUMIFS(MVT_NET,MVT_LOT,$A14)) -> 590 | V14: =IF($A14="","",COUNTIFS(MVT_LOT,$A14,MVT_BRUT,"<>0")) -> 1 | W14: =IF($A14="","",COUNTIFS(QC_LOT,$A14)) -> 0 | X14: =IF($A14="","",IFERROR(INDEX(QC_DEC,MATCH($A14,QC_CLEDER,0)),"")) | Y14: =IF($A14="","",IF(COUNTIF($A$5:$A$204,$A14)>1,IF(SUMPRODUCT(($A$5:$A$204=$A14)*(($C$5:$C$204<>$C14)+($D$5:$D$204<>$D14)))>0,"INCOHERENCE","LOT EN DOUBLE"),"OK")) -> OK | Z14: =IF($A14="",0,IF(AND($O14<>"",$A14<>R_LOT,$O14=IFERROR(INDEX(LOT_EXTE,MATCH(R_LOT,LOT_KEY,0)),"#")),1,0)) -> 0 | AA14: =IF($Z14=0,"",COUNTIF($Z$5:$Z14,1))
N15: =IF($A15="","",IF($L15<>"",$L15,IF(IFERROR(INDEX(RES_LOTSRC,MATCH($A15,RES_LOTEFF,0)),"")=$A15,"",IFERROR(INDEX(RES_LOTSRC,MATCH($A15,RES_LOTEFF,0)),"")))) | O15: =IF($A15="","",IF($B15<>"",$B15,IF($N15="","",IFERROR(INDEX($B$5:$B$204,MATCH($N15,$A$5:$A$204,0)),"")))) | P15: =IF($A15="","",IF($C15<>"",$C15,IF($N15="","",IFERROR(INDEX($C$5:$C$204,MATCH($N15,$A$5:$A$204,0)),"")))) | Q15: =IF($A15="","",IF($D15<>"",$D15,IF($N15="","",IFERROR(INDEX($D$5:$D$204,MATCH($N15,$A$5:$A$204,0)),"")))) | R15: =IF($A15="","",IF($E15<>"",$E15,IF($N15="","",IFERROR(INDEX($E$5:$E$204,MATCH($N15,$A$5:$A$204,0)),"")))) | S15: =IF($A15="","",IF($H15<>"",$H15,IF($N15="","",IFERROR(INDEX($H$5:$H$204,MATCH($N15,$A$5:$A$204,0)),"")))) | T15: =IF($A15="","",IF($F15<>"",$F15,IF($N15="","",IFERROR(INDEX($F$5:$F$204,MATCH($N15,$A$5:$A$204,0)),"")))) | U15: =IF($A15="","",SUMIFS(MVT_NET,MVT_LOT,$A15)) | V15: =IF($A15="","",COUNTIFS(MVT_LOT,$A15,MVT_BRUT,"<>0")) | W15: =IF($A15="","",COUNTIFS(QC_LOT,$A15)) | X15: =IF($A15="","",IFERROR(INDEX(QC_DEC,MATCH($A15,QC_CLEDER,0)),"")) | Y15: =IF($A15="","",IF(COUNTIF($A$5:$A$204,$A15)>1,IF(SUMPRODUCT(($A$5:$A$204=$A15)*(($C$5:$C$204<>$C15)+($D$5:$D$204<>$D15)))>0,"INCOHERENCE","LOT EN DOUBLE"),"OK")) | Z15: =IF($A15="",0,IF(AND($O15<>"",$A15<>R_LOT,$O15=IFERROR(INDEX(LOT_EXTE,MATCH(R_LOT,LOT_KEY,0)),"#")),1,0)) -> 0 | AA15: =IF($Z15=0,"",COUNTIF($Z$5:$Z15,1))
N16: =IF($A16="","",IF($L16<>"",$L16,IF(IFERROR(INDEX(RES_LOTSRC,MATCH($A16,RES_LOTEFF,0)),"")=$A16,"",IFERROR(INDEX(RES_LOTSRC,MATCH($A16,RES_LOTEFF,0)),"")))) | O16: =IF($A16="","",IF($B16<>"",$B16,IF($N16="","",IFERROR(INDEX($B$5:$B$204,MATCH($N16,$A$5:$A$204,0)),"")))) | P16: =IF($A16="","",IF($C16<>"",$C16,IF($N16="","",IFERROR(INDEX($C$5:$C$204,MATCH($N16,$A$5:$A$204,0)),"")))) | Q16: =IF($A16="","",IF($D16<>"",$D16,IF($N16="","",IFERROR(INDEX($D$5:$D$204,MATCH($N16,$A$5:$A$204,0)),"")))) | R16: =IF($A16="","",IF($E16<>"",$E16,IF($N16="","",IFERROR(INDEX($E$5:$E$204,MATCH($N16,$A$5:$A$204,0)),"")))) | S16: =IF($A16="","",IF($H16<>"",$H16,IF($N16="","",IFERROR(INDEX($H$5:$H$204,MATCH($N16,$A$5:$A$204,0)),"")))) | T16: =IF($A16="","",IF($F16<>"",$F16,IF($N16="","",IFERROR(INDEX($F$5:$F$204,MATCH($N16,$A$5:$A$204,0)),"")))) | U16: =IF($A16="","",SUMIFS(MVT_NET,MVT_LOT,$A16)) | V16: =IF($A16="","",COUNTIFS(MVT_LOT,$A16,MVT_BRUT,"<>0")) | W16: =IF($A16="","",COUNTIFS(QC_LOT,$A16)) | X16: =IF($A16="","",IFERROR(INDEX(QC_DEC,MATCH($A16,QC_CLEDER,0)),"")) | Y16: =IF($A16="","",IF(COUNTIF($A$5:$A$204,$A16)>1,IF(SUMPRODUCT(($A$5:$A$204=$A16)*(($C$5:$C$204<>$C16)+($D$5:$D$204<>$D16)))>0,"INCOHERENCE","LOT EN DOUBLE"),"OK")) | Z16: =IF($A16="",0,IF(AND($O16<>"",$A16<>R_LOT,$O16=IFERROR(INDEX(LOT_EXTE,MATCH(R_LOT,LOT_KEY,0)),"#")),1,0)) -> 0 | AA16: =IF($Z16=0,"",COUNTIF($Z$5:$Z16,1))
N17: =IF($A17="","",IF($L17<>"",$L17,IF(IFERROR(INDEX(RES_LOTSRC,MATCH($A17,RES_LOTEFF,0)),"")=$A17,"",IFERROR(INDEX(RES_LOTSRC,MATCH($A17,RES_LOTEFF,0)),"")))) | O17: =IF($A17="","",IF($B17<>"",$B17,IF($N17="","",IFERROR(INDEX($B$5:$B$204,MATCH($N17,$A$5:$A$204,0)),"")))) | P17: =IF($A17="","",IF($C17<>"",$C17,IF($N17="","",IFERROR(INDEX($C$5:$C$204,MATCH($N17,$A$5:$A$204,0)),"")))) | Q17: =IF($A17="","",IF($D17<>"",$D17,IF($N17="","",IFERROR(INDEX($D$5:$D$204,MATCH($N17,$A$5:$A$204,0)),"")))) | R17: =IF($A17="","",IF($E17<>"",$E17,IF($N17="","",IFERROR(INDEX($E$5:$E$204,MATCH($N17,$A$5:$A$204,0)),"")))) | S17: =IF($A17="","",IF($H17<>"",$H17,IF($N17="","",IFERROR(INDEX($H$5:$H$204,MATCH($N17,$A$5:$A$204,0)),"")))) | T17: =IF($A17="","",IF($F17<>"",$F17,IF($N17="","",IFERROR(INDEX($F$5:$F$204,MATCH($N17,$A$5:$A$204,0)),"")))) | U17: =IF($A17="","",SUMIFS(MVT_NET,MVT_LOT,$A17)) | V17: =IF($A17="","",COUNTIFS(MVT_LOT,$A17,MVT_BRUT,"<>0")) | W17: =IF($A17="","",COUNTIFS(QC_LOT,$A17)) | X17: =IF($A17="","",IFERROR(INDEX(QC_DEC,MATCH($A17,QC_CLEDER,0)),"")) | Y17: =IF($A17="","",IF(COUNTIF($A$5:$A$204,$A17)>1,IF(SUMPRODUCT(($A$5:$A$204=$A17)*(($C$5:$C$204<>$C17)+($D$5:$D$204<>$D17)))>0,"INCOHERENCE","LOT EN DOUBLE"),"OK")) | Z17: =IF($A17="",0,IF(AND($O17<>"",$A17<>R_LOT,$O17=IFERROR(INDEX(LOT_EXTE,MATCH(R_LOT,LOT_KEY,0)),"#")),1,0)) -> 0 | AA17: =IF($Z17=0,"",COUNTIF($Z$5:$Z17,1))
N18: =IF($A18="","",IF($L18<>"",$L18,IF(IFERROR(INDEX(RES_LOTSRC,MATCH($A18,RES_LOTEFF,0)),"")=$A18,"",IFERROR(INDEX(RES_LOTSRC,MATCH($A18,RES_LOTEFF,0)),"")))) | O18: =IF($A18="","",IF($B18<>"",$B18,IF($N18="","",IFERROR(INDEX($B$5:$B$204,MATCH($N18,$A$5:$A$204,0)),"")))) | P18: =IF($A18="","",IF($C18<>"",$C18,IF($N18="","",IFERROR(INDEX($C$5:$C$204,MATCH($N18,$A$5:$A$204,0)),"")))) | Q18: =IF($A18="","",IF($D18<>"",$D18,IF($N18="","",IFERROR(INDEX($D$5:$D$204,MATCH($N18,$A$5:$A$204,0)),"")))) | R18: =IF($A18="","",IF($E18<>"",$E18,IF($N18="","",IFERROR(INDEX($E$5:$E$204,MATCH($N18,$A$5:$A$204,0)),"")))) | S18: =IF($A18="","",IF($H18<>"",$H18,IF($N18="","",IFERROR(INDEX($H$5:$H$204,MATCH($N18,$A$5:$A$204,0)),"")))) | T18: =IF($A18="","",IF($F18<>"",$F18,IF($N18="","",IFERROR(INDEX($F$5:$F$204,MATCH($N18,$A$5:$A$204,0)),"")))) | U18: =IF($A18="","",SUMIFS(MVT_NET,MVT_LOT,$A18)) | V18: =IF($A18="","",COUNTIFS(MVT_LOT,$A18,MVT_BRUT,"<>0")) | W18: =IF($A18="","",COUNTIFS(QC_LOT,$A18)) | X18: =IF($A18="","",IFERROR(INDEX(QC_DEC,MATCH($A18,QC_CLEDER,0)),"")) | Y18: =IF($A18="","",IF(COUNTIF($A$5:$A$204,$A18)>1,IF(SUMPRODUCT(($A$5:$A$204=$A18)*(($C$5:$C$204<>$C18)+($D$5:$D$204<>$D18)))>0,"INCOHERENCE","LOT EN DOUBLE"),"OK")) | Z18: =IF($A18="",0,IF(AND($O18<>"",$A18<>R_LOT,$O18=IFERROR(INDEX(LOT_EXTE,MATCH(R_LOT,LOT_KEY,0)),"#")),1,0)) -> 0 | AA18: =IF($Z18=0,"",COUNTIF($Z$5:$Z18,1))
N19: =IF($A19="","",IF($L19<>"",$L19,IF(IFERROR(INDEX(RES_LOTSRC,MATCH($A19,RES_LOTEFF,0)),"")=$A19,"",IFERROR(INDEX(RES_LOTSRC,MATCH($A19,RES_LOTEFF,0)),"")))) | O19: =IF($A19="","",IF($B19<>"",$B19,IF($N19="","",IFERROR(INDEX($B$5:$B$204,MATCH($N19,$A$5:$A$204,0)),"")))) | P19: =IF($A19="","",IF($C19<>"",$C19,IF($N19="","",IFERROR(INDEX($C$5:$C$204,MATCH($N19,$A$5:$A$204,0)),"")))) | Q19: =IF($A19="","",IF($D19<>"",$D19,IF($N19="","",IFERROR(INDEX($D$5:$D$204,MATCH($N19,$A$5:$A$204,0)),"")))) | R19: =IF($A19="","",IF($E19<>"",$E19,IF($N19="","",IFERROR(INDEX($E$5:$E$204,MATCH($N19,$A$5:$A$204,0)),"")))) | S19: =IF($A19="","",IF($H19<>"",$H19,IF($N19="","",IFERROR(INDEX($H$5:$H$204,MATCH($N19,$A$5:$A$204,0)),"")))) | T19: =IF($A19="","",IF($F19<>"",$F19,IF($N19="","",IFERROR(INDEX($F$5:$F$204,MATCH($N19,$A$5:$A$204,0)),"")))) | U19: =IF($A19="","",SUMIFS(MVT_NET,MVT_LOT,$A19)) | V19: =IF($A19="","",COUNTIFS(MVT_LOT,$A19,MVT_BRUT,"<>0")) | W19: =IF($A19="","",COUNTIFS(QC_LOT,$A19)) | X19: =IF($A19="","",IFERROR(INDEX(QC_DEC,MATCH($A19,QC_CLEDER,0)),"")) | Y19: =IF($A19="","",IF(COUNTIF($A$5:$A$204,$A19)>1,IF(SUMPRODUCT(($A$5:$A$204=$A19)*(($C$5:$C$204<>$C19)+($D$5:$D$204<>$D19)))>0,"INCOHERENCE","LOT EN DOUBLE"),"OK")) | Z19: =IF($A19="",0,IF(AND($O19<>"",$A19<>R_LOT,$O19=IFERROR(INDEX(LOT_EXTE,MATCH(R_LOT,LOT_KEY,0)),"#")),1,0)) -> 0 | AA19: =IF($Z19=0,"",COUNTIF($Z$5:$Z19,1))
N20: =IF($A20="","",IF($L20<>"",$L20,IF(IFERROR(INDEX(RES_LOTSRC,MATCH($A20,RES_LOTEFF,0)),"")=$A20,"",IFERROR(INDEX(RES_LOTSRC,MATCH($A20,RES_LOTEFF,0)),"")))) | O20: =IF($A20="","",IF($B20<>"",$B20,IF($N20="","",IFERROR(INDEX($B$5:$B$204,MATCH($N20,$A$5:$A$204,0)),"")))) | P20: =IF($A20="","",IF($C20<>"",$C20,IF($N20="","",IFERROR(INDEX($C$5:$C$204,MATCH($N20,$A$5:$A$204,0)),"")))) | Q20: =IF($A20="","",IF($D20<>"",$D20,IF($N20="","",IFERROR(INDEX($D$5:$D$204,MATCH($N20,$A$5:$A$204,0)),"")))) | R20: =IF($A20="","",IF($E20<>"",$E20,IF($N20="","",IFERROR(INDEX($E$5:$E$204,MATCH($N20,$A$5:$A$204,0)),"")))) | S20: =IF($A20="","",IF($H20<>"",$H20,IF($N20="","",IFERROR(INDEX($H$5:$H$204,MATCH($N20,$A$5:$A$204,0)),"")))) | T20: =IF($A20="","",IF($F20<>"",$F20,IF($N20="","",IFERROR(INDEX($F$5:$F$204,MATCH($N20,$A$5:$A$204,0)),"")))) | U20: =IF($A20="","",SUMIFS(MVT_NET,MVT_LOT,$A20)) | V20: =IF($A20="","",COUNTIFS(MVT_LOT,$A20,MVT_BRUT,"<>0")) | W20: =IF($A20="","",COUNTIFS(QC_LOT,$A20)) | X20: =IF($A20="","",IFERROR(INDEX(QC_DEC,MATCH($A20,QC_CLEDER,0)),"")) | Y20: =IF($A20="","",IF(COUNTIF($A$5:$A$204,$A20)>1,IF(SUMPRODUCT(($A$5:$A$204=$A20)*(($C$5:$C$204<>$C20)+($D$5:$D$204<>$D20)))>0,"INCOHERENCE","LOT EN DOUBLE"),"OK")) | Z20: =IF($A20="",0,IF(AND($O20<>"",$A20<>R_LOT,$O20=IFERROR(INDEX(LOT_EXTE,MATCH(R_LOT,LOT_KEY,0)),"#")),1,0)) -> 0 | AA20: =IF($Z20=0,"",COUNTIF($Z$5:$Z20,1))
N21: =IF($A21="","",IF($L21<>"",$L21,IF(IFERROR(INDEX(RES_LOTSRC,MATCH($A21,RES_LOTEFF,0)),"")=$A21,"",IFERROR(INDEX(RES_LOTSRC,MATCH($A21,RES_LOTEFF,0)),"")))) | O21: =IF($A21="","",IF($B21<>"",$B21,IF($N21="","",IFERROR(INDEX($B$5:$B$204,MATCH($N21,$A$5:$A$204,0)),"")))) | P21: =IF($A21="","",IF($C21<>"",$C21,IF($N21="","",IFERROR(INDEX($C$5:$C$204,MATCH($N21,$A$5:$A$204,0)),"")))) | Q21: =IF($A21="","",IF($D21<>"",$D21,IF($N21="","",IFERROR(INDEX($D$5:$D$204,MATCH($N21,$A$5:$A$204,0)),"")))) | R21: =IF($A21="","",IF($E21<>"",$E21,IF($N21="","",IFERROR(INDEX($E$5:$E$204,MATCH($N21,$A$5:$A$204,0)),"")))) | S21: =IF($A21="","",IF($H21<>"",$H21,IF($N21="","",IFERROR(INDEX($H$5:$H$204,MATCH($N21,$A$5:$A$204,0)),"")))) | T21: =IF($A21="","",IF($F21<>"",$F21,IF($N21="","",IFERROR(INDEX($F$5:$F$204,MATCH($N21,$A$5:$A$204,0)),"")))) | U21: =IF($A21="","",SUMIFS(MVT_NET,MVT_LOT,$A21)) | V21: =IF($A21="","",COUNTIFS(MVT_LOT,$A21,MVT_BRUT,"<>0")) | W21: =IF($A21="","",COUNTIFS(QC_LOT,$A21)) | X21: =IF($A21="","",IFERROR(INDEX(QC_DEC,MATCH($A21,QC_CLEDER,0)),"")) | Y21: =IF($A21="","",IF(COUNTIF($A$5:$A$204,$A21)>1,IF(SUMPRODUCT(($A$5:$A$204=$A21)*(($C$5:$C$204<>$C21)+($D$5:$D$204<>$D21)))>0,"INCOHERENCE","LOT EN DOUBLE"),"OK")) | Z21: =IF($A21="",0,IF(AND($O21<>"",$A21<>R_LOT,$O21=IFERROR(INDEX(LOT_EXTE,MATCH(R_LOT,LOT_KEY,0)),"#")),1,0)) -> 0 | AA21: =IF($Z21=0,"",COUNTIF($Z$5:$Z21,1))
N22: =IF($A22="","",IF($L22<>"",$L22,IF(IFERROR(INDEX(RES_LOTSRC,MATCH($A22,RES_LOTEFF,0)),"")=$A22,"",IFERROR(INDEX(RES_LOTSRC,MATCH($A22,RES_LOTEFF,0)),"")))) | O22: =IF($A22="","",IF($B22<>"",$B22,IF($N22="","",IFERROR(INDEX($B$5:$B$204,MATCH($N22,$A$5:$A$204,0)),"")))) | P22: =IF($A22="","",IF($C22<>"",$C22,IF($N22="","",IFERROR(INDEX($C$5:$C$204,MATCH($N22,$A$5:$A$204,0)),"")))) | Q22: =IF($A22="","",IF($D22<>"",$D22,IF($N22="","",IFERROR(INDEX($D$5:$D$204,MATCH($N22,$A$5:$A$204,0)),"")))) | R22: =IF($A22="","",IF($E22<>"",$E22,IF($N22="","",IFERROR(INDEX($E$5:$E$204,MATCH($N22,$A$5:$A$204,0)),"")))) | S22: =IF($A22="","",IF($H22<>"",$H22,IF($N22="","",IFERROR(INDEX($H$5:$H$204,MATCH($N22,$A$5:$A$204,0)),"")))) | T22: =IF($A22="","",IF($F22<>"",$F22,IF($N22="","",IFERROR(INDEX($F$5:$F$204,MATCH($N22,$A$5:$A$204,0)),"")))) | U22: =IF($A22="","",SUMIFS(MVT_NET,MVT_LOT,$A22)) | V22: =IF($A22="","",COUNTIFS(MVT_LOT,$A22,MVT_BRUT,"<>0")) | W22: =IF($A22="","",COUNTIFS(QC_LOT,$A22)) | X22: =IF($A22="","",IFERROR(INDEX(QC_DEC,MATCH($A22,QC_CLEDER,0)),"")) | Y22: =IF($A22="","",IF(COUNTIF($A$5:$A$204,$A22)>1,IF(SUMPRODUCT(($A$5:$A$204=$A22)*(($C$5:$C$204<>$C22)+($D$5:$D$204<>$D22)))>0,"INCOHERENCE","LOT EN DOUBLE"),"OK")) | Z22: =IF($A22="",0,IF(AND($O22<>"",$A22<>R_LOT,$O22=IFERROR(INDEX(LOT_EXTE,MATCH(R_LOT,LOT_KEY,0)),"#")),1,0)) -> 0 | AA22: =IF($Z22=0,"",COUNTIF($Z$5:$Z22,1))
N23: =IF($A23="","",IF($L23<>"",$L23,IF(IFERROR(INDEX(RES_LOTSRC,MATCH($A23,RES_LOTEFF,0)),"")=$A23,"",IFERROR(INDEX(RES_LOTSRC,MATCH($A23,RES_LOTEFF,0)),"")))) | O23: =IF($A23="","",IF($B23<>"",$B23,IF($N23="","",IFERROR(INDEX($B$5:$B$204,MATCH($N23,$A$5:$A$204,0)),"")))) | P23: =IF($A23="","",IF($C23<>"",$C23,IF($N23="","",IFERROR(INDEX($C$5:$C$204,MATCH($N23,$A$5:$A$204,0)),"")))) | Q23: =IF($A23="","",IF($D23<>"",$D23,IF($N23="","",IFERROR(INDEX($D$5:$D$204,MATCH($N23,$A$5:$A$204,0)),"")))) | R23: =IF($A23="","",IF($E23<>"",$E23,IF($N23="","",IFERROR(INDEX($E$5:$E$204,MATCH($N23,$A$5:$A$204,0)),"")))) | S23: =IF($A23="","",IF($H23<>"",$H23,IF($N23="","",IFERROR(INDEX($H$5:$H$204,MATCH($N23,$A$5:$A$204,0)),"")))) | T23: =IF($A23="","",IF($F23<>"",$F23,IF($N23="","",IFERROR(INDEX($F$5:$F$204,MATCH($N23,$A$5:$A$204,0)),"")))) | U23: =IF($A23="","",SUMIFS(MVT_NET,MVT_LOT,$A23)) | V23: =IF($A23="","",COUNTIFS(MVT_LOT,$A23,MVT_BRUT,"<>0")) | W23: =IF($A23="","",COUNTIFS(QC_LOT,$A23)) | X23: =IF($A23="","",IFERROR(INDEX(QC_DEC,MATCH($A23,QC_CLEDER,0)),"")) | Y23: =IF($A23="","",IF(COUNTIF($A$5:$A$204,$A23)>1,IF(SUMPRODUCT(($A$5:$A$204=$A23)*(($C$5:$C$204<>$C23)+($D$5:$D$204<>$D23)))>0,"INCOHERENCE","LOT EN DOUBLE"),"OK")) | Z23: =IF($A23="",0,IF(AND($O23<>"",$A23<>R_LOT,$O23=IFERROR(INDEX(LOT_EXTE,MATCH(R_LOT,LOT_KEY,0)),"#")),1,0)) -> 0 | AA23: =IF($Z23=0,"",COUNTIF($Z$5:$Z23,1))
N24: =IF($A24="","",IF($L24<>"",$L24,IF(IFERROR(INDEX(RES_LOTSRC,MATCH($A24,RES_LOTEFF,0)),"")=$A24,"",IFERROR(INDEX(RES_LOTSRC,MATCH($A24,RES_LOTEFF,0)),"")))) | O24: =IF($A24="","",IF($B24<>"",$B24,IF($N24="","",IFERROR(INDEX($B$5:$B$204,MATCH($N24,$A$5:$A$204,0)),"")))) | P24: =IF($A24="","",IF($C24<>"",$C24,IF($N24="","",IFERROR(INDEX($C$5:$C$204,MATCH($N24,$A$5:$A$204,0)),"")))) | Q24: =IF($A24="","",IF($D24<>"",$D24,IF($N24="","",IFERROR(INDEX($D$5:$D$204,MATCH($N24,$A$5:$A$204,0)),"")))) | R24: =IF($A24="","",IF($E24<>"",$E24,IF($N24="","",IFERROR(INDEX($E$5:$E$204,MATCH($N24,$A$5:$A$204,0)),"")))) | S24: =IF($A24="","",IF($H24<>"",$H24,IF($N24="","",IFERROR(INDEX($H$5:$H$204,MATCH($N24,$A$5:$A$204,0)),"")))) | T24: =IF($A24="","",IF($F24<>"",$F24,IF($N24="","",IFERROR(INDEX($F$5:$F$204,MATCH($N24,$A$5:$A$204,0)),"")))) | U24: =IF($A24="","",SUMIFS(MVT_NET,MVT_LOT,$A24)) | V24: =IF($A24="","",COUNTIFS(MVT_LOT,$A24,MVT_BRUT,"<>0")) | W24: =IF($A24="","",COUNTIFS(QC_LOT,$A24)) | X24: =IF($A24="","",IFERROR(INDEX(QC_DEC,MATCH($A24,QC_CLEDER,0)),"")) | Y24: =IF($A24="","",IF(COUNTIF($A$5:$A$204,$A24)>1,IF(SUMPRODUCT(($A$5:$A$204=$A24)*(($C$5:$C$204<>$C24)+($D$5:$D$204<>$D24)))>0,"INCOHERENCE","LOT EN DOUBLE"),"OK")) | Z24: =IF($A24="",0,IF(AND($O24<>"",$A24<>R_LOT,$O24=IFERROR(INDEX(LOT_EXTE,MATCH(R_LOT,LOT_KEY,0)),"#")),1,0)) -> 0 | AA24: =IF($Z24=0,"",COUNTIF($Z$5:$Z24,1))
N25: =IF($A25="","",IF($L25<>"",$L25,IF(IFERROR(INDEX(RES_LOTSRC,MATCH($A25,RES_LOTEFF,0)),"")=$A25,"",IFERROR(INDEX(RES_LOTSRC,MATCH($A25,RES_LOTEFF,0)),"")))) | O25: =IF($A25="","",IF($B25<>"",$B25,IF($N25="","",IFERROR(INDEX($B$5:$B$204,MATCH($N25,$A$5:$A$204,0)),"")))) | P25: =IF($A25="","",IF($C25<>"",$C25,IF($N25="","",IFERROR(INDEX($C$5:$C$204,MATCH($N25,$A$5:$A$204,0)),"")))) | Q25: =IF($A25="","",IF($D25<>"",$D25,IF($N25="","",IFERROR(INDEX($D$5:$D$204,MATCH($N25,$A$5:$A$204,0)),"")))) | R25: =IF($A25="","",IF($E25<>"",$E25,IF($N25="","",IFERROR(INDEX($E$5:$E$204,MATCH($N25,$A$5:$A$204,0)),"")))) | S25: =IF($A25="","",IF($H25<>"",$H25,IF($N25="","",IFERROR(INDEX($H$5:$H$204,MATCH($N25,$A$5:$A$204,0)),"")))) | T25: =IF($A25="","",IF($F25<>"",$F25,IF($N25="","",IFERROR(INDEX($F$5:$F$204,MATCH($N25,$A$5:$A$204,0)),"")))) | U25: =IF($A25="","",SUMIFS(MVT_NET,MVT_LOT,$A25)) | V25: =IF($A25="","",COUNTIFS(MVT_LOT,$A25,MVT_BRUT,"<>0")) | W25: =IF($A25="","",COUNTIFS(QC_LOT,$A25)) | X25: =IF($A25="","",IFERROR(INDEX(QC_DEC,MATCH($A25,QC_CLEDER,0)),"")) | Y25: =IF($A25="","",IF(COUNTIF($A$5:$A$204,$A25)>1,IF(SUMPRODUCT(($A$5:$A$204=$A25)*(($C$5:$C$204<>$C25)+($D$5:$D$204<>$D25)))>0,"INCOHERENCE","LOT EN DOUBLE"),"OK")) | Z25: =IF($A25="",0,IF(AND($O25<>"",$A25<>R_LOT,$O25=IFERROR(INDEX(LOT_EXTE,MATCH(R_LOT,LOT_KEY,0)),"#")),1,0)) -> 0 | AA25: =IF($Z25=0,"",COUNTIF($Z$5:$Z25,1))
N26: =IF($A26="","",IF($L26<>"",$L26,IF(IFERROR(INDEX(RES_LOTSRC,MATCH($A26,RES_LOTEFF,0)),"")=$A26,"",IFERROR(INDEX(RES_LOTSRC,MATCH($A26,RES_LOTEFF,0)),"")))) | O26: =IF($A26="","",IF($B26<>"",$B26,IF($N26="","",IFERROR(INDEX($B$5:$B$204,MATCH($N26,$A$5:$A$204,0)),"")))) | P26: =IF($A26="","",IF($C26<>"",$C26,IF($N26="","",IFERROR(INDEX($C$5:$C$204,MATCH($N26,$A$5:$A$204,0)),"")))) | Q26: =IF($A26="","",IF($D26<>"",$D26,IF($N26="","",IFERROR(INDEX($D$5:$D$204,MATCH($N26,$A$5:$A$204,0)),"")))) | R26: =IF($A26="","",IF($E26<>"",$E26,IF($N26="","",IFERROR(INDEX($E$5:$E$204,MATCH($N26,$A$5:$A$204,0)),"")))) | S26: =IF($A26="","",IF($H26<>"",$H26,IF($N26="","",IFERROR(INDEX($H$5:$H$204,MATCH($N26,$A$5:$A$204,0)),"")))) | T26: =IF($A26="","",IF($F26<>"",$F26,IF($N26="","",IFERROR(INDEX($F$5:$F$204,MATCH($N26,$A$5:$A$204,0)),"")))) | U26: =IF($A26="","",SUMIFS(MVT_NET,MVT_LOT,$A26)) | V26: =IF($A26="","",COUNTIFS(MVT_LOT,$A26,MVT_BRUT,"<>0")) | W26: =IF($A26="","",COUNTIFS(QC_LOT,$A26)) | X26: =IF($A26="","",IFERROR(INDEX(QC_DEC,MATCH($A26,QC_CLEDER,0)),"")) | Y26: =IF($A26="","",IF(COUNTIF($A$5:$A$204,$A26)>1,IF(SUMPRODUCT(($A$5:$A$204=$A26)*(($C$5:$C$204<>$C26)+($D$5:$D$204<>$D26)))>0,"INCOHERENCE","LOT EN DOUBLE"),"OK")) | Z26: =IF($A26="",0,IF(AND($O26<>"",$A26<>R_LOT,$O26=IFERROR(INDEX(LOT_EXTE,MATCH(R_LOT,LOT_KEY,0)),"#")),1,0)) -> 0 | AA26: =IF($Z26=0,"",COUNTIF($Z$5:$Z26,1))
... N204: =IF($A204="","",IF($L204<>"",$L204,IF(IFERROR(INDEX(RES_LOTSRC,MATCH($A204,RES_LOTEFF,0)),"")=$A204,"",IFERROR(INDEX(RES_LOTSRC,MATCH($A204,RES_LOTEFF,0)),"")))) | O204: =IF($A204="","",IF($B204<>"",$B204,IF($N204="","",IFERROR(INDEX($B$5:$B$204,MATCH($N204,$A$5:$A$204,0)),"")))) | P204: =IF($A204="","",IF($C204<>"",$C204,IF($N204="","",IFERROR(INDEX($C$5:$C$204,MATCH($N204,$A$5:$A$204,0)),"")))) | Q204: =IF($A204="","",IF($D204<>"",$D204,IF($N204="","",IFERROR(INDEX($D$5:$D$204,MATCH($N204,$A$5:$A$204,0)),"")))) | R204: =IF($A204="","",IF($E204<>"",$E204,IF($N204="","",IFERROR(INDEX($E$5:$E$204,MATCH($N204,$A$5:$A$204,0)),"")))) | S204: =IF($A204="","",IF($H204<>"",$H204,IF($N204="","",IFERROR(INDEX($H$5:$H$204,MATCH($N204,$A$5:$A$204,0)),"")))) | T204: =IF($A204="","",IF($F204<>"",$F204,IF($N204="","",IFERROR(INDEX($F$5:$F$204,MATCH($N204,$A$5:$A$204,0)),"")))) | U204: =IF($A204="","",SUMIFS(MVT_NET,MVT_LOT,$A204)) | V204: =IF($A204="","",COUNTIFS(MVT_LOT,$A204,MVT_BRUT,"<>0")) | W204: =IF($A204="","",COUNTIFS(QC_LOT,$A204)) | X204: =IF($A204="","",IFERROR(INDEX(QC_DEC,MATCH($A204,QC_CLEDER,0)),"")) | Y204: =IF($A204="","",IF(COUNTIF($A$5:$A$204,$A204)>1,IF(SUMPRODUCT(($A$5:$A$204=$A204)*(($C$5:$C$204<>$C204)+($D$5:$D$204<>$D204)))>0,"INCOHERENCE","LOT EN DOUBLE"),"OK")) | Z204: =IF($A204="",0,IF(AND($O204<>"",$A204<>R_LOT,$O204=IFERROR(INDEX(LOT_EXTE,MATCH(R_LOT,LOT_KEY,0)),"#")),1,0)) -> 0 | AA204: =IF($Z204=0,"",COUNTIF($Z$5:$Z204,1))

Sheet OPERATIONS
A1: OPERATIONS DE STOCK - RECEPTION / TRANSFERT / CONSOMMATION / AJUSTEMENT
A2: RECEPTION = entree sur un emplacement. TRANSFERT = sortie d'un emplacement + entree sur un autre (meme quantite). CONSOMMATION = sortie de la seule quantite consommee. AJUSTEMENT = correction d'inventaire sur l'emplacement de destination : quantite signee (negative = perte) et MOTIF obligatoire.
A3: Saisie minimale : DATE, TYPE, LOT INTERNE, EMPLACEMENT(S), QUANTITE. Le reste est deduit du lot.
A4: ID OPERATION | B4: DATE | C4: TYPE | D4: LOT INTERNE | E4: EMPL. SOURCE | F4: EMPL. DESTINATION | G4: QUANTITE (KG) | H4: MOTIF / DESTINATION | I4: OBSERVATION | J4: LOT EXTERNE | K4: ESPECE | L4: PRODUCTEUR | M4: CLASSE SOURCE | N4: CLASSE DEST. | O4: VALIDE | P4: DISPO AVANT (KG) | Q4: STATUT | R4: IMPACT STOCK | S4: CONTROLE / ACTION
A5: =IF($C5="","","OP-"&TEXT(ROW()-4,"000")) -> OP-001 | B5: 46237 | C5: RECEPTION | D5: 255 | F5: OCEAMIC 2 | G5: 1000 | H5: Reception usine | I5: Scenario 1 - nouveau lot interne | J5: =IF($D5="","",IFERROR(INDEX(LOT_EXTE,MATCH($D5,LOT_KEY,0)),"")) -> L-EXT-255 | K5: =IF($D5="","",IFERROR(INDEX(LOT_PRODE,MATCH($D5,LOT_KEY,0)),"LOT NON REFERENCE")) -> Sardine | L5: =IF($D5="","",IFERROR(INDEX(LOT_FOURNE,MATCH($D5,LOT_KEY,0)),"")) -> Fournisseur local | M5: =IF($E5="","",IFERROR(INDEX(EMPL_CLASSE,MATCH($E5,EMPL_KEY,0)),"?")) | N5: =IF($F5="","",IFERROR(INDEX(EMPL_CLASSE,MATCH($F5,EMPL_KEY,0)),"?")) -> INTERNE | O5: =IF($C5="",0,IF(OR($B5="",$D5=""),0,IF($C5="AJUSTEMENT",IF(OR(NOT(ISNUMBER($G5)),$G5=0,$F5="",$H5=""),0,1),IF(OR(NOT(ISNUMBER($G5)),$G5<=0),0,IF($C5="RECEPTION",IF($F5="",0,1),IF($C5="CONSOMMATION",IF($E5="",0,1),IF(OR($E5="",$F5="",$E5=$F5),0,1))))))) -> 1 | P5: =IF(OR($O5=0,$C5="RECEPTION"),"",IF($C5="AJUSTEMENT",IF($G5>0,"",SUMIFS(MVT_BRUT,MVT_LOT,$D5,MVT_EMPL,$F5)-$G5),SUMIFS(MVT_BRUT,MVT_LOT,$D5,MVT_EMPL,$E5)+$G5)) | Q5: =IF($C5="","",IF($O5=0,"DONNEES MANQUANTES",IF($C5="RECEPTION","OK",IF(AND($C5="AJUSTEMENT",$G5>0),"OK",IF($P5<=0,"EMPLACEMENT INCOHERENT",IF(ABS($G5)>$P5+0.001,"STOCK INSUFFISANT","OK")))))) -> OK | R5: =IF($Q5="OK",1,0) -> 1 | S5: =IF($C5="","",IF($O5=0,"A COMPLETER : "&IF($B5="","DATE; ","")&IF($D5="","LOT INTERNE; ","")&IF(NOT(ISNUMBER($G5)),"QUANTITE; ",IF(AND($C5="AJUSTEMENT",$G5=0),"QUANTITE <> 0; ",IF(AND($C5<>"AJUSTEMENT",$G5<=0),"QUANTITE > 0; ","")))&IF(AND($C5="AJUSTEMENT",$H5=""),"MOTIF; ","")&IF(AND(OR($C5="TRANSFERT",$C5="CONSOMMATION"),$E5=""),"EMPL. SOURCE; ","")&IF(AND($C5<>"CONSOMMATION",$F5=""),"EMPL. DESTINATION; ","")&IF(AND($C5="TRANSFERT",$E5<>"",$E5=$F5),"SOURCE = DESTINATION; ",""),IF($Q5="EMPLACEMENT INCOHERENT","Le lot "&$D5&" n'existe pas sur cet emplacement (stock 0). Verifier l'emplacement.",IF($Q5="STOCK INSUFFISANT","Disponible avant operation : "&TEXT($P5,"#,##0.00")&" kg. Ligne NON comptee en stock.",IF(COUNTIFS($B$5:$B$304,$B5,$C$5:$C$304,$C5,$D$5:$D$304,$D5,$G$5:$G$304,$G5)>1,"Doublon possible (meme date, type, lot et quantite).",IF($K5="LOT NON REFERENCE","Creer d'abord la fiche du lot dans l'onglet LOTS.",""))))))
A6: =IF($C6="","","OP-"&TEXT(ROW()-4,"000")) -> OP-002 | B6: 46238 | C6: RECEPTION | D6: 256 | F6: SARMA | G6: 2000 | H6: Reception entrepot externe | I6: Scenario 2 - lot externe | J6: =IF($D6="","",IFERROR(INDEX(LOT_EXTE,MATCH($D6,LOT_KEY,0)),"")) -> L-EXT-256 | K6: =IF($D6="","",IFERROR(INDEX(LOT_PRODE,MATCH($D6,LOT_KEY,0)),"LOT NON REFERENCE")) -> Maquereau | L6: =IF($D6="","",IFERROR(INDEX(LOT_FOURNE,MATCH($D6,LOT_KEY,0)),"")) -> Producteur Boujdour | M6: =IF($E6="","",IFERROR(INDEX(EMPL_CLASSE,MATCH($E6,EMPL_KEY,0)),"?")) | N6: =IF($F6="","",IFERROR(INDEX(EMPL_CLASSE,MATCH($F6,EMPL_KEY,0)),"?")) -> EXTERNE | O6: =IF($C6="",0,IF(OR($B6="",$D6=""),0,IF($C6="AJUSTEMENT",IF(OR(NOT(ISNUMBER($G6)),$G6=0,$F6="",$H6=""),0,1),IF(OR(NOT(ISNUMBER($G6)),$G6<=0),0,IF($C6="RECEPTION",IF($F6="",0,1),IF($C6="CONSOMMATION",IF($E6="",0,1),IF(OR($E6="",$F6="",$E6=$F6),0,1))))))) -> 1 | P6: =IF(OR($O6=0,$C6="RECEPTION"),"",IF($C6="AJUSTEMENT",IF($G6>0,"",SUMIFS(MVT_BRUT,MVT_LOT,$D6,MVT_EMPL,$F6)-$G6),SUMIFS(MVT_BRUT,MVT_LOT,$D6,MVT_EMPL,$E6)+$G6)) | Q6: =IF($C6="","",IF($O6=0,"DONNEES MANQUANTES",IF($C6="RECEPTION","OK",IF(AND($C6="AJUSTEMENT",$G6>0),"OK",IF($P6<=0,"EMPLACEMENT INCOHERENT",IF(ABS($G6)>$P6+0.001,"STOCK INSUFFISANT","OK")))))) -> OK | R6: =IF($Q6="OK",1,0) -> 1 | S6: =IF($C6="","",IF($O6=0,"A COMPLETER : "&IF($B6="","DATE; ","")&IF($D6="","LOT INTERNE; ","")&IF(NOT(ISNUMBER($G6)),"QUANTITE; ",IF(AND($C6="AJUSTEMENT",$G6=0),"QUANTITE <> 0; ",IF(AND($C6<>"AJUSTEMENT",$G6<=0),"QUANTITE > 0; ","")))&IF(AND($C6="AJUSTEMENT",$H6=""),"MOTIF; ","")&IF(AND(OR($C6="TRANSFERT",$C6="CONSOMMATION"),$E6=""),"EMPL. SOURCE; ","")&IF(AND($C6<>"CONSOMMATION",$F6=""),"EMPL. DESTINATION; ","")&IF(AND($C6="TRANSFERT",$E6<>"",$E6=$F6),"SOURCE = DESTINATION; ",""),IF($Q6="EMPLACEMENT INCOHERENT","Le lot "&$D6&" n'existe pas sur cet emplacement (stock 0). Verifier l'emplacement.",IF($Q6="STOCK INSUFFISANT","Disponible avant operation : "&TEXT($P6,"#,##0.00")&" kg. Ligne NON comptee en stock.",IF(COUNTIFS($B$5:$B$304,$B6,$C$5:$C$304,$C6,$D$5:$D$304,$D6,$G$5:$G$304,$G6)>1,"Doublon possible (meme date, type, lot et quantite).",IF($K6="LOT NON REFERENCE","Creer d'abord la fiche du lot dans l'onglet LOTS.",""))))))
A7: =IF($C7="","","OP-"&TEXT(ROW()-4,"000")) -> OP-003 | B7: 46239 | C7: RECEPTION | D7: 257 | F7: OCEAMIC 2 | G7: 800 | H7: Reception usine | J7: =IF($D7="","",IFERROR(INDEX(LOT_EXTE,MATCH($D7,LOT_KEY,0)),"")) -> L-EXT-255 | K7: =IF($D7="","",IFERROR(INDEX(LOT_PRODE,MATCH($D7,LOT_KEY,0)),"LOT NON REFERENCE")) -> Sardine | L7: =IF($D7="","",IFERROR(INDEX(LOT_FOURNE,MATCH($D7,LOT_KEY,0)),"")) -> Fournisseur local | M7: =IF($E7="","",IFERROR(INDEX(EMPL_CLASSE,MATCH($E7,EMPL_KEY,0)),"?")) | N7: =IF($F7="","",IFERROR(INDEX(EMPL_CLASSE,MATCH($F7,EMPL_KEY,0)),"?")) -> INTERNE | O7: =IF($C7="",0,IF(OR($B7="",$D7=""),0,IF($C7="AJUSTEMENT",IF(OR(NOT(ISNUMBER($G7)),$G7=0,$F7="",$H7=""),0,1),IF(OR(NOT(ISNUMBER($G7)),$G7<=0),0,IF($C7="RECEPTION",IF($F7="",0,1),IF($C7="CONSOMMATION",IF($E7="",0,1),IF(OR($E7="",$F7="",$E7=$F7),0,1))))))) -> 1 | P7: =IF(OR($O7=0,$C7="RECEPTION"),"",IF($C7="AJUSTEMENT",IF($G7>0,"",SUMIFS(MVT_BRUT,MVT_LOT,$D7,MVT_EMPL,$F7)-$G7),SUMIFS(MVT_BRUT,MVT_LOT,$D7,MVT_EMPL,$E7)+$G7)) | Q7: =IF($C7="","",IF($O7=0,"DONNEES MANQUANTES",IF($C7="RECEPTION","OK",IF(AND($C7="AJUSTEMENT",$G7>0),"OK",IF($P7<=0,"EMPLACEMENT INCOHERENT",IF(ABS($G7)>$P7+0.001,"STOCK INSUFFISANT","OK")))))) -> OK | R7: =IF($Q7="OK",1,0) -> 1 | S7: =IF($C7="","",IF($O7=0,"A COMPLETER : "&IF($B7="","DATE; ","")&IF($D7="","LOT INTERNE; ","")&IF(NOT(ISNUMBER($G7)),"QUANTITE; ",IF(AND($C7="AJUSTEMENT",$G7=0),"QUANTITE <> 0; ",IF(AND($C7<>"AJUSTEMENT",$G7<=0),"QUANTITE > 0; ","")))&IF(AND($C7="AJUSTEMENT",$H7=""),"MOTIF; ","")&IF(AND(OR($C7="TRANSFERT",$C7="CONSOMMATION"),$E7=""),"EMPL. SOURCE; ","")&IF(AND($C7<>"CONSOMMATION",$F7=""),"EMPL. DESTINATION; ","")&IF(AND($C7="TRANSFERT",$E7<>"",$E7=$F7),"SOURCE = DESTINATION; ",""),IF($Q7="EMPLACEMENT INCOHERENT","Le lot "&$D7&" n'existe pas sur cet emplacement (stock 0). Verifier l'emplacement.",IF($Q7="STOCK INSUFFISANT","Disponible avant operation : "&TEXT($P7,"#,##0.00")&" kg. Ligne NON comptee en stock.",IF(COUNTIFS($B$5:$B$304,$B7,$C$5:$C$304,$C7,$D$5:$D$304,$D7,$G$5:$G$304,$G7)>1,"Doublon possible (meme date, type, lot et quantite).",IF($K7="LOT NON REFERENCE","Creer d'abord la fiche du lot dans l'onglet LOTS.",""))))))
A8: =IF($C8="","","OP-"&TEXT(ROW()-4,"000")) -> OP-004 | B8: 46240 | C8: RECEPTION | D8: 258 | F8: OCEAMIC 2 | G8: 200 | H8: Reception usine | J8: =IF($D8="","",IFERROR(INDEX(LOT_EXTE,MATCH($D8,LOT_KEY,0)),"")) -> L-EXT-258 | K8: =IF($D8="","",IFERROR(INDEX(LOT_PRODE,MATCH($D8,LOT_KEY,0)),"LOT NON REFERENCE")) -> Sardine | L8: =IF($D8="","",IFERROR(INDEX(LOT_FOURNE,MATCH($D8,LOT_KEY,0)),"")) -> Fournisseur local | M8: =IF($E8="","",IFERROR(INDEX(EMPL_CLASSE,MATCH($E8,EMPL_KEY,0)),"?")) | N8: =IF($F8="","",IFERROR(INDEX(EMPL_CLASSE,MATCH($F8,EMPL_KEY,0)),"?")) -> INTERNE | O8: =IF($C8="",0,IF(OR($B8="",$D8=""),0,IF($C8="AJUSTEMENT",IF(OR(NOT(ISNUMBER($G8)),$G8=0,$F8="",$H8=""),0,1),IF(OR(NOT(ISNUMBER($G8)),$G8<=0),0,IF($C8="RECEPTION",IF($F8="",0,1),IF($C8="CONSOMMATION",IF($E8="",0,1),IF(OR($E8="",$F8="",$E8=$F8),0,1))))))) -> 1 | P8: =IF(OR($O8=0,$C8="RECEPTION"),"",IF($C8="AJUSTEMENT",IF($G8>0,"",SUMIFS(MVT_BRUT,MVT_LOT,$D8,MVT_EMPL,$F8)-$G8),SUMIFS(MVT_BRUT,MVT_LOT,$D8,MVT_EMPL,$E8)+$G8)) | Q8: =IF($C8="","",IF($O8=0,"DONNEES MANQUANTES",IF($C8="RECEPTION","OK",IF(AND($C8="AJUSTEMENT",$G8>0),"OK",IF($P8<=0,"EMPLACEMENT INCOHERENT",IF(ABS($G8)>$P8+0.001,"STOCK INSUFFISANT","OK")))))) -> OK | R8: =IF($Q8="OK",1,0) -> 1 | S8: =IF($C8="","",IF($O8=0,"A COMPLETER : "&IF($B8="","DATE; ","")&IF($D8="","LOT INTERNE; ","")&IF(NOT(ISNUMBER($G8)),"QUANTITE; ",IF(AND($C8="AJUSTEMENT",$G8=0),"QUANTITE <> 0; ",IF(AND($C8<>"AJUSTEMENT",$G8<=0),"QUANTITE > 0; ","")))&IF(AND($C8="AJUSTEMENT",$H8=""),"MOTIF; ","")&IF(AND(OR($C8="TRANSFERT",$C8="CONSOMMATION"),$E8=""),"EMPL. SOURCE; ","")&IF(AND($C8<>"CONSOMMATION",$F8=""),"EMPL. DESTINATION; ","")&IF(AND($C8="TRANSFERT",$E8<>"",$E8=$F8),"SOURCE = DESTINATION; ",""),IF($Q8="EMPLACEMENT INCOHERENT","Le lot "&$D8&" n'existe pas sur cet emplacement (stock 0). Verifier l'emplacement.",IF($Q8="STOCK INSUFFISANT","Disponible avant operation : "&TEXT($P8,"#,##0.00")&" kg. Ligne NON comptee en stock.",IF(COUNTIFS($B$5:$B$304,$B8,$C$5:$C$304,$C8,$D$5:$D$304,$D8,$G$5:$G$304,$G8)>1,"Doublon possible (meme date, type, lot et quantite).",IF($K8="LOT NON REFERENCE","Creer d'abord la fiche du lot dans l'onglet LOTS.",""))))))
A9: =IF($C9="","","OP-"&TEXT(ROW()-4,"000")) -> OP-005 | B9: 46242 | C9: CONSOMMATION | D9: 257 | E9: OCEAMIC 2 | G9: 300 | H9: Production conserve | I9: Scenario 3 - il doit rester 500 kg | J9: =IF($D9="","",IFERROR(INDEX(LOT_EXTE,MATCH($D9,LOT_KEY,0)),"")) -> L-EXT-255 | K9: =IF($D9="","",IFERROR(INDEX(LOT_PRODE,MATCH($D9,LOT_KEY,0)),"LOT NON REFERENCE")) -> Sardine | L9: =IF($D9="","",IFERROR(INDEX(LOT_FOURNE,MATCH($D9,LOT_KEY,0)),"")) -> Fournisseur local | M9: =IF($E9="","",IFERROR(INDEX(EMPL_CLASSE,MATCH($E9,EMPL_KEY,0)),"?")) -> INTERNE | N9: =IF($F9="","",IFERROR(INDEX(EMPL_CLASSE,MATCH($F9,EMPL_KEY,0)),"?")) | O9: =IF($C9="",0,IF(OR($B9="",$D9=""),0,IF($C9="AJUSTEMENT",IF(OR(NOT(ISNUMBER($G9)),$G9=0,$F9="",$H9=""),0,1),IF(OR(NOT(ISNUMBER($G9)),$G9<=0),0,IF($C9="RECEPTION",IF($F9="",0,1),IF($C9="CONSOMMATION",IF($E9="",0,1),IF(OR($E9="",$F9="",$E9=$F9),0,1))))))) -> 1 | P9: =IF(OR($O9=0,$C9="RECEPTION"),"",IF($C9="AJUSTEMENT",IF($G9>0,"",SUMIFS(MVT_BRUT,MVT_LOT,$D9,MVT_EMPL,$F9)-$G9),SUMIFS(MVT_BRUT,MVT_LOT,$D9,MVT_EMPL,$E9)+$G9)) -> 800 | Q9: =IF($C9="","",IF($O9=0,"DONNEES MANQUANTES",IF($C9="RECEPTION","OK",IF(AND($C9="AJUSTEMENT",$G9>0),"OK",IF($P9<=0,"EMPLACEMENT INCOHERENT",IF(ABS($G9)>$P9+0.001,"STOCK INSUFFISANT","OK")))))) -> OK | R9: =IF($Q9="OK",1,0) -> 1 | S9: =IF($C9="","",IF($O9=0,"A COMPLETER : "&IF($B9="","DATE; ","")&IF($D9="","LOT INTERNE; ","")&IF(NOT(ISNUMBER($G9)),"QUANTITE; ",IF(AND($C9="AJUSTEMENT",$G9=0),"QUANTITE <> 0; ",IF(AND($C9<>"AJUSTEMENT",$G9<=0),"QUANTITE > 0; ","")))&IF(AND($C9="AJUSTEMENT",$H9=""),"MOTIF; ","")&IF(AND(OR($C9="TRANSFERT",$C9="CONSOMMATION"),$E9=""),"EMPL. SOURCE; ","")&IF(AND($C9<>"CONSOMMATION",$F9=""),"EMPL. DESTINATION; ","")&IF(AND($C9="TRANSFERT",$E9<>"",$E9=$F9),"SOURCE = DESTINATION; ",""),IF($Q9="EMPLACEMENT INCOHERENT","Le lot "&$D9&" n'existe pas sur cet emplacement (stock 0). Verifier l'emplacement.",IF($Q9="STOCK INSUFFISANT","Disponible avant operation : "&TEXT($P9,"#,##0.00")&" kg. Ligne NON comptee en stock.",IF(COUNTIFS($B$5:$B$304,$B9,$C$5:$C$304,$C9,$D$5:$D$304,$D9,$G$5:$G$304,$G9)>1,"Doublon possible (meme date, type, lot et quantite).",IF($K9="LOT NON REFERENCE","Creer d'abord la fiche du lot dans l'onglet LOTS.",""))))))
A10: =IF($C10="","","OP-"&TEXT(ROW()-4,"000")) -> OP-006 | B10: 46243 | C10: TRANSFERT | D10: 256 | E10: SARMA | F10: OCEAMIC 2 | G10: 800 | H10: Rapatriement usine | I10: Scenario 4 - transfert partiel | J10: =IF($D10="","",IFERROR(INDEX(LOT_EXTE,MATCH($D10,LOT_KEY,0)),"")) -> L-EXT-256 | K10: =IF($D10="","",IFERROR(INDEX(LOT_PRODE,MATCH($D10,LOT_KEY,0)),"LOT NON REFERENCE")) -> Maquereau | L10: =IF($D10="","",IFERROR(INDEX(LOT_FOURNE,MATCH($D10,LOT_KEY,0)),"")) -> Producteur Boujdour | M10: =IF($E10="","",IFERROR(INDEX(EMPL_CLASSE,MATCH($E10,EMPL_KEY,0)),"?")) -> EXTERNE | N10: =IF($F10="","",IFERROR(INDEX(EMPL_CLASSE,MATCH($F10,EMPL_KEY,0)),"?")) -> INTERNE | O10: =IF($C10="",0,IF(OR($B10="",$D10=""),0,IF($C10="AJUSTEMENT",IF(OR(NOT(ISNUMBER($G10)),$G10=0,$F10="",$H10=""),0,1),IF(OR(NOT(ISNUMBER($G10)),$G10<=0),0,IF($C10="RECEPTION",IF($F10="",0,1),IF($C10="CONSOMMATION",IF($E10="",0,1),IF(OR($E10="",$F10="",$E10=$F10),0,1))))))) -> 1 | P10: =IF(OR($O10=0,$C10="RECEPTION"),"",IF($C10="AJUSTEMENT",IF($G10>0,"",SUMIFS(MVT_BRUT,MVT_LOT,$D10,MVT_EMPL,$F10)-$G10),SUMIFS(MVT_BRUT,MVT_LOT,$D10,MVT_EMPL,$E10)+$G10)) -> 2000 | Q10: =IF($C10="","",IF($O10=0,"DONNEES MANQUANTES",IF($C10="RECEPTION","OK",IF(AND($C10="AJUSTEMENT",$G10>0),"OK",IF($P10<=0,"EMPLACEMENT INCOHERENT",IF(ABS($G10)>$P10+0.001,"STOCK INSUFFISANT","OK")))))) -> OK | R10: =IF($Q10="OK",1,0) -> 1 | S10: =IF($C10="","",IF($O10=0,"A COMPLETER : "&IF($B10="","DATE; ","")&IF($D10="","LOT INTERNE; ","")&IF(NOT(ISNUMBER($G10)),"QUANTITE; ",IF(AND($C10="AJUSTEMENT",$G10=0),"QUANTITE <> 0; ",IF(AND($C10<>"AJUSTEMENT",$G10<=0),"QUANTITE > 0; ","")))&IF(AND($C10="AJUSTEMENT",$H10=""),"MOTIF; ","")&IF(AND(OR($C10="TRANSFERT",$C10="CONSOMMATION"),$E10=""),"EMPL. SOURCE; ","")&IF(AND($C10<>"CONSOMMATION",$F10=""),"EMPL. DESTINATION; ","")&IF(AND($C10="TRANSFERT",$E10<>"",$E10=$F10),"SOURCE = DESTINATION; ",""),IF($Q10="EMPLACEMENT INCOHERENT","Le lot "&$D10&" n'existe pas sur cet emplacement (stock 0). Verifier l'emplacement.",IF($Q10="STOCK INSUFFISANT","Disponible avant operation : "&TEXT($P10,"#,##0.00")&" kg. Ligne NON comptee en stock.",IF(COUNTIFS($B$5:$B$304,$B10,$C$5:$C$304,$C10,$D$5:$D$304,$D10,$G$5:$G$304,$G10)>1,"Doublon possible (meme date, type, lot et quantite).",IF($K10="LOT NON REFERENCE","Creer d'abord la fiche du lot dans l'onglet LOTS.",""))))))
A11: =IF($C11="","","OP-"&TEXT(ROW()-4,"000")) -> OP-007 | B11: 46244 | C11: RECEPTION | D11: 301 | F11: OCEAMIC 2 | G11: 400 | H11: Reception usine | J11: =IF($D11="","",IFERROR(INDEX(LOT_EXTE,MATCH($D11,LOT_KEY,0)),"")) -> L-EXT-301 | K11: =IF($D11="","",IFERROR(INDEX(LOT_PRODE,MATCH($D11,LOT_KEY,0)),"LOT NON REFERENCE")) -> Maquereau | L11: =IF($D11="","",IFERROR(INDEX(LOT_FOURNE,MATCH($D11,LOT_KEY,0)),"")) -> Producteur Boujdour | M11: =IF($E11="","",IFERROR(INDEX(EMPL_CLASSE,MATCH($E11,EMPL_KEY,0)),"?")) | N11: =IF($F11="","",IFERROR(INDEX(EMPL_CLASSE,MATCH($F11,EMPL_KEY,0)),"?")) -> INTERNE | O11: =IF($C11="",0,IF(OR($B11="",$D11=""),0,IF($C11="AJUSTEMENT",IF(OR(NOT(ISNUMBER($G11)),$G11=0,$F11="",$H11=""),0,1),IF(OR(NOT(ISNUMBER($G11)),$G11<=0),0,IF($C11="RECEPTION",IF($F11="",0,1),IF($C11="CONSOMMATION",IF($E11="",0,1),IF(OR($E11="",$F11="",$E11=$F11),0,1))))))) -> 1 | P11: =IF(OR($O11=0,$C11="RECEPTION"),"",IF($C11="AJUSTEMENT",IF($G11>0,"",SUMIFS(MVT_BRUT,MVT_LOT,$D11,MVT_EMPL,$F11)-$G11),SUMIFS(MVT_BRUT,MVT_LOT,$D11,MVT_EMPL,$E11)+$G11)) | Q11: =IF($C11="","",IF($O11=0,"DONNEES MANQUANTES",IF($C11="RECEPTION","OK",IF(AND($C11="AJUSTEMENT",$G11>0),"OK",IF($P11<=0,"EMPLACEMENT INCOHERENT",IF(ABS($G11)>$P11+0.001,"STOCK INSUFFISANT","OK")))))) -> OK | R11: =IF($Q11="OK",1,0) -> 1 | S11: =IF($C11="","",IF($O11=0,"A COMPLETER : "&IF($B11="","DATE; ","")&IF($D11="","LOT INTERNE; ","")&IF(NOT(ISNUMBER($G11)),"QUANTITE; ",IF(AND($C11="AJUSTEMENT",$G11=0),"QUANTITE <> 0; ",IF(AND($C11<>"AJUSTEMENT",$G11<=0),"QUANTITE > 0; ","")))&IF(AND($C11="AJUSTEMENT",$H11=""),"MOTIF; ","")&IF(AND(OR($C11="TRANSFERT",$C11="CONSOMMATION"),$E11=""),"EMPL. SOURCE; ","")&IF(AND($C11<>"CONSOMMATION",$F11=""),"EMPL. DESTINATION; ","")&IF(AND($C11="TRANSFERT",$E11<>"",$E11=$F11),"SOURCE = DESTINATION; ",""),IF($Q11="EMPLACEMENT INCOHERENT","Le lot "&$D11&" n'existe pas sur cet emplacement (stock 0). Verifier l'emplacement.",IF($Q11="STOCK INSUFFISANT","Disponible avant operation : "&TEXT($P11,"#,##0.00")&" kg. Ligne NON comptee en stock.",IF(COUNTIFS($B$5:$B$304,$B11,$C$5:$C$304,$C11,$D$5:$D$304,$D11,$G$5:$G$304,$G11)>1,"Doublon possible (meme date, type, lot et quantite).",IF($K11="LOT NON REFERENCE","Creer d'abord la fiche du lot dans l'onglet LOTS.",""))))))
A12: =IF($C12="","","OP-"&TEXT(ROW()-4,"000")) -> OP-008 | B12: 46245 | C12: CONSOMMATION | D12: 258 | E12: OCEAMIC 2 | G12: 500 | H12: Production conserve | I12: Scenario 13 - doit etre refuse : stock disponible 200 kg | J12: =IF($D12="","",IFERROR(INDEX(LOT_EXTE,MATCH($D12,LOT_KEY,0)),"")) -> L-EXT-258 | K12: =IF($D12="","",IFERROR(INDEX(LOT_PRODE,MATCH($D12,LOT_KEY,0)),"LOT NON REFERENCE")) -> Sardine | L12: =IF($D12="","",IFERROR(INDEX(LOT_FOURNE,MATCH($D12,LOT_KEY,0)),"")) -> Fournisseur local | M12: =IF($E12="","",IFERROR(INDEX(EMPL_CLASSE,MATCH($E12,EMPL_KEY,0)),"?")) -> INTERNE | N12: =IF($F12="","",IFERROR(INDEX(EMPL_CLASSE,MATCH($F12,EMPL_KEY,0)),"?")) | O12: =IF($C12="",0,IF(OR($B12="",$D12=""),0,IF($C12="AJUSTEMENT",IF(OR(NOT(ISNUMBER($G12)),$G12=0,$F12="",$H12=""),0,1),IF(OR(NOT(ISNUMBER($G12)),$G12<=0),0,IF($C12="RECEPTION",IF($F12="",0,1),IF($C12="CONSOMMATION",IF($E12="",0,1),IF(OR($E12="",$F12="",$E12=$F12),0,1))))))) -> 1 | P12: =IF(OR($O12=0,$C12="RECEPTION"),"",IF($C12="AJUSTEMENT",IF($G12>0,"",SUMIFS(MVT_BRUT,MVT_LOT,$D12,MVT_EMPL,$F12)-$G12),SUMIFS(MVT_BRUT,MVT_LOT,$D12,MVT_EMPL,$E12)+$G12)) -> 200 | Q12: =IF($C12="","",IF($O12=0,"DONNEES MANQUANTES",IF($C12="RECEPTION","OK",IF(AND($C12="AJUSTEMENT",$G12>0),"OK",IF($P12<=0,"EMPLACEMENT INCOHERENT",IF(ABS($G12)>$P12+0.001,"STOCK INSUFFISANT","OK")))))) -> STOCK INSUFFISANT | R12: =IF($Q12="OK",1,0) -> 0 | S12: =IF($C12="","",IF($O12=0,"A COMPLETER : "&IF($B12="","DATE; ","")&IF($D12="","LOT INTERNE; ","")&IF(NOT(ISNUMBER($G12)),"QUANTITE; ",IF(AND($C12="AJUSTEMENT",$G12=0),"QUANTITE <> 0; ",IF(AND($C12<>"AJUSTEMENT",$G12<=0),"QUANTITE > 0; ","")))&IF(AND($C12="AJUSTEMENT",$H12=""),"MOTIF; ","")&IF(AND(OR($C12="TRANSFERT",$C12="CONSOMMATION"),$E12=""),"EMPL. SOURCE; ","")&IF(AND($C12<>"CONSOMMATION",$F12=""),"EMPL. DESTINATION; ","")&IF(AND($C12="TRANSFERT",$E12<>"",$E12=$F12),"SOURCE = DESTINATION; ",""),IF($Q12="EMPLACEMENT INCOHERENT","Le lot "&$D12&" n'existe pas sur cet emplacement (stock 0). Verifier l'emplacement.",IF($Q12="STOCK INSUFFISANT","Disponible avant operation : "&TEXT($P12,"#,##0.00")&" kg. Ligne NON comptee en stock.",IF(COUNTIFS($B$5:$B$304,$B12,$C$5:$C$304,$C12,$D$5:$D$304,$D12,$G$5:$G$304,$G12)>1,"Doublon possible (meme date, type, lot et quantite).",IF($K12="LOT NON REFERENCE","Creer d'abord la fiche du lot dans l'onglet LOTS.","")))))) -> Disponible avant operation : 200.00 kg. Ligne NON comptee en stock.
